Workbook
Name Insurer: [1]Details!$F$10
Name Period_End: [1]Details!$F$18
Name Type_of_Return: [1]Details!$F$12
Name Year: [1]Details!$F$16

Sheet 41-1A
B2: FORM No. INS 41-1A
B3: Total Capital Available
B4: NAME OF INSURER
B5: YEAR
B7: Capital Available | C7: Line | D7: General Business
B8: All amounts in KES | D8: [B]
B9: Tier-1 Capital
B10: Fully paid-up ordinary shares | C10: 10 | D10: 0
B11: Share Premiums | C11: 11 | D11: 0
B12: Statutory Reserves | C12: 12 | D12: 0
A13: 0 | B13: Retained profits/(accumulated losses) | C13: 13 | D13: 0
B14: Total Amount | C14: 15 | D14: =SUM(D10:D13) -> 0
B15: Tier-2 Capital
B16: Irredeemable preference shares | C16: 16 | D16: 0
B17: Capital loan stocks or similar instruments | C17: 17 | D17: 0
B18: Subordinated loans | C18: 18 | D18: 0
B19: Convertible preference shares | C19: 19 | D19: 0
B20: Revaluation reserves | C20: 20 | D20: 0
B21: Fair value reserves for financial assets measured at FVOCI | C21: 21 | D21: 0
B22: Proposed Dividends | C22: 22 | D22: 0
B23: Other reserves | C23: 23
B24: Total Amount | C24: 24 | D24: =SUM(D16:D23) -> 0
B25: Deductions (Tier 3)
B26: Goodwill & other intangible assets | C26: 25 | D26: 0
B27: Deferred tax assets | C27: 26 | D27: 0
B28: Assets pledged to support credit facilities obtained by an insurer | C28: 29 | D28: 0
B29: Other Fixed Assets 1 | C29: 30 | D29: 0
B30: Under-reserving | C30: 31 | D30: 0
B31: Assets with over concentration limits | C31: 32 | D31: 0
B32: Other Deductions | C32: 33 | D32: 0
B33: Total Amount | C33: 34 | D33: =SUM(D26:D32) -> 0
B35: Total Capital Available | C35: 35 | D35: =D14+D24-D33 -> 0
B37: 1 Includes Computer equipments, Office Equipments , Motor Vehicles and Furniture and Fittings.

Sheet 41-1B
B2: FORM No. INS 41-1B
B3: Insurance Risk (Gross less reinsurance)
B4: ='41-1A'!B4 -> NAME OF INSURER
B5: ='41-1A'!B5 -> YEAR
B7: Class of Business | C7: Line | E7: Liability for Incurred Claims | K7: Liability for Remaining Coverage
E8: Risk Charge | F8: Best Estimate Liability (Gross BEL minus Reinsurance BEL) | G8: Risk Adjustment | H8: Total | I8: Capital Charge | K8: Risk Charge | L8: LRC | M8: Capital Charge
E9: [A] | F9: [B] | G9: [C] | H9: [D] | I9: [E]=A*D | K9: [F] | L9: [G] | M9: [H]=F*G
B11: Aviation | C11: 10 | E11: 0.29 | F11: 0 | G11: 0 | H11: 0 | I11: 0 | K11: 0.39 | L11: 0 | M11: =K11*L11 -> 0
B12: Engineering | C12: 11 | E12: 0.04 | F12: 0 | G12: 0 | H12: =SUM(F12:G12) -> 0 | I12: =E12*H12 -> 0 | K12: 0.08 | L12: 0 | M12: =K12*L12 -> 0
B13: Fire Domestic | C13: 12 | E13: 0.02 | F13: 0 | G13: 0 | H13: =SUM(F13:G13) -> 0 | I13: =E13*H13 -> 0 | K13: 0.03 | L13: 0 | M13: =K13*L13 -> 0
B14: Fire Industrial | C14: 13 | E14: 0.06 | F14: 0 | G14: 0 | H14: =SUM(F14:G14) -> 0 | I14: =E14*H14 -> 0 | K14: 0.09 | L14: 0 | M14: =K14*L14 -> 0
B15: Liability | C15: 14 | E15: 0.09 | F15: 0 | G15: 0 | H15: =SUM(F15:G15) -> 0 | I15: =E15*H15 -> 0 | K15: 0.09 | L15: 0 | M15: =K15*L15 -> 0
B16: Marine | C16: 15 | E16: 0.08 | F16: 0 | G16: 0 | H16: =SUM(F16:G16) -> 0 | I16: =E16*H16 -> 0 | K16: 0.07 | L16: 0 | M16: =K16*L16 -> 0
B17: Motor Private | C17: 16 | F17: 0 | G17: 0 | L17: 0
B18: Property damage | C18: 17 | E18: 0.05 | F18: 0 | G18: 0 | H18: =SUM(F18:G18) -> 0 | I18: =E18*H18 -> 0 | K18: 0.05 | L18: 0 | M18: =K18*L18 -> 0
B19: Liability | C19: 18 | E19: 0.12 | F19: 0 | G19: 0 | H19: =SUM(F19:G19) -> 0 | I19: =E19*H19 -> 0 | K19: 0.12 | L19: 0 | M19: =K19*L19 -> 0
B20: Motor Commercial | C20: 19 | F20: 0 | G20: 0 | L20: 0
B21: Property damage | C21: 20 | E21: 0.03 | F21: 0 | G21: 0 | H21: =SUM(F21:G21) -> 0 | I21: =E21*H21 -> 0 | K21: 0.03 | L21: 0 | M21: =K21*L21 -> 0
B22: Liability | C22: 21 | E22: 0.13 | F22: 0 | G22: 0 | H22: =SUM(F22:G22) -> 0 | I22: =E22*H22 -> 0 | K22: 0.13 | L22: 0 | M22: =K22*L22 -> 0
B23: Motor Commercial-PSV | C23: 22 | F23: 0 | G23: 0 | L23: 0
B24: Property damage | C24: 23 | E24: 0.03 | F24: 0 | G24: 0 | H24: =SUM(F24:G24) -> 0 | I24: =E24*H24 -> 0 | K24: 0.03 | L24: 0 | M24: =K24*L24 -> 0
B25: Liability | C25: 24 | E25: 0.14 | F25: 0 | G25: 0 | K25: 0.14 | L25: 0 | M25: 0
B26: Personal Accident | C26: 25 | E26: 0.09 | F26: 0 | G26: 0 | H26: =SUM(F26:G26) -> 0 | I26: =E26*H26 -> 0 | K26: 0.06 | L26: 0 | M26: =K26*L26 -> 0
B27: Theft | C27: 26 | E27: 0.04 | F27: 0 | G27: 0 | H27: =SUM(F27:G27) -> 0 | I27: =E27*H27 -> 0 | K27: 0.04 | L27: 0 | M27: =K27*L27 -> 0
B28: Workmens' Compensation | C28: 27 | E28: 0.19 | F28: 0 | G28: 0 | H28: =SUM(F28:G28) -> 0 | I28: =E28*H28 -> 0 | K28: 0.18 | L28: 0 | M28: =K28*L28 -> 0
B29: Miscellaneous | C29: 28 | E29: 0.06 | F29: 0 | G29: 0 | H29: =SUM(F29:G29) -> 0 | I29: =E29*H29 -> 0 | K29: 0.08 | L29: 0 | M29: =K29*L29 -> 0
B30: Medical | C30: 29 | E30: 0.13 | F30: 0 | G30: 0 | H30: =SUM(F30:G30) -> 0 | I30: =E30*H30 -> 0 | K30: 0.15 | L30: 0 | M30: =K30*L30 -> 0
B31: Total | C31: 30 | F31: =SUM(F11:F30) -> 0 | G31: =SUM(G12:G30) -> 0 | H31: =SUM(H11:H30) -> 0 | I31: =SUM(I12:I30) -> 0 | L31: =SUM(L11:L30) -> 0 | M31: =SUM(M11:M30) -> 0
B33: Catastrophe Risk | C33: Line | E33: Risk Charge | F33: Net Earned Premium Previous Year | G33: Capital Charge
B35: Catastrophe Risk Charge | C35: 31 | E35: 0.02 | F35: ='41-1E'!D17 -> 0 | G35: =E35*F35 -> 0
B37: Insurance Risk Capital | C37: 32 | G37: =I31+M31+G35 -> 0

Sheet 41-1C
B2: FORM No. INS 41-1C
B3: Market Risk
B4: ='41-1A'!B4 -> NAME OF INSURER
B5: ='41-1A'!B5 -> YEAR
C7: Line | D7: Total exposure | E7: Risk charge | F7: Capital charge
B8: All amounts in KES | D8: [A] | E8: [B] | F8: [C]
B9: Equity Risk
B10: Listed Ordinary Shares on the NSE | C10: 10 | D10: 0 | E10: 0.3 | F10: =D10*E10 -> 0
B11: Listed Ordinary Shares on other recognized stock exchanges | C11: 11 | D11: 0 | E11: 0.3 | F11: =D11*E11 -> 0
B12: Listed Preference Shares on the NSE | C12: 12 | D12: 0 | E12: 0.35 | F12: =D12*E12 -> 0
B13: Listed Preference Shares on other recognized stock exchanges | C13: 13 | D13: 0 | E13: 0.4 | F13: =D13*E13 -> 0
B14: Unlisted Shares and/or private equity (including venture capital) | C14: 14 | D14: 0 | E14: 0.4 | F14: =D14*E14 -> 0
B15: Total Amount | C15: 15 | D15: =SUM(D10:D14) -> 0 | F15: =SUM(F10:F14) -> 0
B17: Property Risks
B18: Land and Self-occupied properties | C18: 16 | D18: 0 | E18: 0.4 | F18: =D18*E18 -> 0
B19: Investment property, property-related investments | C19: 17 | D19: 0 | E19: 0.3 | F19: =D19*E19 -> 0
B20: REITS | C20: 17 | D20: 0 | E20: 0.3 | F20: 0
B21: Total Amount | C21: 19 | D21: =SUM(D18:D20) -> 0 | F21: =SUM(F18:F20) -> 0
B23: Interest Rate Risk
B24: General Insurance Fund
B25: Scenario | C25: 20 | D25: Asset Value 1 | E25: Liability Value 2 | F25: Surplus
B26: Base Interest Rate3 | C26: 21 | F26: 0
B27: Increasing interest rate | C27: 22 | F27: 0
B28: Decreasing interest rate | C28: 23 | F28: 0
B29: Interest Rate Risk Charge | C29: 24 | F29: 0
B31: Note:
B32: 1 Refers to interest rate related securities held by the insurer
B33: 2 The base liability is the value derived based on the valuation basis which includes the provision of risk margin for adverse deviation as prescribed and discounted at the risk-free rate
B34: 3 The amount of capital charges for each fund is the higher of zero or the reduction in surplus based on the dominant scenario at the company level
B36: Currency Risk
B37: Types of currency | D37: Net On Balance Sheet Position 1/ | E37: Net Forward Position 2/ | F37: Net Long Position | G37: Net Short Position
B60: Total Position | F60: 0 | G60: 0
F61: Exposure | G61: 0
F62: Risk charge | G62: 0.08
B63: Note: | F63: Capital Charge | G63: 0
B64: 1 - equivalent value of all foreign currency assets less all foreign currency liabilities in a particular foreign currency.
B65: 2 - equivalent value of all amounts to be received less the value of all amounts to be paid under unsettled spot transactions, forward foreign exchange transactions,
B66: including currency futures, the principal on currency swaps position and interest rate transactions such as futures, swaps etc. denominated in a foreign currency.
B68: Market Risk Charge3 | F68: =SQRT((F15^2)+(F21^2)+(F29^2)+(G63^2)) -> 0
B70: Notes
...

Sheet 41-1D
B2: FORM No. INS 41-1D
B3: Credit Risk
B4: ='41-1A'!B4 -> NAME OF INSURER
B5: ='41-1A'!B5 -> YEAR
C7: Line | D7: Total exposure | E7: Risk charge | F7: Capital charge
B8: All amounts in KES | D8: [A] | E8: [B] | F8: [C]
B9: Securities
B10: Kenyan Government Bonds | C10: 10 | D10: 0 | E10: 0 | F10: =D10*E10 -> 0
B11: Kenyan Government Treasury Bills | C11: 11 | D11: 0 | E11: 0 | F11: =D11*E11 -> 0
B12: Foreign Government Bonds | C12: 12 | D12: 0 | E12: 0.05 | F12: =D12*E12 -> 0
B13: County Government Bonds | C13: 13 | D13: 0 | E13: 0.12 | F13: =D13*E13 -> 0
B14: Corporations and other organisations bonds | C14: 14 | D14: 0 | E14: 0.12 | F14: =D14*E14 -> 0
B17: Term Deposits and Cash
B18: Term Deposits | C18: 15 | D18: 0 | E18: 0 | F18: 0
B19: Cash and Cash Balances | C19: 16 | D19: 0 | E19: 0 | F19: 0
B21: Debt Obligations
B22: Policy loans | C22: 17 | D22: 0 | E22: 0 | F22: =D22*E22 -> 0
B23: Secured Loans- Corporations and other organisations | C23: 18 | D23: 0 | E23: 0.1 | F23: =D23*E23 -> 0
B24: Secured Loans-Staff and Individuals | C24: 19 | D24: 0 | E24: 0.3 | F24: =D24*E24 -> 0
B25: Investment in Subsidiaries,Associates and Joint Ventures | C25: 20 | D25: 0 | E25: 0.4 | F25: =D25*E25 -> 0
B26: Mortgages | C26: 21 | D26: 0 | E26: 0.3 | F26: =D26*E26 -> 0
B27: Unsecured Loans | C27: 22 | D27: 0 | E27: 1 | F27: =D27*E27 -> 0
B28: Secured Loans to related parties | C28: 23 | D28: 0 | E28: 1 | F28: =D28*E28 -> 0
B30: Credit exposures to (re)insurers with the following rating categories:
B31: Category 1 - Reinsurers with rated above A- | C31: 24 | D31: 0 | E31: 0.025 | F31: =D31*E31 -> 0
B32: Category 2 - Reinsurers with rated above BBB | C32: 25 | E32: 0.1 | F32: =D32*E32 -> 0
B33: Category 3 - Reinsurers with rated below BBB | C33: 26 | D33: 0 | E33: 0.35 | F33: =D33*E33 -> 0
B34: Category 4 - Reinsurers Unrated | C34: 27 | E34: 1 | F34: =D34*E34 -> 0
B35: Category 5 - Reinsurers licenced under the Insurance Act | C35: 28 | D35: 0 | E35: 0.025 | F35: =D35*E35 -> 0
B37: Other Assets
B38: Premium Receivables | C38: 29 | D38: 0 | E38: 1 | F38: =D38*E38 -> 0
B41: Credit Risk Charge | F41: =SUM(F10:F38) -> 0

Sheet 41-1E
B2: FORM No. INS 41-1E
B3: Operational Risk
B4: ='41-1A'!B4 -> NAME OF INSURER
B5: ='41-1A'!B5 -> YEAR
B7: Risk | C7: Line | D7: General Business
D8: [B]
B10: Credit risk capital charges | C10: 10 | D10: ='41-1D'!F41 -> 0
B11: Market risk capital charges | C11: 11 | D11: ='41-1C'!F68 -> 0
B12: Insurance risk capital charges | C12: 12 | D12: ='41-1B'!G37 -> 0
B14: Basic Operational Risk Charge1 | C14: 13 | D14: =0.3*(SQRT((D10^2)+(D11^2)+(D12^2))) -> 0
B15: Basic Operational Risk Charge2 | C15: 14 | D15: =0.03*D16 -> 0
B16: Prior Year Gross Earned Premium | C16: 15 | D16: 0
B17: Prior Year Net Earned Premium | C17: 16 | D17: 0
B19: Operational Risk Charge | C19: 19 | D19: =MAX(D14,D15) -> 0
B21: Notes
B22: 1 30% of the square root of the sum of squares of the capital required for
B23: Insurance, Market and Credit risk

Sheet 41-1F
B2: FORM No. INS 41-1F
B3: Capital Required
B4: ='41-1A'!B4 -> NAME OF INSURER
B5: ='41-1A'!B5 -> YEAR
B7: Risk | C7: Line | D7: General Business
D8: [B]
B10: Credit risk capital charges | C10: 10 | D10: ='41-1D'!F41 -> 0
B11: Market risk capital charges | C11: 11 | D11: ='41-1C'!F68 -> 0
B12: Insurance risk capital charges | C12: 12 | D12: ='41-1B'!G37 -> 0
B13: Operational risk capital charges | C13: 13 | D13: ='41-1E'!D19 -> 0
B15: Risk Based Capital1 | C15: 14 | D15: =D13+SQRT((D10^2)+(D11^2)+(D12^2)) -> 0
B17: Notes
B18: 1 Square root of the sum of squares of the capital required for Insurance,
B19: Market and Credit risk plus the Operational Risk

Sheet 41-1
B2: FORM No. INS 41-1
B3: Capital Adequacy Ratio
B4: ='41-1A'!B4 -> NAME OF INSURER
B5: ='41-1A'!B5 -> YEAR
B7: Capital | C7: Line | D7: General Business
D8: [B]
B10: Tier-1 Capital | C10: 10 | D10: ='41-1A'!D14 -> 0
B11: Tier-2 Capital | C11: 11 | D11: ='41-1A'!D24 -> 0
B12: Deductions | C12: 12 | D12: ='41-1A'!D33 -> 0
B13: Total Capital Available (TCA) | C13: 13 | D13: =D10+D11-D12 -> 0
B15: Absolute Amount Minimum1 | C15: 14 | D15: =IF(D13=0,0,600000000) -> 0
B16: Volume of Business Minimum2 | C16: 15 | D16: =0.2*'41-1E'!D17 -> 0
B17: Risk Based Capital Minimum | C17: 16 | D17: ='41-1F'!D15 -> 0
B18: Minimum Required Capital | C18: 17 | D18: =MAX(D15,D16,D17) -> 0
B20: Capital Adequacy Ratio | C20: 18 | D20: =IFERROR(D13/D18,"")

Sheet Valuation Results
C2: XX Insurance Company Limited Net LIC Results as at 31 December 2025 | I2: XX Insurance Company Limited Net LRC Results as at 31 December 2025
C4: Business Class | D4: IBNR* | E4: OCR | F4: Risk Adjustment | G4: Gross LIC Reserves | I4: Business Class | J4: LRC | K4: Loss Component | L4: Total LRC
C5: Aviation | D5: 1000000 | E5: 200000 | F5: 90000 | G5: =SUM(D5:F5) -> 1290000 | I5: Aviation | J5: 7000000 | K5: 0 | L5: =SUM(J5:K5) -> 7000000
C6: Engineering | D6: 1400000 | E6: 13500000 | F6: 97500 | G6: =SUM(D6:F6) -> 14997500 | I6: Engineering | J6: 8200000 | K6: 900000 | L6: =SUM(J6:K6) -> 9100000
C7: Fire Domestic | D7: 600000 | E7: 3600000 | F7: 17000 | G7: =SUM(D7:F7) -> 4217000 | I7: Fire Domestic | J7: 5800000 | K7: 0 | L7: =SUM(J7:K7) -> 5800000
C8: Fire Industrial | D8: 250000 | E8: 11300000 | F8: 100000 | G8: =SUM(D8:F8) -> 11650000 | I8: Fire Industrial | J8: 12700000 | K8: 0 | L8: =SUM(J8:K8) -> 12700000
C9: Liability | D9: 3300000 | E9: 80000000 | F9: 1000000 | G9: =SUM(D9:F9) -> 84300000 | I9: Liability | J9: 20000000 | K9: 0 | L9: =SUM(J9:K9) -> 20000000
C10: Marine | D10: 2500000 | E10: 28500000 | F10: 300000 | G10: =SUM(D10:F10) -> 31300000 | I10: Marine | J10: 6700000 | K10: 0 | L10: =SUM(J10:K10) -> 6700000
C11: Medical | D11: 560000 | E11: 6600000 | F11: 120000 | G11: =SUM(D11:F11) -> 7280000 | I11: Medical | J11: 19000000 | L11: =SUM(J11:K11) -> 19000000
C12: Miscellaneous | D12: 3200000 | E12: 5000000 | F12: 70000 | G12: =SUM(D12:F12) -> 8270000 | I12: Miscellaneous | J12: 6500000 | K12: 0 | L12: =SUM(J12:K12) -> 6500000
C13: Motor Commercial | D13: 87000000 | E13: 535000000 | F13: 55000000 | G13: =SUM(D13:F13) -> 677000000 | I13: Motor Commercial | J13: 350000000 | K13: 15000000 | L13: =SUM(J13:K13) -> 365000000
C14: Motor Commercial-PSV | D14: 4000000 | E14: 35000000 | F14: 1200000 | G14: =SUM(D14:F14) -> 40200000 | I14: Motor Commercial-PSV | J14: 17000000 | K14: 1000000 | L14: =SUM(J14:K14) -> 18000000
C15: Motor Private | D15: 78000000 | E15: 750000000 | F15: 48000000 | G15: =SUM(D15:F15) -> 876000000 | I15: Motor Private | J15: 600000000 | K15: 150000000 | L15: =SUM(J15:K15) -> 750000000
C16: Personal Accident | D16: 1500000 | E16: 400000 | F16: 18000 | G16: =SUM(D16:F16) -> 1918000 | I16: Personal Accident | J16: 3000000 | L16: =SUM(J16:K16) -> 3000000
C17: Theft | D17: 2700000 | E17: 45000000 | F17: 280000 | G17: =SUM(D17:F17) -> 47980000 | I17: Theft | J17: 14000000 | K17: 0 | L17: =SUM(J17:K17) -> 14000000
C18: Workmens' Compensation | D18: 180000000 | E18: 175000000 | F18: 9000000 | G18: =SUM(D18:F18) -> 364000000 | I18: Workmens' Compensation | J18: 89000000 | K18: 325000 | L18: =SUM(J18:K18) -> 89325000
C19: TOTAL | D19: =SUM(D5:D18) -> 366010000 | E19: =SUM(E5:E18) -> 1689100000 | F19: =SUM(F5:F18) -> 115292500 | G19: =SUM(G5:G18) -> 2170402500 | I19: TOTAL | J19: =SUM(J5:J18) -> 1158900000 | K19: =SUM(K5:K18) -> 167225000 | L19: =SUM(L5:L18) -> 1326125000
C20: *IBNR is inclusive of IBNER

Sheet Premium Receivables
C2: FORM No. INS 59-8
C3: PREMIUM RECEIVABLES FROM INTERMEDIARIES, INSURERS AND POLICYHOLDERS
E5: Name of Insurer | F5: ='41-1A'!B4 -> NAME OF INSURER
E6: For the year | F6: ='41-1A'!B5 -> YEAR
C8: TOTAL | E8: =SUM(E14:E17) -> 218000500 | F8: =SUM(F14:F17) -> 28500000 | G8: =SUM(G14:G17) -> 7000000 | H8: =SUM(H14:H17) -> 12000000 | I8: =SUM(I14:I17) -> 12000000 | J8: =SUM(J14:J17) -> 265500500 | K8: =SUM(K14:K17) -> 253500500
C9: PREMIUM RECEIVABLES FROM INTERMEDIARIES, REINSURERS AND POLICYHOLDERS
C10: No. | E10: Amount outstanding for | I10: Provision/ | J10: Total | K10: Net
D11: Name of the Entity | E11: Less than | F11: 30 days | H11: Over | I11: Bad Debts | J11: Gross | K11: Amount
E12: 30 days | F12: to 90 days | G12: to 6 months | H12: 6 months | I12: written off (KES) | J12: Amount
D13: (01) | E13: (02) | F13: (03) | G13: (04) | H13: (05) | I13: (06) | J13: (07)=(02)+(03)+(04)+(05) | K13: (08)=(07)-(06)
C14: 1 | D14: From Bancassurance Intermediaries | E14: 200000000 | F14: 22000000 | G14: 7000000 | H14: 12000000 | I14: 12000000 | J14: =SUM(E14:H14) -> 241000000 | K14: =J14-I14 -> 229000000
C15: =C14+1 -> 2 | D15: From Policyholders | E15: 10000000 | J15: =SUM(E15:H15) -> 10000000 | K15: =J15-I15 -> 10000000
C16: =C15+1 -> 3 | D16: From Insurers | E16: 8000500 | F16: 6500000 | G16: 0 | H16: 0 | J16: =SUM(E16:H16) -> 14500500 | K16: =J16-I16 -> 14500500
D17: Other Receivables (Specify): | E17: =SUM(E18:E27) -> 0 | F17: =SUM(F18:F27) -> 0 | G17: =SUM(G18:G27) -> 0 | H17: =SUM(H18:H27) -> 0 | I17: =SUM(I18:I27) -> 0 | J17: =SUM(E17:H17) -> 0 | K17: =J17-I17 -> 0
C18: 1 | J18: =SUM(E18:H18) -> 0 | K18: =J18-I18 -> 0
C19: 2 | J19: =SUM(E19:H19) -> 0 | K19: =J19-I19 -> 0
C20: 3 | J20: =SUM(E20:H20) -> 0 | K20: =J20-I20 -> 0
C21: 4 | J21: =SUM(E21:H21) -> 0 | K21: =J21-I21 -> 0
C22: 5 | J22: =SUM(E22:H22) -> 0 | K22: =J22-I22 -> 0
C23: 6 | J23: =SUM(E23:H23) -> 0 | K23: =J23-I23 -> 0
C24: 7 | J24: =SUM(E24:H24) -> 0 | K24: =J24-I24 -> 0
C25: 8 | J25: =SUM(E25:H25) -> 0 | K25: =J25-I25 -> 0
C26: 9 | J26: =SUM(E26:H26) -> 0 | K26: =J26-I26 -> 0
C27: 10 | J27: =SUM(E27:H27) -> 0 | K27: =J27-I27 -> 0
C28: TOTAL | E28: =SUM(E34:E1048576) -> 5500000 | F28: =SUM(F34:F1048576) -> 22055000 | G28: =SUM(G34:G1048576) -> 12235000 | H28: =SUM(H34:H1048576) -> 5280000 | I28: =SUM(I34:I1048576) -> 1130000 | J28: =SUM(J34:J1048576) -> 42700000 | K28: =SUM(K34:K1048576) -> 41570000
C29: PREMIUM RECEIVABLES FROM BROKERS
E30: Amount outstanding for | I30: Provision/ | J30: Total | K30: Net
D31: Name of the Broker | E31: Less than | F31: 30 days | G31: 90 days | H31: Over | I31: Bad Debts | J31: Gross | K31: Amount
E32: 30 days | F32: to 90 days | G32: to 6 months | H32: 6 months | I32: written off (KES) | J32: Amount
D33: (01) | E33: (02) | F33: (03) | G33: (04) | H33: (05) | I33: (06) | J33: (07)=(02)+(03)+(04)+(05) | K33: (08)=(07)-(06)
C34: =C33+1 -> 1 | D34: AA INSURANCE BROKER | E34: 2500000 | F34: 22000000 | G34: 12000000 | H34: 4000000 | I34: 1000000 | J34: =SUM(F34:H34) -> 38000000 | K34: =J34-I34 -> 37000000
C35: =C34+1 -> 2 | D35: BB INSURANCE BROKERS | E35: 3000000 | F35: 50000 | G35: 220000 | H35: 1200000 | I35: 50000 | J35: =SUM(E35:I35) -> 4520000 | K35: =J35-I35 -> 4470000
C36: =C35+1 -> 3 | D36: CC INSURANCE BROKERS | E36: 0 | F36: 5000 | G36: 15000 | H36: 80000 | I36: 80000 | J36: =SUM(E36:I36) -> 180000 | K36: =J36-I36 -> 100000
C37: =C36+1 -> 4 | J37: =SUM(E37:H37) -> 0 | K37: =J37-I37 -> 0
C38: =C37+1 -> 5 | J38: =SUM(E38:H38) -> 0 | K38: =J38-I38 -> 0
C39: =C38+1 -> 6 | J39: =SUM(E39:H39) -> 0 | K39: =J39-I39 -> 0
C40: =C39+1 -> 7 | J40: =SUM(E40:H40) -> 0 | K40: =J40-I40 -> 0
C41: =C40+1 -> 8 | J41: =SUM(E41:H41) -> 0 | K41: =J41-I41 -> 0
C42: =C41+1 -> 9 | J42: =SUM(E42:H42) -> 0 | K42: =J42-I42 -> 0
C43: =C42+1 -> 10 | J43: =SUM(E43:H43) -> 0 | K43: =J43-I43 -> 0
...
