Workbook
Name A_Million: Investments!$D$1
Name A_Thousand: Investments!$D$2
Name Val_Date: [1]INTRO!$E$23

Sheet Intro
C15: Pioneer General Insurance Limited
D17: Financial Condition Report — Working File
D21: Valuation Date | E21: 45291

Sheet Data
G1: From (Prem Analysis) Exposure Tab - Unique Policies Per Source File
B3: Pioneer General Insurance Limited Summary of Data Provided | G3: Pioneer General Insurance Limited Unique Policy Count
B4: Paid Claims Data | C4: Premium Data | D4: Outstanding Claims Data | H4: Underwriting Year
B5: Unique Policy Identifier | C5: Unique Policy Identifier | D5: Unique Policy Identifier | G5: Business Class | H5: 2017 | I5: 2018 | J5: =I5+1 -> 2019 | K5: =J5+1 -> 2020 | L5: 2021 | M5: =L5+1 -> 2022
B6: Class of Business | C6: Class of Business | D6: Class of Business | G6: Engineering | H6: 67 | I6: 202 | J6: 266 | K6: 247 | L6: 299 | M6: 324 | N6: =M6/J6-1 -> 0.21804511 | O6: =K6/J6-1 -> -0.071428571
B7: Inward/Outward Indicator | C7: Product Description | D7: Product Description | G7: Fire Domestic | H7: 141 | I7: 321 | J7: 364 | K7: 550 | L7: 431 | M7: 332 | N7: =M7/J7-1 -> -0.087912088 | O7: =K7/J7-1 -> 0.51098901
B8: Start Date of Cover Period | C8: Date of Loss | D8: Date of Accident | G8: Fire Industrial | H8: 220 | I8: 499 | J8: 572 | K8: 579 | L8: 594 | M8: 761 | N8: =M8/J8-1 -> 0.33041958 | O8: =K8/J8-1 -> 0.012237762
B9: End Date of Cover Period | C9: Date of Report | D9: Outstanding Claim Amount - Gross | G9: Liability | H9: 111 | I9: 377 | J9: 509 | K9: 503 | L9: 629 | M9: 693 | N9: =M9/J9-1 -> 0.36149312 | O9: =K9/J9-1 -> -0.011787819
B10: Gross written premium | C10: Date of Payment | D10: Outstanding Claim Amount - Reinsurance estimate | G10: Marine | H10: 556 | I10: 1148 | J10: 368 | K10: 260 | L10: 540 | M10: 335 | N10: =M10/J10-1 -> -0.089673913 | O10: =K10/J10-1 -> -0.29347826
B11: Reinsurance Premium Amount Paid | C11: Amount of Gross Claim Payment | G11: Miscellaneous | H11: 207 | I11: 368 | J11: 246 | K11: 201 | L11: 688 | M11: 311 | N11: =M11/J11-1 -> 0.26422764 | O11: =K11/J11-1 -> -0.18292683
B12: Commissions Paid | C12: Amount of Reinsurance Recovery | G12: Motor Commercial | H12: 511 | I12: 2422 | J12: 3281 | K12: 3478 | L12: 5462 | M12: 6454 | N12: =M12/J12-1 -> 0.96708321 | O12: =K12/J12-1 -> 0.06004267
G13: Motor Private | H13: 1702 | I13: 7323 | J13: 11676 | K13: 14306 | L13: 21996 | M13: 22849 | N13: =M13/J13-1 -> 0.95692018 | O13: =K13/J13-1 -> 0.22524837
B14: Other General Information | G14: Personal Accident | H14: 106 | I14: 555 | J14: 1246 | K14: 938 | L14: 949 | M14: 1047 | N14: =M14/J14-1 -> -0.15971108 | O14: =K14/J14-1 -> -0.24719101
B15: Organization Structure, including Board details | G15: Theft | H15: 78 | I15: 208 | J15: 435 | K15: 348 | L15: 534 | M15: 1107 | N15: =M15/J15-1 -> 1.5448276 | O15: =K15/J15-1 -> -0.2
B16: Risk Management strategy | G16: Workmen's Compensation | H16: 65 | I16: 223 | J16: 298 | K16: 313 | L16: 402 | M16: 420 | N16: =M16/J16-1 -> 0.40939597 | O16: =K16/J16-1 -> 0.05033557
B17: Reinsurance Strategy and Treaties (2022 & 2023) | G17: TOTAL | H17: =SUM(H6:H16) -> 3764 | I17: =SUM(I6:I16) -> 13646 | J17: =SUM(J6:J16) -> 19261 | K17: 21723 | L17: 32524 | M17: =SUM(M6:M16) -> 34633 | N17: =M17/J17-1 -> 0.7980894 | O17: =K17/J17-1 -> 0.12782306
B18: Underwriting Manual | I18: =I17/H17-1 -> 2.6253985 | J18: =J17/I17-1 -> 0.41147589 | K18: =K17/J17-1 -> 0.12782306 | L18: =L17/K17-1 -> 0.49721493 | M18: =M17/L17-1 -> 0.064844423
B19: Claims Manual

Sheet Data_Recon
B4: Pioneer General Insurance Limited | H4: Pioneer General Insurance Limited | N4: Pioneer General Insurance Limited | T4: Pioneer General Insurance Limited
B5: Premium Data Variation Checks as at 31 December 2023 | H5: Summary of Claims Valuation Data as at 31 December 2023 | N5: Premium Data Variation Checks as at 31 December 2022 | T5: Summary of Claims Valuation Data as at 31 December 2022
B6: Business Class | C6: Gross Written Premium | H6: Business Class | I6: Paid Claims | N6: Business Class | O6: Gross Written Premium | T6: Business Class | U6: Paid Claims
C7: Data | D7: Financials | E7: Variation | I7: Data | J7: Financials | K7: Variation | O7: Data | P7: Financials | Q7: Variation | U7: Data | V7: Financials | W7: Variation
B8: Engineering | C8: 32682894 | D8: =_xlfn.XLOOKUP(B8,RA!$C$8:$N$8,RA!$C$9:$N$9) -> 32682894 | E8: =IFERROR(C9/D8-1,0) -> -0.66998492 | H8: Engineering | I8: 1696807 | J8: =_xlfn.XLOOKUP(H8,RA!$C$8:$N$8,RA!$C$19:$N$19) -> 1418131 | K8: =I8/J8-1 -> 0.19650935 | N8: Engineering | O8: 40945277 | P8: =_xlfn.XLOOKUP(N8,RA!$C$8:$N$8,RA!$C$44:$N$44) -> 40945277 | Q8: =IFERROR(O8/P8-1,0) -> 0 | T8: Engineering | U8: 3670143 | V8: =_xlfn.XLOOKUP(T8,RA!$C$8:$N$8,RA!$C$54:$N$54) -> 3851902 | W8: =U8/V8-1 -> -0.047186818
B9: Fire Domestic | C9: 10785848 | D9: =_xlfn.XLOOKUP(B9,RA!$C$8:$N$8,RA!$C$9:$N$9) -> 10785848 | E9: =IFERROR(C10/D9-1,0) -> 6.0699136 | H9: Fire Domestic | I9: 1111024 | J9: =_xlfn.XLOOKUP(H9,RA!$C$8:$N$8,RA!$C$19:$N$19) -> 1842476 | K9: =I9/J9-1 -> -0.39699404 | N9: Fire Domestic | O9: 8873879 | P9: =_xlfn.XLOOKUP(N9,RA!$C$8:$N$8,RA!$C$44:$N$44) -> 8873879 | Q9: =IFERROR(O9/P9-1,0) -> 0 | T9: Fire Domestic | U9: 436821 | V9: =_xlfn.XLOOKUP(T9,RA!$C$8:$N$8,RA!$C$54:$N$54) -> 435021 | W9: =U9/V9-1 -> 0.0041377313
B10: Fire Industrial | C10: 76255014 | D10: =_xlfn.XLOOKUP(B10,RA!$C$8:$N$8,RA!$C$9:$N$9) -> 76255014 | E10: =IFERROR(C11/D10-1,0) -> -0.47670735 | H10: Fire Industrial | I10: 13983797 | J10: =_xlfn.XLOOKUP(H10,RA!$C$8:$N$8,RA!$C$19:$N$19) -> 32243776 | K10: =I10/J10-1 -> -0.56631019 | N10: Fire Industrial | O10: 78279579 | P10: =_xlfn.XLOOKUP(N10,RA!$C$8:$N$8,RA!$C$44:$N$44) -> 78279579 | Q10: =IFERROR(O10/P10-1,0) -> 0 | T10: Fire Industrial | U10: 2535775 | V10: =_xlfn.XLOOKUP(T10,RA!$C$8:$N$8,RA!$C$54:$N$54) -> 2535775 | W10: =U10/V10-1 -> 0
B11: Liability | C11: 39903688 | D11: =_xlfn.XLOOKUP(B11,RA!$C$8:$N$8,RA!$C$9:$N$9) -> 39903688 | E11: =IFERROR(C12/D11-1,0) -> -0.6984694 | H11: Liability | I11: 7875581 | J11: =_xlfn.XLOOKUP(H11,RA!$C$8:$N$8,RA!$C$19:$N$19) -> 4746034 | K11: =I11/J11-1 -> 0.65940257 | N11: Liability | O11: 34436388 | P11: =_xlfn.XLOOKUP(N11,RA!$C$8:$N$8,RA!$C$44:$N$44) -> 34436388 | Q11: =IFERROR(O11/P11-1,0) -> 0 | T11: Liability | U11: 3684013 | V11: =_xlfn.XLOOKUP(T11,RA!$C$8:$N$8,RA!$C$54:$N$54) -> 3684013 | W11: =U11/V11-1 -> 0
B12: Marine | C12: 12032183 | D12: =_xlfn.XLOOKUP(B12,RA!$C$8:$N$8,RA!$C$9:$N$9) -> 12032183 | E12: =IFERROR(C13/D12-1,0) -> -0.54699384 | H12: Marine | I12: 0 | J12: =_xlfn.XLOOKUP(H12,RA!$C$8:$N$8,RA!$C$19:$N$19) -> 3277913 | K12: =I12/J12-1 -> -1 | N12: Marine | O12: 12488935 | P12: =_xlfn.XLOOKUP(N12,RA!$C$8:$N$8,RA!$C$44:$N$44) -> 12488935 | Q12: =IFERROR(O12/P12-1,0) -> 0 | T12: Marine | U12: 3262515 | V12: =_xlfn.XLOOKUP(T12,RA!$C$8:$N$8,RA!$C$54:$N$54) -> 3262515 | W12: =U12/V12-1 -> 0
B13: Miscellaneous | C13: 5450653 | D13: =_xlfn.XLOOKUP(B13,RA!$C$8:$N$8,RA!$C$9:$N$9) -> 5450653 | E13: =IFERROR(C14/D13-1,0) -> 67.086712 | H13: Miscellaneous | I13: 1465774 | J13: =_xlfn.XLOOKUP(H13,RA!$C$8:$N$8,RA!$C$19:$N$19) -> 30087 | K13: =I13/J13-1 -> 47.717852 | N13: Miscellaneous | O13: 19171387 | P13: =_xlfn.XLOOKUP(N13,RA!$C$8:$N$8,RA!$C$44:$N$44) -> 19171387 | Q13: =IFERROR(O13/P13-1,0) -> 0 | T13: Miscellaneous | U13: 711302 | V13: =_xlfn.XLOOKUP(T13,RA!$C$8:$N$8,RA!$C$54:$N$54) -> 299905 | W13: =U13/V13-1 -> 1.3717577
B14: Motor Commercial | C14: 371117040 | D14: =_xlfn.XLOOKUP(B14,RA!$C$8:$N$8,RA!$C$9:$N$9) -> 371117040 | E14: =IFERROR(C15/D14-1,0) -> 1.467254 | H14: Motor Commercial | I14: 221638337 | J14: =_xlfn.XLOOKUP(H14,RA!$C$8:$N$8,RA!$C$19:$N$19) -> 290849318 | K14: =I14/J14-1 -> -0.23796164 | N14: Motor Commercial | O14: 305362725 | P14: =_xlfn.XLOOKUP(N14,RA!$C$8:$N$8,RA!$C$44:$N$44) -> 305362726 | Q14: =IFERROR(O14/P14-1,0) -> -3.2747939e-09 | T14: Motor Commercial | U14: 170846151 | V14: =_xlfn.XLOOKUP(T14,RA!$C$8:$N$8,RA!$C$54:$N$54) -> 168089826 | W14: =U14/V14-1 -> 0.016397929
B15: Motor Private | C15: 915640011 | D15: =_xlfn.XLOOKUP(B15,RA!$C$8:$N$8,RA!$C$9:$N$9) -> 915640011 | E15: =IFERROR(C16/D15-1,0) -> -0.98977804 | H15: Motor Private | I15: 496327594 | J15: =_xlfn.XLOOKUP(H15,RA!$C$8:$N$8,RA!$C$19:$N$19) -> 611465508 | K15: =I15/J15-1 -> -0.1882983 | N15: Motor Private | O15: 818548381 | P15: =_xlfn.XLOOKUP(N15,RA!$C$8:$N$8,RA!$C$44:$N$44) -> 818548382 | Q15: =IFERROR(O15/P15-1,0) -> -1.2216749e-09 | T15: Motor Private | U15: 534598589 | V15: =_xlfn.XLOOKUP(T15,RA!$C$8:$N$8,RA!$C$54:$N$54) -> 527547701 | W15: =U15/V15-1 -> 0.013365404
B16: Personal Accident | C16: 9359638 | D16: =_xlfn.XLOOKUP(B16,RA!$C$8:$N$8,RA!$C$9:$N$9) -> 9359638 | E16: =IFERROR(C17/D16-1,0) -> 0.8117549 | H16: Personal Accident | I16: 1370079 | J16: =_xlfn.XLOOKUP(H16,RA!$C$8:$N$8,RA!$C$19:$N$19) -> 1250041 | K16: =I16/J16-1 -> 0.09602725 | N16: Personal Accident | O16: 7134489 | P16: =_xlfn.XLOOKUP(N16,RA!$C$8:$N$8,RA!$C$44:$N$44) -> 7134489 | Q16: =IFERROR(O16/P16-1,0) -> 0 | T16: Personal Accident | U16: 506105 | V16: =_xlfn.XLOOKUP(T16,RA!$C$8:$N$8,RA!$C$54:$N$54) -> 506105 | W16: =U16/V16-1 -> 0
B17: Theft | C17: 16957370 | D17: =_xlfn.XLOOKUP(B17,RA!$C$8:$N$8,RA!$C$9:$N$9) -> 16957370 | E17: =IFERROR(C18/D17-1,0) -> 5.2147394 | H17: Theft | I17: 192755 | J17: =_xlfn.XLOOKUP(H17,RA!$C$8:$N$8,RA!$C$19:$N$19) -> 702509 | K17: =I17/J17-1 -> -0.72561917 | N17: Theft | O17: 14671830 | P17: =_xlfn.XLOOKUP(N17,RA!$C$8:$N$8,RA!$C$44:$N$44) -> 14671830 | Q17: =IFERROR(O17/P17-1,0) -> 0 | T17: Theft | U17: 600134 | V17: =_xlfn.XLOOKUP(T17,RA!$C$8:$N$8,RA!$C$54:$N$54) -> 600134 | W17: =U17/V17-1 -> 0
B18: Workmen's Compensation | C18: 105385636 | D18: =_xlfn.XLOOKUP(B18,RA!$C$8:$N$8,RA!$C$9:$N$9) -> 105385636 | E18: =IFERROR(C19/D18-1,0) -> 14.140298 | H18: Workmen's Compensation | I18: 47855391 | J18: =_xlfn.XLOOKUP(H18,RA!$C$8:$N$8,RA!$C$19:$N$19) -> 64293934 | K18: =I18/J18-1 -> -0.25567798 | N18: Workmen's Compensation | O18: 295958506 | P18: =_xlfn.XLOOKUP(N18,RA!$C$8:$N$8,RA!$C$44:$N$44) -> 295958506 | Q18: =IFERROR(O18/P18-1,0) -> 0 | T18: Workmen's Compensation | U18: 18455701 | V18: =_xlfn.XLOOKUP(T18,RA!$C$8:$N$8,RA!$C$54:$N$54) -> 18623238 | W18: =U18/V18-1 -> -0.0089961262
B19: TOTAL | C19: 1595569975 | D19: =SUM(D8:D18) -> 1595569975 | E19: =IFERROR(#REF!/D19-1,0) -> 0 | H19: TOTAL | I19: 793517139 | J19: =SUM(J8:J18) -> 1012119727 | K19: =I19/J19-1 -> -0.21598491 | N19: TOTAL | O19: 1635871377 | P19: =SUM(P8:P18) -> 1635871378 | Q19: =IFERROR(O19/P19-1,0) -> -6.1129501e-10 | T19: TOTAL | U19: 745397273 | V19: =SUM(V8:V18) -> 729436135 | W19: =U19/V19-1 -> 0.021881474
B25: Pioneer General Insurance Limited | N25: Pioneer General Insurance Limited
B26: Summary of Historical Paid Claims Data | N26: Summary of Historical Paid Claims Data
B27: Year | C27: Data | D27: Financials | E27: Variation | N27: Year | O27: Data | P27: Financials | Q27: Variation
B28: 2017 | C28: 16693084 | D28: 16445890 | E28: -0.01 | N28: 2017 | O28: 16693084 | P28: 16445890 | Q28: -0.01
B29: 2018 | C29: 203087756 | D29: 203183186 | E29: 0 | N29: 2018 | O29: 203087756 | P29: 203183186 | Q29: 0
B30: 2019 | C30: 333749230 | D30: 333775300 | E30: 0 | N30: 2019 | O30: 333749230 | P30: 333775300 | Q30: 0
B31: 2020 | C31: 410615315 | D31: 402655339 | E31: -0.02 | N31: 2020 | O31: 410615315 | P31: 402655339 | Q31: -0.02
B32: 2021 | C32: 513592593 | D32: 520243988 | E32: 0.01 | N32: 2021 | O32: 513592593 | P32: 520243988 | Q32: 0.01
B33: 2022 | C33: =U19 -> 745397273 | D33: =V19 -> 729436135 | E33: =C33/D33-1 -> 0.021881474 | N33: 2022 | O33: =U19 -> 745397273 | P33: =V19 -> 729436135 | Q33: =O33/P33-1 -> 0.021881474
B34: 2023 | C34: =I19 -> 793517139 | D34: =J19 -> 1012119727 | E34: =C34/D34-1 -> -0.21598491 | N34: 2023 | O34: =I19 -> 793517139 | P34: =J19 -> 1012119727 | Q34: =O34/P34-1 -> -0.21598491

Sheet Stakeholders
B5: Pioneer General Insurance Company Shareholders and Directors | L5: Pioneer General Insurance Limited
B6: Name | C6: Description | D6: Nationality/Location | E6: Ordinary Shares | F6: Stake | L6: Management Team
B7: Pioneer Insurance Holdings | C7: Shareholder | D7: Kenya | E7: 360000 | F7: 0.6 | L7: Title | M7: Name
B8: Parkview Inv. Ltd | C8: Shareholder | D8: Dubai | E8: 120000 | F8: 0.2 | L8: Managing Director | M8: Ms. Milcah Kinyua
B9: Medillon Trading FZE | C9: Shareholder | D9: Dubai | E9: 78000 | F9: 0.13 | L9: Assistant General Manager - Operations | M9: Mrs. Anne Muhindi
B10: Abcon Int. LLC | C10: Shareholder | D10: Dubai | E10: 42000 | F10: 0.07 | L10: Underwriting Manager | M10: Stephen Okeyo
B11: Brigid Cherono | C11: Director | D11: Kenyan | E11: - | F11: 0 | L11: Claims Manager | M11: Gershom Mulwa Mutua
B12: Michael Mure | C12: Director | D12: Kenyan | E12: - | F12: 0 | L12: Business Development Manager | M12: Chris G. Mbugua
B13: Moses Kimani | C13: Director | D13: Kenyan | E13: - | F13: 0 | L13: Finance Manager | M13: Ms. Flora Muthomi
B14: Shiraz A. Jeraj | C14: Director | D14: Kenyan | E14: - | F14: 0 | L14: Head of Human Resources & Administration | M14: Ms. Margaret Mwashimba
B15: Wamuyu Catherine | C15: Director | D15: Kenyan | E15: - | F15: 0 | L15: ICT Manager | M15: Stephen Masinde
B16: Total Shares | E16: 600000 | F16: 1

Sheet Reserves
B2: Refer to the IBNR Computations in Valuation Working Files
B6: FORM NO. INS57-lb
B7: GENERAL BUSINESS OF PIONEER GENERAL INSURANCE LIMITED
B8: SUMMARY OF DISCOUNTED RESERVES AND THE VALUATION OF POLICIES AS AT 31 DECEMBER 2023
C10: Gross Discounted Technical Reserve | H10: Net Discounted Technical Reserve
B11: Insurance Business | C11: Outstanding Claims Reported | D11: Incurred But Not Reported (IBNR) Claims Reserves* | E11: Liability for Remaining Coverage | F11: Loss Component | G11: Total Gross Technical Reserves | H11: Outstanding Claims Reported | I11: Incurred But Not Reported (IBNR) Claims Reserves* | J11: Liability for Remaining Coverage | K11: Loss Component | L11: Total Net Technical Reserves
B12: Engineering | C12: 720888 | D12: 1129958.7 | E12: 11751170 | F12: 0 | G12: 13602017 | H12: 244194 | I12: 773696.78 | J12: 8046177.2 | K12: 0 | L12: 9064068
B13: Fire Domestic | C13: 1053592 | D13: 100635.35 | E13: 4275813.2 | F13: 0 | G13: 5430040.5 | H13: 1053592 | I13: 95221.165 | J13: 3771743.4 | K13: 0 | L13: 4920556.5
B14: Fire Industrial | C14: 22370600 | D14: 3772967.5 | E14: 35502836 | F14: 0 | G14: 61646403 | H14: 2023004.6 | I14: 1345416 | J14: 12660085 | K14: 0 | L14: 16028506
B15: Liability | C15: 7876415.6 | D15: 3151354.2 | E15: 22751668 | F15: 0 | G15: 33779437 | H15: 3924366.5 | I15: 2920878.8 | J15: 21087714 | K15: 0 | L15: 27932959
B16: Marine | C16: 3277913.4 | D16: 271069.47 | E16: 1041311 | F16: 0 | G16: 4590293.8 | H16: 3182556.4 | I16: 263183.61 | J16: 816734.8 | K16: 0 | L16: 4262474.8
B17: Miscellaneous | C17: 304072.06 | D17: 240982.05 | E17: 3420439.5 | F17: 0 | G17: 3965493.6 | H17: 304072.06 | I17: 209362.22 | J17: 2971636.9 | K17: 0 | L17: 3485071.1
B18: Motor Commercial | C18: 1.8108534e+08 | D18: 56238267 | E18: 1.264396e+08 | F18: 10555188 | G18: 3.7431839e+08 | H18: 1.4720465e+08 | I18: 56101688 | J18: 1.2609261e+08 | K18: 10529554 | L18: 3.399285e+08
B19: Motor Private | C19: 3.9336455e+08 | D19: 1.6468584e+08 | E19: 3.44562e+08 | F19: 27871187 | G19: 9.3048358e+08 | H19: 3.6240602e+08 | I19: 1.6438035e+08 | J19: 3.4353663e+08 | K19: 27819485 | L19: 8.9814249e+08
B20: Personal Accident | C20: 756365.79 | D20: 1158921.1 | E20: 3428032 | F20: 0 | G20: 5343318.9 | H20: 747712.97 | I20: 953278.03 | J20: 2819750.7 | K20: 0 | L20: 4520741.7
B21: Theft | C21: 829305.44 | D21: 668503.4 | E21: 8116281.3 | F21: 0 | G21: 9614090.1 | H21: 829305.44 | I21: 668503.15 | J21: 6313782 | K21: 0 | L21: 7811590.6
B22: Workmen's Compensation | C22: 40111080 | D22: 3.0488615e+08 | E22: 1.2253209e+08 | F22: 0 | G22: 4.6752932e+08 | H22: 20355942 | I22: 2.7964555e+08 | J22: 40060419 | K22: 0 | L22: 3.4006191e+08
B23: Total Business | C23: 6.5175012e+08 | D23: 5.3630465e+08 | E23: 6.8382124e+08 | F23: 38426375 | G23: 1.9103024e+09 | H23: 5.4227542e+08 | I23: 5.0735713e+08 | J23: 5.6817728e+08 | K23: 38349039 | L23: 1.6561589e+09
B24: *Includes Incurred But Not Enough Reported Claims Reserve & Risk Margin
D25: =D23/SUM(C23:D23) -> 0.45141408
H28: =SUM(H30:H31)=C23+D23 -> TRUE | I28: =SUM(I30:I31)=F23+E23 -> TRUE
G29: Gross | H29: Claims Reserves | I29: Premium Reserves
G30: Motor Classes | H30: =SUM(C18:D19) -> 7.95374e+08 | I30: =SUM(E18:E19,F23) -> 5.0942797e+08
G31: Non-Motor Classes | H31: =SUM(C23:D23)-H30 -> 3.9268077e+08 | I31: =SUM(E23:F23)-I30 -> 2.1281964e+08
H32: =SUM(H34:H35)=H23+I23 -> TRUE | I32: =SUM(I34:I35)=K23+J23 -> TRUE
G33: Net | H33: Claims Reserves | I33: Premium Reserves
G34: Motor Classes | H34: =SUM(H18:I19) -> 7.3009271e+08 | I34: =SUM(J18:J19,K23) -> 5.0797828e+08
G35: Non-Motor Classes | H35: =SUM(H23:I23)-H34 -> 3.1953984e+08 | I35: =SUM(J23:K23)-I34 -> 98548043
H38: =H30/SUM(H30:H31) -> 0.66947587 | I38: =I30/SUM(I30:I31) -> 0.70533701
H39: =H34/SUM(H34:H35) -> 0.69556981 | I39: =I34/SUM(I34:I35) -> 0.83752058

Sheet Reinsurance
E2: Pioneer General Insurance Limited
E3: Summary of Reinsurance Treaties (in Kes M)
E4: Form & Type of Reinsurance | G4: Class of Insurance | H4: Pioneer General | L4: Reinsurers | P4: Treaty Capacity
H5: 2023 | J5: 2024 | L5: 2023 | N5: 2024
H6: %/Lines | I6: Limit | J6: %/Lines | K6: Limit | L6: %/Lines | M6: Limit | N6: %/Lines | O6: Limit | P6: 2023 | Q6: 2024
E7: Proportional Business | F7: Surplus | G7: Fire & Engineering | H7: 1 | I7: 50 | J7: 1 | K7: 50 | L7: 15 | M7: 750 | N7: 20 | O7: 1000 | P7: 800 | Q7: 1050
G8: Personal Accident & WIBA
G9: Any one Loss | H9: 1 | I9: 10 | J9: 1 | K9: 10 | L9: 25 | M9: 250 | N9: 25 | O9: 250 | P9: 260 | Q9: 260
G10: Known Accumulation | H10: 1 | I10: 20 | J10: 1 | K10: 20 | L10: 25 | M10: 500 | N10: 25 | O10: 500 | P10: 520 | Q10: 520
G11: Marine
G12: Cargo | H12: 1 | I12: 50 | J12: 1 | K12: 50 | L12: 6 | M12: 300 | N12: 6 | O12: 300 | P12: 350 | Q12: 350
G13: Hull | H13: 1 | I13: 6 | J13: 1 | K13: 6 | L13: 5 | M13: 30 | N13: 5 | O13: 30 | P13: 36 | Q13: 36
F14: Quota Share | G14: Bonds & Guarantees
G15: Any one bond | H15: 0.2 | I15: 12 | J15: 0.2 | K15: 12 | L15: 0.8 | M15: 48 | N15: 0.8 | O15: 48 | P15: 60 | Q15: 60
G16: Any one contractor | H16: 0.2 | I16: 30 | J16: 0.2 | K16: 30 | L16: 0.8 | M16: 120 | N16: 0.8 | O16: 120 | P16: 150 | Q16: 150
G17: Terrorism & Political Risks | H17: 0.2 | I17: 60 | J17: 0.2 | K17: 100 | L17: 0.8 | M17: 240 | N17: 0.8 | O17: 400 | P17: 300 | Q17: 500
G18: Travel | H18: 0.1 | J18: 0.1 | L18: 0.9 | N18: 0.9
E21: Non-Proportional Business | F21: Excess of Loss | G21: Fire & Engineering | I21: 15 | K21: 15 | M21: 485 | O21: 485 | P21: 500 | Q21: 500
G22: Motor, Marine, Accident & Liability | I22: 5 | K22: 5 | M22: 295 | O22: 295 | P22: 300 | Q22: 300
E29: Pioneer General Insurance Limited
E30: Summary of Reinsurance Treaties (Amounts in KES M)
E31: Form & Type of Reinsurance | G31: Class of Insurance | H31: Pioneer General | L31: Reinsurers | P31: Treaty Capacity
H32: 2022 | J32: 2023 | L32: 2022 | N32: 2023
H33: %/Lines | I33: Limit | J33: %/Lines | K33: Limit | L33: %/Lines | M33: Limit | N33: %/Lines | O33: Limit | P33: 2022 | Q33: 2023
E34: Proportional Business | F34: Surplus | G34: Fire & Engineering | H34: 1 | I34: 50 | J34: 1 | K34: 30 | L34: 14 | M34: 700 | N34: 29 | O34: 870 | P34: 750 | Q34: 900
G35: Personal Accident & WIBA
G36: Any one Loss | H36: 1 | I36: 10 | J36: 1 | K36: 10 | L36: 14 | M36: 140 | N36: 24 | O36: 240 | P36: 150 | Q36: 250
G37: Known Accumulation | H37: 1 | I37: 20 | J37: 1 | K37: 20 | L37: 14 | M37: 280 | N37: 24 | O37: 480 | P37: 300 | Q37: 500
G38: Marine
G39: Cargo | H39: 1 | I39: 50 | J39: 1 | K39: 50 | L39: 5 | M39: 250 | N39: 5 | O39: 250 | P39: 300 | Q39: 300
G40: Hull | H40: 1 | I40: 6 | J40: 1 | K40: 6 | L40: 4 | M40: 24 | N40: 4 | O40: 24 | P40: 30 | Q40: 30
F41: Quota Share | G41: Bonds & Guarantees
G42: Any one bond | H42: 0.2 | I42: 12 | J42: 0.2 | K42: 12 | L42: 0.8 | M42: 48 | N42: 0.8 | O42: 48 | P42: 60 | Q42: 60
G43: Any one contractor | H43: 0.2 | I43: 30 | J43: 0.2 | K43: 30 | L43: 0.8 | M43: 120 | N43: 0.8 | O43: 120 | P43: 150 | Q43: 150
G44: Terrorism & Political Risks | H44: 0.2 | I44: 40 | J44: 0.2 | K44: 40 | L44: 0.8 | M44: 160 | N44: 0.8 | O44: 160 | P44: 200 | Q44: 200
G45: Travel
G46: Aviation | J46: 0.1 | K46: 10 | N46: 0.9 | O46: 90 | Q46: 100
E48: Non-Proportional Business | F48: Excess of Loss | G48: Fire & Engineering | I48: 15 | K48: 15 | M48: 485 | O48: 485 | P48: 500 | Q48: 500
G49: Motor, Marine, Accident & Liability | I49: 3 | K49: 4 | M49: 297 | O49: 296 | P49: 300 | Q49: 300

Sheet Ratios
C5: Pioneer General Insurance Limited Key Net Ratio Analysis - 2017 | J5: Pioneer General Insurance Limited Management Expense Amounts (KES '000) | S5: Pioneer General Insurance Limited Management Expense Ratios (2018 - 2023)
C6: Class | D6: Loss Ratios | E6: Commission Ratios | F6: Expense Ratios | G6: Combined Ratio | J6: Class | K6: 2017 | L6: =K6+1 -> 2018 | M6: =L6+1 -> 2019 | N6: =M6+1 -> 2020 | O6: 2021 | P6: 2022 | Q6: 2023 | S6: Class | T6: 2017 | U6: =T6+1 -> 2018 | V6: =U6+1 -> 2019 | W6: =V6+1 -> 2020 | X6: 2021 | Y6: 2022 | Z6: 2023 | AB6: 2018 | AC6: 2019 | AD6: 2020 | AE6: 2021 | AF6: 2022 | AG6: 2023
C7: Engineering | D7: =HLOOKUP($C7,RA!$D$244:$O$248,2,0) -> 0.34107794 | E7: =HLOOKUP($C7,RA!$D$244:$O$248,3,0) -> -0.21516982 | F7: =HLOOKUP($C7,RA!$D$244:$O$248,4,0) -> 0.75330162 | G7: =SUM(D7:F7) -> 0.87920975 | J7: Engineering | K7: =HLOOKUP($J7,RA!$D$219:$O$241,19,0) -> 979552 | L7: =HLOOKUP($J7,RA!$D$184:$O$209,22,0) -> 4858196.6 | M7: =HLOOKUP($J7,RA!$D$148:$O$173,22,0) -> 5245342.3 | N7: =HLOOKUP($J7,RA!$B$113:$O$144,21,0) -> 5588180.5 | O7: =_xlfn.XLOOKUP(J7,RA!$C$78:$N$78,RA!$C$98:$N$98) -> 4234328.4 | P7: =HLOOKUP($J7,RA!$B$43:$O$74,21,0) -> 9129181.9 | Q7: =HLOOKUP($J7,RA!$B$8:$O$39,21,0) -> 9043615.1 | S7: Engineering | T7: =HLOOKUP($S7,RA!$D$244:$O$248,4,0) -> 0.75330162 | U7: =HLOOKUP($S7,RA!$D$212:$O$216,4,0) -> 1.2993485 | V7: =HLOOKUP($S7,RA!$D$176:$O$180,4,0) -> 0.56924266 | W7: =HLOOKUP($S7,RA!$B$140:$O$144,4,0) -> 0.63398977 | X7: =_xlfn.XLOOKUP(S7,RA!$C$78:$N$78,RA!$C$108:$N$108) -> 0.36232679 | Y7: =HLOOKUP($S7,RA!$B$70:$O$74,4,0) -> 0.59310099 | Z7: =HLOOKUP($S7,RA!$B$35:$O$39,4,0) -> 0.39998375 | AB7: =U7-T7 -> 0.54604692 | AC7: =V7-U7 -> -0.73010588 | AD7: =W7-V7 -> 0.064747112 | AE7: =X7-W7 -> -0.27166299 | AF7: =Y7-X7 -> 0.23077421 | AG7: =Z7-Y7 -> -0.19311725
C8: Fire Domestic | D8: =HLOOKUP($C8,RA!$D$244:$O$248,2,0) -> 0.20194533 | E8: =HLOOKUP($C8,RA!$D$244:$O$248,3,0) -> 0.1185166 | F8: =HLOOKUP($C8,RA!$D$244:$O$248,4,0) -> 4.0337687 | G8: =SUM(D8:F8) -> 4.3542307 | J8: Fire Domestic | K8: =HLOOKUP($J8,RA!$D$219:$O$241,19,0) -> 2938657 | L8: =HLOOKUP($J8,RA!$D$184:$O$209,22,0) -> 2996730.9 | M8: =HLOOKUP($J8,RA!$D$148:$O$173,22,0) -> 3256838.8 | N8: =HLOOKUP($J8,RA!$B$113:$O$144,21,0) -> 2605813.4 | O8: =_xlfn.XLOOKUP(J8,RA!$C$78:$N$78,RA!$C$98:$N$98) -> 2180353.4 | P8: =HLOOKUP($J8,RA!$B$43:$O$74,21,0) -> 1978525 | Q8: =HLOOKUP($J8,RA!$B$8:$O$39,21,0) -> 2984529.4 | S8: Fire Domestic | T8: =HLOOKUP($S8,RA!$D$244:$O$248,4,0) -> 4.0337687 | U8: =HLOOKUP($S8,RA!$D$212:$O$216,4,0) -> 1.585457 | V8: =HLOOKUP($S8,RA!$D$176:$O$180,4,0) -> 0.38173936 | W8: =HLOOKUP($S8,RA!$B$140:$O$144,4,0) -> 0.25409067 | X8: =_xlfn.XLOOKUP(S8,RA!$C$78:$N$78,RA!$C$108:$N$108) -> 0.34281995 | Y8: =HLOOKUP($S8,RA!$B$70:$O$74,4,0) -> 0.34694921 | Z8: =HLOOKUP($S8,RA!$B$35:$O$39,4,0) -> 0.32011116 | AB8: =U8-T8 -> -2.4483118 | AC8: =V8-U8 -> -1.2037176 | AD8: =W8-V8 -> -0.12764869 | AE8: =X8-W8 -> 0.088729281 | AF8: =Y8-X8 -> 0.0041292598 | AG8: =Z8-Y8 -> -0.026838049
C9: Fire Industrial | D9: =HLOOKUP($C9,RA!$D$244:$O$248,2,0) -> 0.11835056 | E9: =HLOOKUP($C9,RA!$D$244:$O$248,3,0) -> -0.35021924 | F9: =HLOOKUP($C9,RA!$D$244:$O$248,4,0) -> 1.2508289 | G9: =SUM(D9:F9) -> 1.0189602 | J9: Fire Industrial | K9: =HLOOKUP($J9,RA!$D$219:$O$241,19,0) -> 4897762 | L9: =HLOOKUP($J9,RA!$D$184:$O$209,22,0) -> 17238341 | M9: =HLOOKUP($J9,RA!$D$148:$O$173,22,0) -> 18174754 | N9: =HLOOKUP($J9,RA!$B$113:$O$144,21,0) -> 19278172 | O9: =_xlfn.XLOOKUP(J9,RA!$C$78:$N$78,RA!$C$98:$N$98) -> 12661741 | P9: =HLOOKUP($J9,RA!$B$43:$O$74,21,0) -> 17453259 | Q9: =HLOOKUP($J9,RA!$B$8:$O$39,21,0) -> 21100365 | S9: Fire Industrial | T9: =HLOOKUP($S9,RA!$D$244:$O$248,4,0) -> 1.2508289 | U9: =HLOOKUP($S9,RA!$D$212:$O$216,4,0) -> 2.2683675 | V9: =HLOOKUP($S9,RA!$D$176:$O$180,4,0) -> 1.5760211 | W9: =HLOOKUP($S9,RA!$B$140:$O$144,4,0) -> 1.4582014 | X9: =_xlfn.XLOOKUP(S9,RA!$C$78:$N$78,RA!$C$108:$N$108) -> 0.74343312 | Y9: =HLOOKUP($S9,RA!$B$70:$O$74,4,0) -> 0.94560067 | Z9: =HLOOKUP($S9,RA!$B$35:$O$39,4,0) -> 0.87692619 | AB9: =U9-T9 -> 1.0175386 | AC9: =V9-U9 -> -0.69234643 | AD9: =W9-V9 -> -0.11781972 | AE9: =X9-W9 -> -0.71476825 | AF9: =Y9-X9 -> 0.20216754 | AG9: =Z9-Y9 -> -0.068674475
C10: Liability | D10: =HLOOKUP($C10,RA!$D$244:$O$248,2,0) -> 0.16550506 | E10: =HLOOKUP($C10,RA!$D$244:$O$248,3,0) -> 0.2287398 | F10: =HLOOKUP($C10,RA!$D$244:$O$248,4,0) -> 0.77660657 | G10: =SUM(D10:F10) -> 1.1708514 | J10: Liability | K10: =HLOOKUP($J10,RA!$D$219:$O$241,19,0) -> 1959105 | L10: =HLOOKUP($J10,RA!$D$184:$O$209,22,0) -> 9258901.7 | M10: =HLOOKUP($J10,RA!$D$148:$O$173,22,0) -> 12328622 | N10: =HLOOKUP($J10,RA!$B$113:$O$144,21,0) -> 10312228 | O10: =_xlfn.XLOOKUP(J10,RA!$C$78:$N$78,RA!$C$98:$N$98) -> 9098653.7 | P10: =HLOOKUP($J10,RA!$B$43:$O$74,21,0) -> 7677956.4 | Q10: =HLOOKUP($J10,RA!$B$8:$O$39,21,0) -> 11041666 | S10: Liability | T10: =HLOOKUP($S10,RA!$D$244:$O$248,4,0) -> 0.77660657 | U10: =HLOOKUP($S10,RA!$D$212:$O$216,4,0) -> 0.63275899 | V10: =HLOOKUP($S10,RA!$D$176:$O$180,4,0) -> 0.44846347 | W10: =HLOOKUP($S10,RA!$B$140:$O$144,4,0) -> 0.29912443 | X10: =_xlfn.XLOOKUP(S10,RA!$C$78:$N$78,RA!$C$108:$N$108) -> 0.26725141 | Y10: =HLOOKUP($S10,RA!$B$70:$O$74,4,0) -> 0.24780634 | Z10: =HLOOKUP($S10,RA!$B$35:$O$39,4,0) -> 0.33711696 | AB10: =U10-T10 -> -0.14384757 | AC10: =V10-U10 -> -0.18429552 | AD10: =W10-V10 -> -0.14933904 | AE10: =X10-W10 -> -0.031873021 | AF10: =Y10-X10 -> -0.019445063 | AG10: =Z10-Y10 -> 0.089310613
C11: Marine | D11: =HLOOKUP($C11,RA!$D$244:$O$248,2,0) -> 0.2113787 | E11: =HLOOKUP($C11,RA!$D$244:$O$248,3,0) -> -0.48304974 | F11: =HLOOKUP($C11,RA!$D$244:$O$248,4,0) -> 1.4588523 | G11: =SUM(D11:F11) -> 1.1871813 | J11: Marine | K11: =HLOOKUP($J11,RA!$D$219:$O$241,19,0) -> 10775076 | L11: =HLOOKUP($J11,RA!$D$184:$O$209,22,0) -> 12248039 | M11: =HLOOKUP($J11,RA!$D$148:$O$173,22,0) -> 5795968.5 | N11: =HLOOKUP($J11,RA!$B$113:$O$144,21,0) -> 2059114.8 | O11: =_xlfn.XLOOKUP(J11,RA!$C$78:$N$78,RA!$C$98:$N$98) -> 7366945.8 | P11: =HLOOKUP($J11,RA!$B$43:$O$74,21,0) -> 2784540 | Q11: =HLOOKUP($J11,RA!$B$8:$O$39,21,0) -> 3329400.1 | S11: Marine | T11: =HLOOKUP($S11,RA!$D$244:$O$248,4,0) -> 1.4588523 | U11: =HLOOKUP($S11,RA!$D$212:$O$216,4,0) -> 1.07313 | V11: =HLOOKUP($S11,RA!$D$176:$O$180,4,0) -> 0.6948806 | W11: =HLOOKUP($S11,RA!$B$140:$O$144,4,0) -> 0.23371364 | X11: =_xlfn.XLOOKUP(S11,RA!$C$78:$N$78,RA!$C$108:$N$108) -> 0.47756874 | Y11: =HLOOKUP($S11,RA!$B$70:$O$74,4,0) -> 0.30236354 | Z11: =HLOOKUP($S11,RA!$B$35:$O$39,4,0) -> 0.41018256 | AB11: =U11-T11 -> -0.38572235 | AC11: =V11-U11 -> -0.37824938 | AD11: =W11-V11 -> -0.46116697 | AE11: =X11-W11 -> 0.24385511 | AF11: =Y11-X11 -> -0.1752052 | AG11: =Z11-Y11 -> 0.10781902
C12: Miscellaneous | D12: =HLOOKUP($C12,RA!$D$244:$O$248,2,0) -> 0.18272568 | E12: =HLOOKUP($C12,RA!$D$244:$O$248,3,0) -> -0.18299357 | F12: =HLOOKUP($C12,RA!$D$244:$O$248,4,0) -> 0.28299294 | G12: =SUM(D12:F12) -> 0.28272505 | J12: Miscellaneous | K12: =HLOOKUP($J12,RA!$D$219:$O$241,19,0) -> 3918209 | L12: =HLOOKUP($J12,RA!$D$184:$O$209,22,0) -> 4887102.9 | M12: =HLOOKUP($J12,RA!$D$148:$O$173,22,0) -> 15728956 | N12: =HLOOKUP($J12,RA!$B$113:$O$144,21,0) -> 13391710 | O12: =_xlfn.XLOOKUP(J12,RA!$C$78:$N$78,RA!$C$98:$N$98) -> 19555865 | P12: =HLOOKUP($J12,RA!$B$43:$O$74,21,0) -> 4274463.2 | Q12: =HLOOKUP($J12,RA!$B$8:$O$39,21,0) -> 1508238.8 | S12: Miscellaneous | T12: =HLOOKUP($S12,RA!$D$244:$O$248,4,0) -> 0.28299294 | U12: =HLOOKUP($S12,RA!$D$212:$O$216,4,0) -> 0.63819711 | V12: =HLOOKUP($S12,RA!$D$176:$O$180,4,0) -> 4.2395993 | W12: =HLOOKUP($S12,RA!$B$140:$O$144,4,0) -> 6.4723328 | X12: =_xlfn.XLOOKUP(S12,RA!$C$78:$N$78,RA!$C$108:$N$108) -> 2.0561346 | Y12: =HLOOKUP($S12,RA!$B$70:$O$74,4,0) -> 0.37267518 | Z12: =HLOOKUP($S12,RA!$B$35:$O$39,4,0) -> 0.60277912 | AB12: =U12-T12 -> 0.35520417 | AC12: =V12-U12 -> 3.6014022 | AD12: =W12-V12 -> 2.2327335 | AE12: =X12-W12 -> -4.4161982 | AF12: =Y12-X12 -> -1.6834594 | AG12: =Z12-Y12 -> 0.23010394
C13: Motor Commercial | D13: =HLOOKUP($C13,RA!$D$244:$O$248,2,0) -> 0.70970537 | E13: =HLOOKUP($C13,RA!$D$244:$O$248,3,0) -> 0.100265 | F13: =HLOOKUP($C13,RA!$D$244:$O$248,4,0) -> 1.000805 | G13: =SUM(D13:F13) -> 1.8107753 | J13: Motor Commercial | K13: =HLOOKUP($J13,RA!$D$219:$O$241,19,0) -> 15672837 | L13: =HLOOKUP($J13,RA!$D$184:$O$209,22,0) -> 34447566 | M13: =HLOOKUP($J13,RA!$D$148:$O$173,22,0) -> 45812338 | N13: =HLOOKUP($J13,RA!$B$113:$O$144,21,0) -> 51335107 | O13: =_xlfn.XLOOKUP(J13,RA!$C$78:$N$78,RA!$C$98:$N$98) -> 52495222 | P13: =HLOOKUP($J13,RA!$B$43:$O$74,21,0) -> 68083845 | Q13: =HLOOKUP($J13,RA!$B$8:$O$39,21,0) -> 1.0269102e+08 | S13: Motor Commercial | T13: =HLOOKUP($S13,RA!$D$244:$O$248,4,0) -> 1.000805 | U13: =HLOOKUP($S13,RA!$D$212:$O$216,4,0) -> 0.44265047 | V13: =HLOOKUP($S13,RA!$D$176:$O$180,4,0) -> 0.30096014 | W13: =HLOOKUP($S13,RA!$B$140:$O$144,4,0) -> 0.35222116 | X13: =_xlfn.XLOOKUP(S13,RA!$C$78:$N$78,RA!$C$108:$N$108) -> 0.26856952 | Y13: =HLOOKUP($S13,RA!$B$70:$O$74,4,0) -> 0.23267272 | Z13: =HLOOKUP($S13,RA!$B$35:$O$39,4,0) -> 0.29103809 | AB13: =U13-T13 -> -0.5581545 | AC13: =V13-U13 -> -0.14169033 | AD13: =W13-V13 -> 0.051261017 | AE13: =X13-W13 -> -0.08365164 | AF13: =Y13-X13 -> -0.035896794 | AG13: =Z13-Y13 -> 0.058365366
C14: Motor Private | D14: =HLOOKUP($C14,RA!$D$244:$O$248,2,0) -> 0.79828609 | E14: =HLOOKUP($C14,RA!$D$244:$O$248,3,0) -> 0.14767045 | F14: =HLOOKUP($C14,RA!$D$244:$O$248,4,0) -> 2.1981426 | G14: =SUM(D14:F14) -> 3.1440992 | J14: Motor Private | K14: =HLOOKUP($J14,RA!$D$219:$O$241,19,0) -> 50653168 | L14: =HLOOKUP($J14,RA!$D$184:$O$209,22,0) -> 66463189 | M14: =HLOOKUP($J14,RA!$D$148:$O$173,22,0) -> 1.0843598e+08 | N14: =HLOOKUP($J14,RA!$B$113:$O$144,21,0) -> 1.3367977e+08 | O14: =_xlfn.XLOOKUP(J14,RA!$C$78:$N$78,RA!$C$98:$N$98) -> 1.3826429e+08 | P14: =HLOOKUP($J14,RA!$B$43:$O$74,21,0) -> 1.8250401e+08 | Q14: =HLOOKUP($J14,RA!$B$8:$O$39,21,0) -> 2.5336483e+08 | S14: Motor Private | T14: =HLOOKUP($S14,RA!$D$244:$O$248,4,0) -> 2.1981426 | U14: =HLOOKUP($S14,RA!$D$212:$O$216,4,0) -> 0.52106495 | V14: =HLOOKUP($S14,RA!$D$176:$O$180,4,0) -> 0.3119834 | W14: =HLOOKUP($S14,RA!$B$140:$O$144,4,0) -> 0.31006818 | X14: =_xlfn.XLOOKUP(S14,RA!$C$78:$N$78,RA!$C$108:$N$108) -> 0.26131748 | Y14: =HLOOKUP($S14,RA!$B$70:$O$74,4,0) -> 0.24038686 | Z14: =HLOOKUP($S14,RA!$B$35:$O$39,4,0) -> 0.2906666 | AB14: =U14-T14 -> -1.6770777 | AC14: =V14-U14 -> -0.20908155 | AD14: =W14-V14 -> -0.0019152145 | AE14: =X14-W14 -> -0.048750707 | AF14: =Y14-X14 -> -0.020930621 | AG14: =Z14-Y14 -> 0.050279744
C15: Personal Accident | D15: =HLOOKUP($C15,RA!$D$244:$O$248,2,0) -> 0.28817519 | E15: =HLOOKUP($C15,RA!$D$244:$O$248,3,0) -> 0.10918498 | F15: =HLOOKUP($C15,RA!$D$244:$O$248,4,0) -> 0.35140103 | G15: =SUM(D15:F15) -> 0.74876119 | J15: Personal Accident | K15: =HLOOKUP($J15,RA!$D$219:$O$241,19,0) -> 1959105 | L15: =HLOOKUP($J15,RA!$D$184:$O$209,22,0) -> 9580110.3 | M15: =HLOOKUP($J15,RA!$D$148:$O$173,22,0) -> 9479105 | N15: =HLOOKUP($J15,RA!$B$113:$O$144,21,0) -> 1870774.6 | O15: =_xlfn.XLOOKUP(J15,RA!$C$78:$N$78,RA!$C$98:$N$98) -> 1416352.7 | P15: =HLOOKUP($J15,RA!$B$43:$O$74,21,0) -> 1590709.7 | Q15: =HLOOKUP($J15,RA!$B$8:$O$39,21,0) -> 2589885.8 | S15: Personal Accident | T15: =HLOOKUP($S15,RA!$D$244:$O$248,4,0) -> 0.35140103 | U15: =HLOOKUP($S15,RA!$D$212:$O$216,4,0) -> 0.25034917 | V15: =HLOOKUP($S15,RA!$D$176:$O$180,4,0) -> 1.0544724 | W15: =HLOOKUP($S15,RA!$B$140:$O$144,4,0) -> 0.16029787 | X15: =_xlfn.XLOOKUP(S15,RA!$C$78:$N$78,RA!$C$108:$N$108) -> -0.69075143 | Y15: =HLOOKUP($S15,RA!$B$70:$O$74,4,0) -> 0.25078053 | Z15: =HLOOKUP($S15,RA!$B$35:$O$39,4,0) -> 0.35856044 | AB15: =U15-T15 -> -0.10105185 | AC15: =V15-U15 -> 0.80412325 | AD15: =W15-V15 -> -0.89417455 | AE15: =X15-W15 -> -0.85104931 | AF15: =Y15-X15 -> 0.94153196 | AG15: =Z15-Y15 -> 0.10777991
C16: Theft | D16: =HLOOKUP($C16,RA!$D$244:$O$248,2,0) -> 2.1182289 | E16: =HLOOKUP($C16,RA!$D$244:$O$248,3,0) -> -0.43391257 | F16: =HLOOKUP($C16,RA!$D$244:$O$248,4,0) -> 19.693585 | G16: =SUM(D16:F16) -> 21.377901 | J16: Theft | K16: =HLOOKUP($J16,RA!$D$219:$O$241,19,0) -> 2938657 | L16: =HLOOKUP($J16,RA!$D$184:$O$209,22,0) -> 4234667 | M16: =HLOOKUP($J16,RA!$D$148:$O$173,22,0) -> 4310598.7 | N16: =HLOOKUP($J16,RA!$B$113:$O$144,21,0) -> 4599512.1 | O16: =_xlfn.XLOOKUP(J16,RA!$C$78:$N$78,RA!$C$98:$N$98) -> 3658504.4 | P16: =HLOOKUP($J16,RA!$B$43:$O$74,21,0) -> 3271239.4 | Q16: =HLOOKUP($J16,RA!$B$8:$O$39,21,0) -> 4692238.3 | S16: Theft | T16: =HLOOKUP($S16,RA!$D$244:$O$248,4,0) -> 19.693585 | U16: =HLOOKUP($S16,RA!$D$212:$O$216,4,0) -> 0.63583093 | V16: =HLOOKUP($S16,RA!$D$176:$O$180,4,0) -> 0.21275605 | W16: =HLOOKUP($S16,RA!$B$140:$O$144,4,0) -> 0.29663086 | X16: =_xlfn.XLOOKUP(S16,RA!$C$78:$N$78,RA!$C$108:$N$108) -> 0.26704873 | Y16: =HLOOKUP($S16,RA!$B$70:$O$74,4,0) -> 0.31806962 | Z16: =HLOOKUP($S16,RA!$B$35:$O$39,4,0) -> 0.37293373 | AB16: =U16-T16 -> -19.057754 | AC16: =V16-U16 -> -0.42307488 | AD16: =W16-V16 -> 0.083874803 | AE16: =X16-W16 -> -0.029582122 | AF16: =Y16-X16 -> 0.051020882 | AG16: =Z16-Y16 -> 0.054864111
C17: Workmen's Compensation | D17: =HLOOKUP($C17,RA!$D$244:$O$248,2,0) -> 0.22947418 | E17: =HLOOKUP($C17,RA!$D$244:$O$248,3,0) -> 0.13705546 | F17: =HLOOKUP($C17,RA!$D$244:$O$248,4,0) -> 0.19555317 | G17: =SUM(D17:F17) -> 0.56208281 | J17: Workmen's Compensation | K17: =HLOOKUP($J17,RA!$D$219:$O$241,19,0) -> 1959105 | L17: =HLOOKUP($J17,RA!$D$184:$O$209,22,0) -> 10230990 | M17: =HLOOKUP($J17,RA!$D$148:$O$173,22,0) -> 10368035 | N17: =HLOOKUP($J17,RA!$B$113:$O$144,21,0) -> 14904287 | O17: =_xlfn.XLOOKUP(J17,RA!$C$78:$N$78,RA!$C$98:$N$98) -> 54271616 | P17: =HLOOKUP($J17,RA!$B$43:$O$74,21,0) -> 65987074 | Q17: =HLOOKUP($J17,RA!$B$8:$O$39,21,0) -> 29161038 | S17: Workmen's Compensation | T17: =HLOOKUP($S17,RA!$D$244:$O$248,4,0) -> 0.19555317 | U17: =HLOOKUP($S17,RA!$D$212:$O$216,4,0) -> 0.45927326 | V17: =HLOOKUP($S17,RA!$D$176:$O$180,4,0) -> 0.2965652 | W17: =HLOOKUP($S17,RA!$B$140:$O$144,4,0) -> 0.52229695 | X17: =_xlfn.XLOOKUP(S17,RA!$C$78:$N$78,RA!$C$108:$N$108) -> 0.3277822 | Y17: =HLOOKUP($S17,RA!$B$70:$O$74,4,0) -> 0.26732437 | Z17: =HLOOKUP($S17,RA!$B$35:$O$39,4,0) -> 0.37957283 | AB17: =U17-T17 -> 0.26372009 | AC17: =V17-U17 -> -0.16270806 | AD17: =W17-V17 -> 0.22573175 | AE17: =X17-W17 -> -0.19451474 | AF17: =Y17-X17 -> -0.060457828 | AG17: =Z17-Y17 -> 0.11224845
C18: Total | D18: =HLOOKUP($C18,RA!$D$244:$O$248,2,0) -> 0.46697779 | E18: =HLOOKUP($C18,RA!$D$244:$O$248,3,0) -> -0.0023666355 | F18: =HLOOKUP($C18,RA!$D$244:$O$248,4,0) -> 1.172393 | G18: =SUM(D18:F18) -> 1.6370041 | J18: Total | K18: =SUM(K7:K17) -> 98651233 | L18: =SUM(L7:L17) -> 1.7644383e+08 | M18: =SUM(M7:M17) -> 2.3893654e+08 | N18: =SUM(N7:N17) -> 259624669 | O18: =SUM(O6:O17) -> 3.052059e+08 | P18: =SUM(P7:P17) -> 3.647348e+08 | Q18: =SUM(Q7:Q17) -> 441506822 | S18: Total | T18: =HLOOKUP($S18,RA!$D$244:$O$248,4,0) -> 1.172393 | U18: =HLOOKUP($S18,RA!$D$212:$O$216,4,0) -> 0.55223357 | V18: =HLOOKUP($S18,RA!$D$176:$O$180,4,0) -> 0.37757371 | W18: =HLOOKUP($S18,RA!$B$140:$O$144,4,0) -> 0.36554807 | X18: =RA!O108 -> 0.30688473 | Y18: =HLOOKUP($S18,RA!$B$70:$O$74,4,0) -> 0.25929434 | Z18: =HLOOKUP($S18,RA!$B$35:$O$39,4,0) -> 0.31080859 | AB18: =U18-T18 -> -0.62015941 | AC18: =V18-U18 -> -0.17465985 | AD18: =W18-V18 -> -0.012025645 | AE18: =X18-W18 -> -0.058663335 | AF18: =Y18-X18 -> -0.047590391 | AG18: =Z18-Y18 -> 0.051514251
C23: Pioneer General Insurance Limited Key Net Ratio Analysis - 2018 | J23: Pioneer General Insurance Limited Management Expense Allocation Proportions
C24: Class | D24: Loss Ratios | E24: Commission Ratios | F24: Expense Ratios | G24: Combined Ratio | J24: Class | K24: 2017 | L24: =K24+1 -> 2018 | M24: =L24+1 -> 2019 | N24: =M24+1 -> 2020 | O24: 2021 | P24: 2022 | Q24: 2023
C25: Engineering | D25: =HLOOKUP($C25,RA!$D$212:$O$216,2,0) -> 0.80877429 | E25: =HLOOKUP($C25,RA!$D$212:$O$216,3,0) -> -0.58119236 | F25: =HLOOKUP($C25,RA!$D$212:$O$216,4,0) -> 1.2993485 | G25: =SUM(D25:F25) -> 1.5269305 | J25: Engineering | K25: =K7/K$18 -> 0.0099294451 | L25: =L7/L$18 -> 0.027533955 | M25: =M7/M$18 -> 0.021952868 | N25: =N7/N$18 -> 0.021524074 | O25: =O7/O$18 -> 0.013873678 | P25: =P7/P$18 -> 0.025029643 | Q25: =Q7/Q$18 -> 0.020483523
C26: Fire Domestic | D26: =HLOOKUP($C26,RA!$D$212:$O$216,2,0) -> 0.52989016 | E26: =HLOOKUP($C26,RA!$D$212:$O$216,3,0) -> -0.16730322 | F26: =HLOOKUP($C26,RA!$D$212:$O$216,4,0) -> 1.585457 | G26: =SUM(D26:F26) -> 1.9480439 | J26: Fire Domestic | K26: =K8/K$18 -> 0.029788345 | L26: =L8/L$18 -> 0.01698405 | M26: =M8/M$18 -> 0.013630559 | N26: =N8/N$18 -> 0.010036848 | O26: =O8/O$18 -> 0.007143877 | P26: =P8/P$18 -> 0.0054245579 | Q26: =Q8/Q$18 -> 0.0067598715
C27: Fire Industrial | D27: =HLOOKUP($C27,RA!$D$212:$O$216,2,0) -> -0.094212764 | E27: =HLOOKUP($C27,RA!$D$212:$O$216,3,0) -> -2.1366104 | F27: =HLOOKUP($C27,RA!$D$212:$O$216,4,0) -> 2.2683675 | G27: =SUM(D27:F27) -> 0.037544303 | J27: Fire Industrial | K27: =K9/K$18 -> 0.049647246 | L27: =L9/L$18 -> 0.097698744 | M27: =M9/M$18 -> 0.076065192 | N27: =N9/N$18 -> 0.074254006 | O27: =O9/O$18 -> 0.041485899 | P27: =P9/P$18 -> 0.047851916 | Q27: =Q9/Q$18 -> 0.047791708
C28: Liability | D28: =HLOOKUP($C28,RA!$D$212:$O$216,2,0) -> 0.60882948 | E28: =HLOOKUP($C28,RA!$D$212:$O$216,3,0) -> 0.17531123 | F28: =HLOOKUP($C28,RA!$D$212:$O$216,4,0) -> 0.63275899 | G28: =SUM(D28:F28) -> 1.4168997 | J28: Liability | K28: =K10/K$18 -> 0.0198589 | L28: =L10/L$18 -> 0.052475065 | M28: =M10/M$18 -> 0.051597893 | N28: =N10/N$18 -> 0.039719756 | O28: =O10/O$18 -> 0.029811527 | P28: =P10/P$18 -> 0.021050792 | Q28: =Q10/Q$18 -> 0.025009049
C29: Marine | D29: =HLOOKUP($C29,RA!$D$212:$O$216,2,0) -> 0.23567657 | E29: =HLOOKUP($C29,RA!$D$212:$O$216,3,0) -> -0.48108242 | F29: =HLOOKUP($C29,RA!$D$212:$O$216,4,0) -> 1.07313 | G29: =SUM(D29:F29) -> 0.82772413 | J29: Marine | K29: =K11/K$18 -> 0.10922394 | L29: =L11/L$18 -> 0.069416079 | M29: =M11/M$18 -> 0.024257355 | N29: =N11/N$18 -> 0.0079311216 | O29: =O11/O$18 -> 0.024137626 | P29: =P11/P$18 -> 0.0076344236 | Q29: =Q11/Q$18 -> 0.0075409936
C30: Miscellaneous | D30: =HLOOKUP($C30,RA!$D$212:$O$216,2,0) -> 0.13197631 | E30: =HLOOKUP($C30,RA!$D$212:$O$216,3,0) -> -0.57357551 | F30: =HLOOKUP($C30,RA!$D$212:$O$216,4,0) -> 0.63819711 | G30: =SUM(D30:F30) -> 0.1965979 | J30: Miscellaneous | K30: =K12/K$18 -> 0.03971779 | L30: =L12/L$18 -> 0.027697782 | M30: =M12/M$18 -> 0.065829008 | N30: =N12/N$18 -> 0.051581037 | O30: =O12/O$18 -> 0.064074336 | P30: =P12/P$18 -> 0.011719373 | Q30: =Q12/Q$18 -> 0.0034161166
C31: Motor Commercial | D31: =HLOOKUP($C31,RA!$D$212:$O$216,2,0) -> 0.70658548 | E31: =HLOOKUP($C31,RA!$D$212:$O$216,3,0) -> 0.14997414 | F31: =HLOOKUP($C31,RA!$D$212:$O$216,4,0) -> 0.44265047 | G31: =SUM(D31:F31) -> 1.2992101 | J31: Motor Commercial | K31: =K13/K$18 -> 0.15887117 | L31: =L13/L$18 -> 0.19523247 | M31: =M13/M$18 -> 0.19173433 | N31: =N13/N$18 -> 0.19772815 | O31: =O13/O$18 -> 0.17199937 | P31: =P13/P$18 -> 0.18666671 | Q31: =Q13/Q$18 -> 0.23259214
C32: Motor Private | D32: =HLOOKUP($C32,RA!$D$212:$O$216,2,0) -> 0.93270649 | E32: =HLOOKUP($C32,RA!$D$212:$O$216,3,0) -> 0.17539146 | F32: =HLOOKUP($C32,RA!$D$212:$O$216,4,0) -> 0.52106495 | G32: =SUM(D32:F32) -> 1.6291629 | J32: Motor Private | K32: =K14/K$18 -> 0.51345702 | L32: =L14/L$18 -> 0.37668184 | M32: =M14/M$18 -> 0.45382755 | N32: =N14/N$18 -> 0.51489626 | O32: =O14/O$18 -> 0.45301973 | P32: =P14/P$18 -> 0.50037454 | Q32: =Q14/Q$18 -> 0.5738639
C33: Personal Accident | D33: =HLOOKUP($C33,RA!$D$212:$O$216,2,0) -> 0.056020679 | E33: =HLOOKUP($C33,RA!$D$212:$O$216,3,0) -> 0.10708649 | F33: =HLOOKUP($C33,RA!$D$212:$O$216,4,0) -> 0.25034917 | G33: =SUM(D33:F33) -> 0.41345634 | J33: Personal Accident | K33: =K15/K$18 -> 0.0198589 | L33: =L15/L$18 -> 0.054295523 | M33: =M15/M$18 -> 0.039672061 | N33: =N15/N$18 -> 0.007205689 | O33: =O15/O$18 -> 0.0046406464 | P33: =P15/P$18 -> 0.0043612775 | Q33: =Q15/Q$18 -> 0.0058660154
C34: Theft | D34: =HLOOKUP($C34,RA!$D$212:$O$216,2,0) -> 0.090126774 | E34: =HLOOKUP($C34,RA!$D$212:$O$216,3,0) -> 0.17900701 | F34: =HLOOKUP($C34,RA!$D$212:$O$216,4,0) -> 0.63583093 | G34: =SUM(D34:F34) -> 0.90496471 | J34: Theft | K34: =K16/K$18 -> 0.029788345 | L34: =L16/L$18 -> 0.024000085 | M34: =M16/M$18 -> 0.018040768 | N34: =N16/N$18 -> 0.017716006 | O34: =O16/O$18 -> 0.011987004 | P34: =P16/P$18 -> 0.0089688164 | Q34: =Q16/Q$18 -> 0.010627782
C35: Workmen's Compensation | D35: =HLOOKUP($C35,RA!$D$212:$O$216,2,0) -> 0.31488202 | E35: =HLOOKUP($C35,RA!$D$212:$O$216,3,0) -> 0.24501644 | F35: =HLOOKUP($C35,RA!$D$212:$O$216,4,0) -> 0.45927326 | G35: =SUM(D35:F35) -> 1.0191717 | J35: Workmen's Compensation | K35: =K17/K$18 -> 0.0198589 | L35: =L17/L$18 -> 0.057984402 | M35: =M17/M$18 -> 0.043392419 | N35: =N17/N$18 -> 0.057407051 | O35: =O17/O$18 -> 0.17781968 | P35: =P17/P$18 -> 0.18091796 | Q35: =Q17/Q$18 -> 0.066048896
C36: Total | D36: =HLOOKUP($C36,RA!$D$212:$O$216,2,0) -> 0.62481314 | E36: =HLOOKUP($C36,RA!$D$212:$O$216,3,0) -> 0.058673911 | F36: =HLOOKUP($C36,RA!$D$212:$O$216,4,0) -> 0.55223357 | G36: =SUM(D36:F36) -> 1.2357206 | J36: Total | K36: =SUM(K25:K35) -> 1 | L36: =L18/L$18 -> 1 | M36: =M18/M$18 -> 1 | N36: =N18/N$18 -> 1 | O36: =O18/O$18 -> 1 | P36: =P18/P$18 -> 1 | Q36: =Q18/Q$18 -> 1
C41: Pioneer General Insurance Limited 2019 Key Net Ratios Analysis | J41: Pioneer General Insurance Limited Combined Net Ratios 2019 - 2023 | S41: Pioneer General Insurance Limited Combined Gross Ratios 2018 - 2023
C42: Class | D42: Loss Ratio | E42: Commission Ratio | F42: Expense Ratio | G42: Combined Ratio | J42: Class | K42: 2017 | L42: =K42+1 -> 2018 | M42: =L42+1 -> 2019 | N42: =M42+1 -> 2020 | O42: 2021 | P42: 2022 | Q42: 2023 | S42: Class | T42: 2017 | U42: =T42+1 -> 2018 | V42: =U42+1 -> 2019 | W42: =V42+1 -> 2020 | X42: 2021 | Y42: 2022 | Z42: 2023
C43: Engineering | D43: =HLOOKUP($S7,RA!$D$176:$O$180,2,0) -> -0.032544013 | E43: =HLOOKUP($S7,RA!$D$176:$O$180,3,0) -> -0.040905637 | F43: =HLOOKUP($S7,RA!$D$176:$O$180,4,0) -> 0.56924266 | G43: =HLOOKUP($S7,RA!$D$176:$O$180,5,0) -> 0.49579301 | J43: Engineering | K43: =G7 -> 0.87920975 | L43: =G25 -> 1.5269305 | M43: =G43 -> 0.49579301 | N43: =G61 -> 1.0022395 | O43: =G78 -> 0.53706642 | P43: =G96 -> 1.125584 | Q43: =G114 -> 0.56182767 | S43: Engineering
C44: Fire Domestic | D44: =HLOOKUP($S8,RA!$D$176:$O$180,2,0) -> 0.14807063 | E44: =HLOOKUP($S8,RA!$D$176:$O$180,3,0) -> -0.007926905 | F44: =HLOOKUP($S8,RA!$D$176:$O$180,4,0) -> 0.38173936 | G44: =HLOOKUP($S8,RA!$D$176:$O$180,5,0) -> 0.52188309 | J44: Fire Domestic | K44: =G8 -> 4.3542307 | L44: =G26 -> 1.9480439 | M44: =G44 -> 0.52188309 | N44: =G62 -> 0.42929883 | O44: =G79 -> 0.6078004 | P44: =G97 -> 0.6144555 | Q44: =G115 -> 0.69880073 | S44: Fire Domestic
C45: Fire Industrial | D45: =HLOOKUP($S9,RA!$D$176:$O$180,2,0) -> 0.35006751 | E45: =HLOOKUP($S9,RA!$D$176:$O$180,3,0) -> 0.19958177 | F45: =HLOOKUP($S9,RA!$D$176:$O$180,4,0) -> 1.5760211 | G45: =HLOOKUP($S9,RA!$D$176:$O$180,5,0) -> 2.1256704 | J45: Fire Industrial | K45: =G9 -> 1.0189602 | L45: =G27 -> 0.037544303 | M45: =G45 -> 2.1256704 | N45: =G63 -> 2.0626935 | O45: =G80 -> 0.51962952 | P45: =G98 -> 1.1694803 | Q45: =G116 -> 1.2919562 | S45: Fire Industrial
C46: Liability | D46: =HLOOKUP($S10,RA!$D$176:$O$180,2,0) -> 0.16716862 | E46: =HLOOKUP($S10,RA!$D$176:$O$180,3,0) -> 0.16838131 | F46: =HLOOKUP($S10,RA!$D$176:$O$180,4,0) -> 0.44846347 | G46: =HLOOKUP($S10,RA!$D$176:$O$180,5,0) -> 0.7840134 | J46: Liability | K46: =G10 -> 1.1708514 | L46: =G28 -> 1.4168997 | M46: =G46 -> 0.7840134 | N46: =G64 -> 0.442339 | O46: =G81 -> 0.50805949 | P46: =G99 -> 0.85501547 | Q46: =G117 -> 0.5876303 | S46: Liability
C47: Marine | D47: =HLOOKUP($S11,RA!$D$176:$O$180,2,0) -> 0.53760564 | E47: =HLOOKUP($S11,RA!$D$176:$O$180,3,0) -> -0.057407808 | F47: =HLOOKUP($S11,RA!$D$176:$O$180,4,0) -> 0.6948806 | G47: =HLOOKUP($S11,RA!$D$176:$O$180,5,0) -> 1.1750784 | J47: Marine | K47: =G11 -> 1.1871813 | L47: =G29 -> 0.82772413 | M47: =G47 -> 1.1750784 | N47: =G65 -> 0.13251095 | O47: =G82 -> 0.56051164 | P47: =G100 -> 0.55061278 | Q47: =G118 -> 1.0258123 | S47: Marine
C48: Miscellaneous | D48: =HLOOKUP($S12,RA!$D$176:$O$180,2,0) -> -0.0058129223 | E48: =HLOOKUP($S12,RA!$D$176:$O$180,3,0) -> -3.4001415 | F48: =HLOOKUP($S12,RA!$D$176:$O$180,4,0) -> 4.2395993 | G48: =HLOOKUP($S12,RA!$D$176:$O$180,5,0) -> 0.83364483 | J48: Miscellaneous | K48: =G12 -> 0.28272505 | L48: =G30 -> 0.1965979 | M48: =G48 -> 0.83364483 | N48: =G66 -> 7.0242986 | O48: =G83 -> 0.86168891 | P48: =G101 -> 1.2161557 | Q48: =G119 -> 0.93191796 | S48: Miscellaneous
C49: Motor Commercial | D49: =HLOOKUP($S13,RA!$D$176:$O$180,2,0) -> 0.54653369 | E49: =HLOOKUP($S13,RA!$D$176:$O$180,3,0) -> 0.09424883 | F49: =HLOOKUP($S13,RA!$D$176:$O$180,4,0) -> 0.30096014 | G49: =HLOOKUP($S13,RA!$D$176:$O$180,5,0) -> 0.94174266 | J49: Motor Commercial | K49: =G13 -> 1.8107753 | L49: =G31 -> 1.2992101 | M49: =G49 -> 0.94174266 | N49: =G67 -> 1.1536875 | O49: =G84 -> 1.0805601 | P49: =G102 -> 0.86544924 | Q49: =G120 -> 1.0852415 | S49: Motor Commercial
C50: Motor Private | D50: =HLOOKUP($S14,RA!$D$176:$O$180,2,0) -> 0.69797934 | E50: =HLOOKUP($S14,RA!$D$176:$O$180,3,0) -> 0.092430159 | F50: =HLOOKUP($S14,RA!$D$176:$O$180,4,0) -> 0.3119834 | G50: =HLOOKUP($S14,RA!$D$176:$O$180,5,0) -> 1.1023929 | J50: Motor Private | K50: =G14 -> 3.1440992 | L50: =G32 -> 1.6291629 | M50: =G50 -> 1.1023929 | N50: =G68 -> 1.1181325 | O50: =G85 -> 1.2437547 | P50: =G103 -> 1.0357456 | Q50: =G121 -> 1.0333027 | S50: Motor Private
C51: Personal Accident | D51: =HLOOKUP($S15,RA!$D$176:$O$180,2,0) -> 0.47070031 | E51: =HLOOKUP($S15,RA!$D$176:$O$180,3,0) -> 0.6399164 | F51: =HLOOKUP($S15,RA!$D$176:$O$180,4,0) -> 1.0544724 | G51: =HLOOKUP($S15,RA!$D$176:$O$180,5,0) -> 2.1650891 | J51: Personal Accident | K51: =G15 -> 0.74876119 | L51: =G33 -> 0.41345634 | M51: =G51 -> 2.1650891 | N51: =G69 -> -0.36601428 | O51: =G86 -> 1.197025 | P51: =G104 -> 0.5105516 | Q51: =G122 -> 0.67669502 | S51: Personal Accident
C52: Theft | D52: =HLOOKUP($S16,RA!$D$176:$O$180,2,0) -> 0.033016832 | E52: =HLOOKUP($S16,RA!$D$176:$O$180,3,0) -> 0.1851338 | F52: =HLOOKUP($S16,RA!$D$176:$O$180,4,0) -> 0.21275605 | G52: =HLOOKUP($S16,RA!$D$176:$O$180,5,0) -> 0.43090669 | J52: Theft | K52: =G16 -> 21.377901 | L52: =G34 -> 0.90496471 | M52: =G52 -> 0.43090669 | N52: =G70 -> 0.48466453 | O52: =G87 -> 0.51773636 | P52: =G105 -> 0.48754077 | Q52: =G123 -> 0.58743635 | S52: Theft
...

Sheet Past_FCR_Recs
B6: Pioneer General Insurance Limited | F6: Pioneer General Insurance Limited | M6: Pioneer General Insurance Company
B7: Past FCR Recommendations | F7: Past FCR Recommendations | M7: Past FCR Recommendations - 2021 | S7: Pioneer Insurance Kenya Limited
B8: 2019 Key Recommendations | D8: Extent Addressed in 2021 | F8: Key Recommendations | H8: Extent Addressed in 2021 | M8: 2021 FCR Recommendations | O8: Extent Addressed as at 2022 | S8: Past FCR Recommendations - 2022
B9: 1 | C9: Historical Reserve Adequacy Tests | D9: Under Continuous Review | F9: 1 | G9: Business Strategy | H9: The company has strived to diversify its business and reduce its exposure in motor business in line with the actuary’s recommendation. As a result, as at the end of 2021, the company’s book comprised of 62% motor business and 38% non-motor. | M9: 1 | N9: Business Strategy | O9: The company has strived to diversify its business and reduce its exposure in motor business in line with the actuary’s recommendation. Further the rates charged on motor business which has been loss making industrywide have been revised upwards to address this. | S9: 2022 FCR Recommendations | U9: Extent Addressed as at 2023
C10: A continuous review and monitoring of the Outstanding Claims Reserves methodology to ensure that any gaps between set reserves and actual pay-outs on settlement are minimal. | G10: Management should explore profitable product lines and create strategies to skew the product mix towards more non-Motor business which is generally more profitable. The book comprised over 70% Motor business which is less profitable due to high loss ratios. | M10: (i) | N10: The proportion of the Motor book reduced from 70% in 2020 to 62% in 2021. However, this remains much higher than the industry average, which has ranged between 30% and 36% over the past five years. We recommend continued efforts by the business to increase exposure to the more profitable non-Motor classes of business. | S10: 1 | T10: Product Mix and Diversification | U10: The company has strived to diversify its business and reduce its exposure in motor business in line with the actuary’s recommendation. Further the rates charged on motor business which has been loss making industrywide have been revised upwards to address this.
B11: 2 | C11: Pricing and Premium Adequacy | D11: Addressed in February 2021 | F11: 1 | G11: Historical Reserve Adequacy Tests | H11: Pioneer has taken steps to address the inadequacies in its case estimates. As at the valuation date, a proposal is under discussion at the senior management level to review the individual case estimate amount to a minimum of Ksh 200,000 from the current Ksh 150,000. | T11: Pioneer’s business mix has historically been mainly dominated by Motor insurance business. Motor business remains dominant for the insurer as at the end of 2022. The company should put in place measures to profitably grow its non-Motor portfolio and hence achieve better diversification.
C12: Review its underwriting procedures as well as its system capabilities to ensure the focus is shifted towards key risk factors e.g. age, gender and experience of driver. | G12: A continuous review and monitoring of the Outstanding Claims Reserves methodology to ensure that any gaps between set reserves and actual pay-outs on settlement are minimal. | M12: 2 | N12: Historical Reserve Adequacy Tests | O12: Pioneer has taken steps to address the inadequacies in its case estimates. As at present the individual case estimate amount has been reviewed upwards from KES 150,000 to KES 180,000. | S12: 2 | T12: Expenses
B13: 3 | C13: Capital Management and Capital Adequacy | D13: Capital Management and Credit Control Policies are in place. | F13: 2 | G13: Pricing and Premium Adequacy | H13: Ongoing implementation | M13: (i) | N13: From the test on the adequacy of previous reserves, the Case Estimates held as at December 2018, 2019, and 2020 are expected to be inadequate. The inadequacy is mainly driven by the Motor classes. | T13: There was a notable decrease in the expense ratio, from 31% in 2021 to 26% in 2022, We recommend that the insurer continues with the strategies aimed at growing the business volume to ensure expense levels are within the statutory allowable limits. | U13: Strategies are in place to grow the business volumes and reduce the expense ratio.
C14: Adoption of a Credit Management Policy to manage credit risk exposure. | G14: We recommend that for Motor insurance business, risk factors such as make and model of vehicles, age, gender and experience of driver etc are included in the Underwriting Manual to be captured and recorded at the underwriting stage. With industry focus shifting towards risk-based pricing, the company needs to review both its underwriting procedures as well as its system capabilities to ensure the focus is shifted towards key risk factors. | N14: As at the valuation date, a proposal is under discussion at the senior management level to review the individual case estimate amount to a minimum of KES. 200,000 from the current KES. 150,000. We recommend adoption and implementation of this proposal | T14: Reinsurance Arrangements | U14: At the end of the year 2023, an assessment of the adequacy of reinsurance strategies and arrangements proposed to cover of the insurer’s underwriting risks was done. Given the company’s plan for the year 2024, the treaty arrangements proposed were appropriate.
C15: The company’s business strategy to focus on capital preservation to improve the company’s Capital Adequacy Ratio | F15: 3 | G15: Capital Management and Capital Adequacy | H15: We have reviewed our product pricing policy especially for loss making classes of business to improve experience. A Credit management policy is in place. | M15: 3 | N15: Pricing and Premium Adequacy | O15: The rates charged on motor business which has been loss making industrywide have been revised upwards to address this. | S15: 3 (i) | T15: The company’s financial results show consistently lower profits on a net basis compared to the gross position, as the company is ceding away more of its profitable non-Motor business than the less profitable Motor business.
B16: 4 | C16: Reinsurance Arrangements | D16: At the end of the year 2020, an assessment of the adequacy of reinsurance strategies and arrangements proposed by the insurer to cover of the insurer’s underwriting risks was done. Given the company’s Plan for the year 2021, the treaty arrangements proposed were appropriate. | G16: We recommend that Pioneer General adopts a Credit Management Policy to help manage its credit risk expose which makes up the most proportion of the Risk Based Capital. | M16: i) | N16: The Motor Private and Motor Commercial classes are loss making, registering a combined loss ratio of more than 100% over the past five years. We recommend that the performance of these classes continue to be monitored and if necessary, premium reviews be conducted. | S16: (ii) | T16: We recommend that Pioneer continuously monitors the cost-effectiveness of these arrangements as the business grows, against actual claims experience to ensure the price paid for reinsurance is commensurate with expected recoveries to be made.
C17: An assessment on the appropriateness of existing reinsurance arrangements for Miscellaneous, Engineering, Fire Industrial, Liability and Marine classes and the cost-effectiveness of these arrangements to ensure the price paid for reinsurance is commensurate with expected recoveries to be made. | G17: Further, the company’s Business Strategy should focus on capital preservation to improve the company’s Capital Adequacy Ratio which currently falls short of the Prescribed Capital Requirements (“PCR”) of 200% provided for in the final capital requirements guidelines. | M17: (ii) | N17: With industry focus shifting towards risk-based pricing, the company needs to review both its underwriting procedures as well as its system capabilities to ensure the focus is shifted towards key risk factors. As at the valuation date, we were informed that this proposal is undergoing implementation. We encourage adoption of the report once complete. | S17: (iii) | T17: We also recommend that Pioneer conducts a Reinsurance Optimisation Exercise to assess the adequacy of its reinsurance arrangements.
B18: 5 | C18: Internal Processes | D18: Under Continuous Review | F18: 4 | G18: Investment Policy | H18: The Investment policy was reviewed in line with recommendation which has seen an increase in investment in government securities. | M18: 4 | N18: Capital Management and Capital Adequacy | O18: We are on course to meet this. A Credit management policy is in place. | T18: Reserving | U18: Pioneer continues to monitor this closely given that it adjusted its minimum case estimates from Kshs. 150,000 to Kshs. 180,000.
C19: The Manual to be: | G19: The Investment Policy should be reviewed to allow more allocation to Treasury Bonds which should help to yield higher investment return (average of 12%, compared to insurer’s actual return of 6.7% in 2020) and improve liquidity. | M19: (i) | N19: We recommend that Pioneer General implements the Credit Management Policy to manage its credit risk exposure. | S19: 4 (i) | T19: From the test on the adequacy of previous reserves, the Case Estimates held as at December 2019, 2020, and 2021 are expected to be inadequate. The inadequacy is mainly driven by the Motor classes.
C20: - Periodically updated to reflect any changes in the policies and procedures arising from the deliberations of the departmental meetings and the company’s changes in philosophies; | F20: 4 | G20: Reinsurance Arrangements | H20: At the end of the year 2021, an assessment of the adequacy of reinsurance strategies and arrangements proposed by the insurer to cover of the insurer’s underwriting risks was done. Given the company’s Plan for the year 2022, the treaty arrangements proposed were appropriate. | M20: (ii) | N20: We recommend Pioneer’s Business Strategy should focus on capital preservation to improve the company’s Capital Adequacy Ratio which currently falls short of the Prescribed Capital Requirements (“PCR”) of 200% provided for in the final capital requirements guidelines | S20: (ii) | T20: Case Estimates should be reviewed by management to ensure adequate reserves are set for Outstanding Claims.
C21: - Reviewed to include all sub-classes of business that the company deals in. | G21: An assessment should be performed on the appropriateness of existing reinsurance arrangements for Miscellaneous, Fire Industrial, Personal Accident and Workmen’s Compensation classes of business. The cost-effectiveness of these arrangements should be monitored as the business grows, against actual claims experience to ensure the price paid for reinsurance is commensurate with expected recoveries to be made. | M21: 5 | N21: Investment Policy | O21: The Investment policy was reviewed in line with recommendation which has seen an increase in investment in government securities.
F22: 5 | G22: Internal Processes | H22: Ongoing implementation | N22: Liquidity ratio is noted to have been declining over the past five years, from 76% in 2017 to 24% in 2021. Liquid assets cover over liabilities is also noted to have declined significantly to 43% as at the end of 2021, from 73% in the previous year. Given the short-term nature of the company’s liabilities, we recommend that the company increases investment allocation to liquid assets.
G23: The Manual to be: | M23: 6 | N23: Reinsurance Arrangements
G24: - Periodically updated to reflect any changes in the policies and procedures arising from the deliberations of the departmental meetings and the company’s changes in philosophies; | M24: (i) | N24: It was noted that the reinsurance cover served to reduce underwriting profit volatility from 11% to 8% over 2018 to 2021. However, the company’s financial results show consistently lower profits on a net basis compared to the gross position, as the company is ceding away more of its profitable non-Motor business than the less profitable Motor business. The cost-effectiveness of these arrangements should be monitored as the business grows, against actual claims experience to ensure the price paid for reinsurance is commensurate with expected recoveries to be made. | O24: At the end of the year 2022, an assessment of the adequacy of reinsurance strategies and arrangements proposed to cover of the insurer’s underwriting risks was done. Given the company’s plan for the year 2023, the treaty arrangements proposed were appropriate.
