Workbook
Name a_billion: Assumptions!$C$17
Name a_million: Assumptions!$C$16
Name a_thousand: Assumptions!$C$15
Name a_trillion: Assumptions!$C$18
Name Age: 'Membership Analysis'!$T$4:$T$950
Name Analysis_Date: Intro!$F$12
Name Ann_Loading: 'Mortality Tables'!$G$1
Name Ann_Salary_Growth_Rate: Assumptions!$C$4
Name Annuity_Ratio: 'Membership Analysis'!$DL$1
Name Comm_Date: 'Membership Analysis'!$B$1
Name Contr_Rate: Assumptions!$C$9
Name Discount_Table: 'v(t)'!$B$5:$DD$111
Name EE_Cont: 'Scheme Details'!$C$13
Name ER: 'Scheme Details'!$C$6
Name ER_Cont: 'Scheme Details'!$C$14
Name Fe_Annuity_Factor: 'Mortality Tables'!$G$4
Name Fe_Annuity_Tables: 'Mortality Tables'!$K$3:$DN$98
Name Fe_MDT: MDT!$O$3:$U$100
Name Fund_Credits: 'Membership Analysis'!$L$4:$L$950
Name Gender: 'Membership Analysis'!$D$4:$D$950
Name Inv_Return: Assumptions!$C$5
Name Male_Annuity_Factor: 'Mortality Tables'!$H$4
Name Male_Annuity_Tables: 'Mortality Tables'!$DQ$3:$HT$98
Name Male_MDT: MDT!$G$3:$M$100
Name Membership_Analysis: 'Membership Analysis'!$A$3:$X$950
Name Membership_Status: 'Membership Analysis'!$C$4:$C$950
Name Mortality_Table: 'Mortality Tables'!$A$3:$C$100
Name NRA: 'Scheme Details'!$C$5
Name scheme_acronym: Assumptions!$C$21
Name Scheme_Name: Assumptions!$C$20
Name Withdrawal_Probs: MDT!$A$3:$B$100
Name Years_To_Retirement: 'Membership Analysis'!$W$4:$W$950

Sheet Intro
C4: =Scheme_Name -> SOLARA SUMMIT STAFF PENSION SCHEME
C10: INVESTMENT POLICY STATEMENT
D12: Analysis Date | F12: 45656

Sheet New Report Sections
B2: 1 | C2: Growth in Assets
B8: Rules
B10: 1 | C10: Show value in maximum three digits ( make value as millions, billions, etc)
B11: 2 | C11: Where items are blank or zero then remove them or categorise as "Others"
B12: 3 | C12: Report assumptions / approach should be disclosed
B13: 4 | C13: The excel should have few hard coded numbers (preferably none)
B14: 5 | C14: In the excel, numbers used in formulas should be colored
B15: 6 | C15: Uniformity of Font Size
B16: 7 | C16: All tables from Excel should use the Atkinson Font
B17: 8 | C17: All numbers to have commas for every thousand

Sheet Scheme Details
B2: =Scheme_Name&" SCHEME DETAILS AS AT THE ANALYSIS DATE" -> SOLARA SUMMIT STAFF PENSION SCHEME SCHEME DETAILS AS AT THE ANALYSIS DATE
B3: Scheme Type | C3: Defined Contribution Scheme
B4: Scheme Commencement Date | C4: 35674
B5: Normal Retirement Age – NRA - (years) | C5: 60
B6: Early Retirement Age (years) | C6: 50
B7: Ill Health Retirement Age (years) | C7: Any age
B8: Scheme Membership | C8: =COUNTA(Membership_Status) -> 500
B9: Average Scheme Age (years) | C9: =AVERAGE(Age) -> 47.262
B10: Average Scheme Age - weighted by fund credits (years) | C10: =SUMPRODUCT(Age,Fund_Credits)/SUM(Fund_Credits) -> 47.591129
B11: Average Years to Retirement (simple average) | C11: =AVERAGE(Years_To_Retirement) -> 12.912
B12: Average Years to Retirement (weighted by fund credits) | C12: =SUMPRODUCT(Years_To_Retirement,Fund_Credits)/SUM(Fund_Credits) -> 12.60523
B13: Scheme Contribution Rate - Employee | C13: 0.15
B14: Scheme Contribution Rate - Employer | C14: 0.15
B15: Additional Voluntary Contributions | C15: Minimum of 3% p.a of Annual Salary
B16: Period before vesting of employee contributions (years) | C16: 0 (immediate)
B17: Period before vesting of employer contributions (years) | C17: 0 (immediate)
B18: Payment of Immediate Pension (mode) | C18: Annuity/Income Drawdown/Lumpsum
B19: Maximum Lump sum (% of Accrued Benefits) | C19: 0.3333
B20: Financial Year | C20: 01 Jan XXXX - 31 Dec XXXX
B22: Service providers as at Analysis Date:
B23: Administrator | C23: Keystone Financial Services Limited
B24: Approved Issuer | C24: Horizon Asset Managers Limited
B25: Custodian | C25: Alpha Bank Kenya Limited
B26: Founder | C26: Solara Company Limited

Sheet Assumptions
B3: Item | C3: Assumption
B4: Salary Growth Rate | C4: =AVERAGE('Fund Performance'!J19:K19) -> 0.05095
B5: Net Annual Investment Return | C5: ='Investment Income'!X47 -> 0.027644324
B6: Administrative Expenses (Proportion of Assets) | C6: ='Investment Income'!K21 -> 0.011555776
B7: Mortality Assumption | C7: a55 - UK table
B8: Discount Rate | C8: ='v(t)'!B2 -> 0.1
B9: Contribution Rate | C9: =EE_Cont+ER_Cont -> 0.3
B15: thousand | C15: 1000
B16: million | C16: 1000000
B17: billion | C17: 1000000000
B18: trillion | C18: 1000000000000
B20: Scheme Name | C20: SOLARA SUMMIT STAFF PENSION SCHEME
B21: Scheme Acronym | C21: SOS-SPS

Sheet v(t)
A2: Investment Return | B2: 0.1
C3: 0 | D3: 1 | E3: 2 | F3: =E3+1 -> 3 | G3: =F3+1 -> 4 | H3: =G3+1 -> 5 | I3: =H3+1 -> 6 | J3: =I3+1 -> 7 | K3: =J3+1 -> 8 | L3: =K3+1 -> 9 | M3: =L3+1 -> 10 | ... DD3: =DC3+1 -> 105
E4: t
B5: Age x | C5: ="v("&C3&")" -> v(0) | D5: ="v("&D3&")" -> v(1) | E5: ="v("&E3&")" -> v(2) | F5: ="v("&F3&")" -> v(3) | G5: ="v("&G3&")" -> v(4) | H5: ="v("&H3&")" -> v(5) | I5: ="v("&I3&")" -> v(6) | J5: ="v("&J3&")" -> v(7) | ... DD5: ="v("&DD3&")" -> v(105)
B6: 15 | C6: =(1+$B$2)^(-C$3) -> 1 | D6: =(1+$B$2)^(-D$3) -> 0.90909091 | E6: =(1+$B$2)^(-E$3) -> 0.82644628 | F6: =(1+$B$2)^(-F$3) -> 0.7513148 | G6: =(1+$B$2)^(-G$3) -> 0.68301346 | H6: =(1+$B$2)^(-H$3) -> 0.62092132 | I6: =(1+$B$2)^(-I$3) -> 0.56447393 | J6: =(1+$B$2)^(-J$3) -> 0.51315812 | ... DD6: =(1+$B$2)^(-DD$3) -> 4.50576e-05
B7: =B6+1 -> 16 | C7: =(1+$B$2)^(-C$3) -> 1 | D7: =(1+$B$2)^(-D$3) -> 0.90909091 | E7: =(1+$B$2)^(-E$3) -> 0.82644628 | F7: =(1+$B$2)^(-F$3) -> 0.7513148 | G7: =(1+$B$2)^(-G$3) -> 0.68301346 | H7: =(1+$B$2)^(-H$3) -> 0.62092132 | I7: =(1+$B$2)^(-I$3) -> 0.56447393 | J7: =(1+$B$2)^(-J$3) -> 0.51315812 | ... DD7: =(1+$B$2)^(-DD$3) -> 4.50576e-05
B8: =B7+1 -> 17 | C8: =(1+$B$2)^(-C$3) -> 1 | D8: =(1+$B$2)^(-D$3) -> 0.90909091 | E8: =(1+$B$2)^(-E$3) -> 0.82644628 | F8: =(1+$B$2)^(-F$3) -> 0.7513148 | G8: =(1+$B$2)^(-G$3) -> 0.68301346 | H8: =(1+$B$2)^(-H$3) -> 0.62092132 | I8: =(1+$B$2)^(-I$3) -> 0.56447393 | J8: =(1+$B$2)^(-J$3) -> 0.51315812 | ... DD8: =(1+$B$2)^(-DD$3) -> 4.50576e-05
B9: =B8+1 -> 18 | C9: =(1+$B$2)^(-C$3) -> 1 | D9: =(1+$B$2)^(-D$3) -> 0.90909091 | E9: =(1+$B$2)^(-E$3) -> 0.82644628 | F9: =(1+$B$2)^(-F$3) -> 0.7513148 | G9: =(1+$B$2)^(-G$3) -> 0.68301346 | H9: =(1+$B$2)^(-H$3) -> 0.62092132 | I9: =(1+$B$2)^(-I$3) -> 0.56447393 | J9: =(1+$B$2)^(-J$3) -> 0.51315812 | ... DD9: =(1+$B$2)^(-DD$3) -> 4.50576e-05
B10: =B9+1 -> 19 | C10: =(1+$B$2)^(-C$3) -> 1 | D10: =(1+$B$2)^(-D$3) -> 0.90909091 | E10: =(1+$B$2)^(-E$3) -> 0.82644628 | F10: =(1+$B$2)^(-F$3) -> 0.7513148 | G10: =(1+$B$2)^(-G$3) -> 0.68301346 | H10: =(1+$B$2)^(-H$3) -> 0.62092132 | I10: =(1+$B$2)^(-I$3) -> 0.56447393 | J10: =(1+$B$2)^(-J$3) -> 0.51315812 | ... DD10: =(1+$B$2)^(-DD$3) -> 4.50576e-05
B11: =B10+1 -> 20 | C11: =(1+$B$2)^(-C$3) -> 1 | D11: =(1+$B$2)^(-D$3) -> 0.90909091 | E11: =(1+$B$2)^(-E$3) -> 0.82644628 | F11: =(1+$B$2)^(-F$3) -> 0.7513148 | G11: =(1+$B$2)^(-G$3) -> 0.68301346 | H11: =(1+$B$2)^(-H$3) -> 0.62092132 | I11: =(1+$B$2)^(-I$3) -> 0.56447393 | J11: =(1+$B$2)^(-J$3) -> 0.51315812 | ... DD11: =(1+$B$2)^(-DD$3) -> 4.50576e-05
B12: =B11+1 -> 21 | C12: =(1+$B$2)^(-C$3) -> 1 | D12: =(1+$B$2)^(-D$3) -> 0.90909091 | E12: =(1+$B$2)^(-E$3) -> 0.82644628 | F12: =(1+$B$2)^(-F$3) -> 0.7513148 | G12: =(1+$B$2)^(-G$3) -> 0.68301346 | H12: =(1+$B$2)^(-H$3) -> 0.62092132 | I12: =(1+$B$2)^(-I$3) -> 0.56447393 | J12: =(1+$B$2)^(-J$3) -> 0.51315812 | ... DD12: =(1+$B$2)^(-DD$3) -> 4.50576e-05
B13: =B12+1 -> 22 | C13: =(1+$B$2)^(-C$3) -> 1 | D13: =(1+$B$2)^(-D$3) -> 0.90909091 | E13: =(1+$B$2)^(-E$3) -> 0.82644628 | F13: =(1+$B$2)^(-F$3) -> 0.7513148 | G13: =(1+$B$2)^(-G$3) -> 0.68301346 | H13: =(1+$B$2)^(-H$3) -> 0.62092132 | I13: =(1+$B$2)^(-I$3) -> 0.56447393 | J13: =(1+$B$2)^(-J$3) -> 0.51315812 | ... DD13: =(1+$B$2)^(-DD$3) -> 4.50576e-05
B14: =B13+1 -> 23 | C14: =(1+$B$2)^(-C$3) -> 1 | D14: =(1+$B$2)^(-D$3) -> 0.90909091 | E14: =(1+$B$2)^(-E$3) -> 0.82644628 | F14: =(1+$B$2)^(-F$3) -> 0.7513148 | G14: =(1+$B$2)^(-G$3) -> 0.68301346 | H14: =(1+$B$2)^(-H$3) -> 0.62092132 | I14: =(1+$B$2)^(-I$3) -> 0.56447393 | J14: =(1+$B$2)^(-J$3) -> 0.51315812 | ... DD14: =(1+$B$2)^(-DD$3) -> 4.50576e-05
B15: =B14+1 -> 24 | C15: =(1+$B$2)^(-C$3) -> 1 | D15: =(1+$B$2)^(-D$3) -> 0.90909091 | E15: =(1+$B$2)^(-E$3) -> 0.82644628 | F15: =(1+$B$2)^(-F$3) -> 0.7513148 | G15: =(1+$B$2)^(-G$3) -> 0.68301346 | H15: =(1+$B$2)^(-H$3) -> 0.62092132 | I15: =(1+$B$2)^(-I$3) -> 0.56447393 | J15: =(1+$B$2)^(-J$3) -> 0.51315812 | ... DD15: =(1+$B$2)^(-DD$3) -> 4.50576e-05
B16: =B15+1 -> 25 | C16: =(1+$B$2)^(-C$3) -> 1 | D16: =(1+$B$2)^(-D$3) -> 0.90909091 | E16: =(1+$B$2)^(-E$3) -> 0.82644628 | F16: =(1+$B$2)^(-F$3) -> 0.7513148 | G16: =(1+$B$2)^(-G$3) -> 0.68301346 | H16: =(1+$B$2)^(-H$3) -> 0.62092132 | I16: =(1+$B$2)^(-I$3) -> 0.56447393 | J16: =(1+$B$2)^(-J$3) -> 0.51315812 | ... DD16: =(1+$B$2)^(-DD$3) -> 4.50576e-05
B17: =B16+1 -> 26 | C17: =(1+$B$2)^(-C$3) -> 1 | D17: =(1+$B$2)^(-D$3) -> 0.90909091 | E17: =(1+$B$2)^(-E$3) -> 0.82644628 | F17: =(1+$B$2)^(-F$3) -> 0.7513148 | G17: =(1+$B$2)^(-G$3) -> 0.68301346 | H17: =(1+$B$2)^(-H$3) -> 0.62092132 | I17: =(1+$B$2)^(-I$3) -> 0.56447393 | J17: =(1+$B$2)^(-J$3) -> 0.51315812 | ... DD17: =(1+$B$2)^(-DD$3) -> 4.50576e-05
B18: =B17+1 -> 27 | C18: =(1+$B$2)^(-C$3) -> 1 | D18: =(1+$B$2)^(-D$3) -> 0.90909091 | E18: =(1+$B$2)^(-E$3) -> 0.82644628 | F18: =(1+$B$2)^(-F$3) -> 0.7513148 | G18: =(1+$B$2)^(-G$3) -> 0.68301346 | H18: =(1+$B$2)^(-H$3) -> 0.62092132 | I18: =(1+$B$2)^(-I$3) -> 0.56447393 | J18: =(1+$B$2)^(-J$3) -> 0.51315812 | ... DD18: =(1+$B$2)^(-DD$3) -> 4.50576e-05
... B111: =B110+1 -> 120 | C111: =(1+$B$2)^(-C$3) -> 1 | D111: =(1+$B$2)^(-D$3) -> 0.90909091 | E111: =(1+$B$2)^(-E$3) -> 0.82644628 | F111: =(1+$B$2)^(-F$3) -> 0.7513148 | G111: =(1+$B$2)^(-G$3) -> 0.68301346 | H111: =(1+$B$2)^(-H$3) -> 0.62092132 | I111: =(1+$B$2)^(-I$3) -> 0.56447393 | J111: =(1+$B$2)^(-J$3) -> 0.51315812 | ... DD111: =(1+$B$2)^(-DD$3) -> 4.50576e-05

Sheet Mortality Tables
A1: a55 - UK table | F1: Loading Factor | G1: 0.1 | M1: 0 | N1: 1 | O1: 2 | P1: =O1+1 -> 3 | Q1: =P1+1 -> 4 | R1: =Q1+1 -> 5 | S1: =R1+1 -> 6 | T1: =S1+1 -> 7 | U1: =T1+1 -> 8 | V1: =U1+1 -> 9 | W1: =V1+1 -> 10 | ... DN1: =DM1+1 -> 105 | DS1: 0 | DT1: 1 | DU1: 2 | DV1: =DU1+1 -> 3 | DW1: =DV1+1 -> 4 | DX1: =DW1+1 -> 5 | DY1: =DX1+1 -> 6 | DZ1: =DY1+1 -> 7 | EA1: =DZ1+1 -> 8 | EB1: =EA1+1 -> 9 | EC1: =EB1+1 -> 10 | ... HT1: =HS1+1 -> 105
F2: Annuity Factors | K2: FEMALE | O2: t | DQ2: MALE | DU2: t
A3: Age x | B3: Female | C3: Male | F3: NRA | G3: Female | H3: Male | K3: Age x | L3: (aq)x | M3: =M1&"(ap)x" -> 0(ap)x | N3: =N1&"(ap)x" -> 1(ap)x | O3: =O1&"(ap)x" -> 2(ap)x | P3: =P1&"(ap)x" -> 3(ap)x | Q3: =Q1&"(ap)x" -> 4(ap)x | R3: =R1&"(ap)x" -> 5(ap)x | S3: =S1&"(ap)x" -> 6(ap)x | T3: =T1&"(ap)x" -> 7(ap)x | ... DN3: =DN1&"(ap)x" -> 105(ap)x | DQ3: Age x | DR3: (aq)x | DS3: =DS1&"(ap)x" -> 0(ap)x | DT3: =DT1&"(ap)x" -> 1(ap)x | DU3: =DU1&"(ap)x" -> 2(ap)x | DV3: =DV1&"(ap)x" -> 3(ap)x | DW3: =DW1&"(ap)x" -> 4(ap)x | DX3: =DX1&"(ap)x" -> 5(ap)x | DY3: =DY1&"(ap)x" -> 6(ap)x | DZ3: =DZ1&"(ap)x" -> 7(ap)x | ... HT3: =HT1&"(ap)x" -> 105(ap)x
A4: 20 | B4: 0.00117 | C4: 0.00118 | F4: =NRA -> 60 | G4: =SUMPRODUCT($N$44:$DN$44,'v(t)'!$D$51:$DD$51)*(1+Ann_Loading) -> 8.8017766 | H4: =SUMPRODUCT($DT$44:$HT$44,'v(t)'!$D$51:$DD$51)*(1+Ann_Loading) -> 8.0909278 | K4: =A4 -> 20 | L4: =VLOOKUP(K4,Fe_MDT,6,0) -> 0.200936 | M4: 1 | N4: =1-L4 -> 0.799064 | O4: =N4*IFERROR(VLOOKUP($K4+N$1,$K$3:$DN$98,4,0),0) -> 0.63849688 | P4: =O4*IFERROR(VLOOKUP($K4+O$1,$K$3:$DN$98,4,0),0) -> 0.51018966 | Q4: =P4*IFERROR(VLOOKUP($K4+P$1,$K$3:$DN$98,4,0),0) -> 0.40766194 | R4: =Q4*IFERROR(VLOOKUP($K4+Q$1,$K$3:$DN$98,4,0),0) -> 0.32573494 | S4: =R4*IFERROR(VLOOKUP($K4+R$1,$K$3:$DN$98,4,0),0) -> 0.26026743 | T4: =S4*IFERROR(VLOOKUP($K4+S$1,$K$3:$DN$98,4,0),0) -> 0.20795576 | U4: =T4*IFERROR(VLOOKUP($K4+T$1,$K$3:$DN$98,4,0),0) -> 0.16615499 | V4: =U4*IFERROR(VLOOKUP($K4+U$1,$K$3:$DN$98,4,0),0) -> 0.13275385 | ... DN4: =DM4*IFERROR(VLOOKUP($K4+DM$1,$K$3:$DN$98,4,0),0) -> 0 | DQ4: =$A4 -> 20 | DR4: =VLOOKUP(DQ4,Male_MDT,6,0) -> 0.200944 | DS4: 1 | DT4: =1-DR4 -> 0.799056 | DU4: =DT4*IFERROR(VLOOKUP($DQ4+DT$1,$DQ$3:$HT$98,4,0),0) -> 0.63847771 | DV4: =DU4*IFERROR(VLOOKUP($DQ4+DU$1,$DQ$3:$HT$98,4,0),0) -> 0.5101539 | DW4: =DV4*IFERROR(VLOOKUP($DQ4+DV$1,$DQ$3:$HT$98,4,0),0) -> 0.40761705 | DX4: =DW4*IFERROR(VLOOKUP($DQ4+DW$1,$DQ$3:$HT$98,4,0),0) -> 0.32568276 | DY4: =DX4*IFERROR(VLOOKUP($DQ4+DX$1,$DQ$3:$HT$98,4,0),0) -> 0.26021271 | DZ4: =DY4*IFERROR(VLOOKUP($DQ4+DY$1,$DQ$3:$HT$98,4,0),0) -> 0.20790163 | EA4: =DZ4*IFERROR(VLOOKUP($DQ4+DZ$1,$DQ$3:$HT$98,4,0),0) -> 0.16610342 | EB4: =EA4*IFERROR(VLOOKUP($DQ4+EA$1,$DQ$3:$HT$98,4,0),0) -> 0.132706 | ... HT4: =HS4*IFERROR(VLOOKUP($DQ4+HS$1,$DQ$3:$HT$98,4,0),0) -> 0
A5: 21 | B5: 0.00118 | C5: 0.0012 | K5: =K4+1 -> 21 | L5: =VLOOKUP(K5,Fe_MDT,6,0) -> 0.200944 | M5: 1 | N5: =1-L5 -> 0.799056 | O5: =N5*IFERROR(VLOOKUP($K5+N$1,$K$3:$DN$98,4,0),0) -> 0.6384841 | P5: =O5*IFERROR(VLOOKUP($K5+O$1,$K$3:$DN$98,4,0),0) -> 0.51017433 | Q5: =P5*IFERROR(VLOOKUP($K5+P$1,$K$3:$DN$98,4,0),0) -> 0.40764562 | R5: =Q5*IFERROR(VLOOKUP($K5+Q$1,$K$3:$DN$98,4,0),0) -> 0.32571537 | S5: =R5*IFERROR(VLOOKUP($K5+R$1,$K$3:$DN$98,4,0),0) -> 0.26024919 | T5: =S5*IFERROR(VLOOKUP($K5+S$1,$K$3:$DN$98,4,0),0) -> 0.20793702 | U5: =T5*IFERROR(VLOOKUP($K5+T$1,$K$3:$DN$98,4,0),0) -> 0.16613669 | V5: =U5*IFERROR(VLOOKUP($K5+U$1,$K$3:$DN$98,4,0),0) -> 0.13273657 | ... DN5: =DM5*IFERROR(VLOOKUP($K5+DM$1,$K$3:$DN$98,4,0),0) -> 0 | DQ5: =DQ4+1 -> 21 | DR5: =VLOOKUP(DQ5,Male_MDT,6,0) -> 0.20096 | DS5: 1 | DT5: =1-DR5 -> 0.79904 | DU5: =DT5*IFERROR(VLOOKUP($DQ5+DT$1,$DQ$3:$HT$98,4,0),0) -> 0.63844574 | DV5: =DU5*IFERROR(VLOOKUP($DQ5+DU$1,$DQ$3:$HT$98,4,0),0) -> 0.51012326 | DW5: =DV5*IFERROR(VLOOKUP($DQ5+DV$1,$DQ$3:$HT$98,4,0),0) -> 0.4075844 | DX5: =DW5*IFERROR(VLOOKUP($DQ5+DW$1,$DQ$3:$HT$98,4,0),0) -> 0.32565015 | DY5: =DX5*IFERROR(VLOOKUP($DQ5+DX$1,$DQ$3:$HT$98,4,0),0) -> 0.26018405 | DZ5: =DY5*IFERROR(VLOOKUP($DQ5+DY$1,$DQ$3:$HT$98,4,0),0) -> 0.20787457 | EA5: =DZ5*IFERROR(VLOOKUP($DQ5+DZ$1,$DQ$3:$HT$98,4,0),0) -> 0.16607848 | EB5: =EA5*IFERROR(VLOOKUP($DQ5+EA$1,$DQ$3:$HT$98,4,0),0) -> 0.13268209 | ... HT5: =HS5*IFERROR(VLOOKUP($DQ5+HS$1,$DQ$3:$HT$98,4,0),0) -> 0
A6: 22 | B6: 0.00119 | C6: 0.00123 | K6: =K5+1 -> 22 | L6: =VLOOKUP(K6,Fe_MDT,6,0) -> 0.200952 | M6: 1 | N6: =1-L6 -> 0.799048 | O6: =N6*IFERROR(VLOOKUP($K6+N$1,$K$3:$DN$98,4,0),0) -> 0.63847131 | P6: =O6*IFERROR(VLOOKUP($K6+O$1,$K$3:$DN$98,4,0),0) -> 0.51015901 | Q6: =P6*IFERROR(VLOOKUP($K6+P$1,$K$3:$DN$98,4,0),0) -> 0.40762521 | R6: =Q6*IFERROR(VLOOKUP($K6+Q$1,$K$3:$DN$98,4,0),0) -> 0.32569581 | S6: =R6*IFERROR(VLOOKUP($K6+R$1,$K$3:$DN$98,4,0),0) -> 0.26022834 | T6: =S6*IFERROR(VLOOKUP($K6+S$1,$K$3:$DN$98,4,0),0) -> 0.2079162 | U6: =T6*IFERROR(VLOOKUP($K6+T$1,$K$3:$DN$98,4,0),0) -> 0.16611673 | V6: =U6*IFERROR(VLOOKUP($K6+U$1,$K$3:$DN$98,4,0),0) -> 0.13271796 | ... DN6: =DM6*IFERROR(VLOOKUP($K6+DM$1,$K$3:$DN$98,4,0),0) -> 0 | DQ6: =DQ5+1 -> 22 | DR6: =VLOOKUP(DQ6,Male_MDT,6,0) -> 0.200984 | DS6: 1 | DT6: =1-DR6 -> 0.799016 | DU6: =DT6*IFERROR(VLOOKUP($DQ6+DT$1,$DQ$3:$HT$98,4,0),0) -> 0.63842018 | DV6: =DU6*IFERROR(VLOOKUP($DQ6+DU$1,$DQ$3:$HT$98,4,0),0) -> 0.51009261 | DW6: =DV6*IFERROR(VLOOKUP($DQ6+DV$1,$DQ$3:$HT$98,4,0),0) -> 0.40755176 | DX6: =DW6*IFERROR(VLOOKUP($DQ6+DW$1,$DQ$3:$HT$98,4,0),0) -> 0.32562081 | DY6: =DX6*IFERROR(VLOOKUP($DQ6+DX$1,$DQ$3:$HT$98,4,0),0) -> 0.2601554 | DZ6: =DY6*IFERROR(VLOOKUP($DQ6+DY$1,$DQ$3:$HT$98,4,0),0) -> 0.20784751 | EA6: =DZ6*IFERROR(VLOOKUP($DQ6+DZ$1,$DQ$3:$HT$98,4,0),0) -> 0.16605187 | EB6: =EA6*IFERROR(VLOOKUP($DQ6+EA$1,$DQ$3:$HT$98,4,0),0) -> 0.13265685 | ... HT6: =HS6*IFERROR(VLOOKUP($DQ6+HS$1,$DQ$3:$HT$98,4,0),0) -> 0
A7: 23 | B7: 0.0012 | C7: 0.00124 | K7: =K6+1 -> 23 | L7: =VLOOKUP(K7,Fe_MDT,6,0) -> 0.20096 | M7: 1 | N7: =1-L7 -> 0.79904 | O7: =N7*IFERROR(VLOOKUP($K7+N$1,$K$3:$DN$98,4,0),0) -> 0.63845853 | P7: =O7*IFERROR(VLOOKUP($K7+O$1,$K$3:$DN$98,4,0),0) -> 0.51013858 | Q7: =P7*IFERROR(VLOOKUP($K7+P$1,$K$3:$DN$98,4,0),0) -> 0.40760481 | R7: =Q7*IFERROR(VLOOKUP($K7+Q$1,$K$3:$DN$98,4,0),0) -> 0.32567298 | S7: =R7*IFERROR(VLOOKUP($K7+R$1,$K$3:$DN$98,4,0),0) -> 0.26020489 | T7: =S7*IFERROR(VLOOKUP($K7+S$1,$K$3:$DN$98,4,0),0) -> 0.2078933 | U7: =T7*IFERROR(VLOOKUP($K7+T$1,$K$3:$DN$98,4,0),0) -> 0.16609511 | V7: =U7*IFERROR(VLOOKUP($K7+U$1,$K$3:$DN$98,4,0),0) -> 0.1326967 | ... DN7: =DM7*IFERROR(VLOOKUP($K7+DM$1,$K$3:$DN$98,4,0),0) -> 0 | DQ7: =DQ6+1 -> 23 | DR7: =VLOOKUP(DQ7,Male_MDT,6,0) -> 0.200992 | DS7: 1 | DT7: =1-DR7 -> 0.799008 | DU7: =DT7*IFERROR(VLOOKUP($DQ7+DT$1,$DQ$3:$HT$98,4,0),0) -> 0.638401 | DV7: =DU7*IFERROR(VLOOKUP($DQ7+DU$1,$DQ$3:$HT$98,4,0),0) -> 0.51006708 | DW7: =DV7*IFERROR(VLOOKUP($DQ7+DV$1,$DQ$3:$HT$98,4,0),0) -> 0.40752727 | DX7: =DW7*IFERROR(VLOOKUP($DQ7+DW$1,$DQ$3:$HT$98,4,0),0) -> 0.32559473 | DY7: =DX7*IFERROR(VLOOKUP($DQ7+DX$1,$DQ$3:$HT$98,4,0),0) -> 0.26012935 | DZ7: =DY7*IFERROR(VLOOKUP($DQ7+DY$1,$DQ$3:$HT$98,4,0),0) -> 0.20782046 | EA7: =DZ7*IFERROR(VLOOKUP($DQ7+DZ$1,$DQ$3:$HT$98,4,0),0) -> 0.16602527 | EB7: =EA7*IFERROR(VLOOKUP($DQ7+EA$1,$DQ$3:$HT$98,4,0),0) -> 0.13263028 | ... HT7: =HS7*IFERROR(VLOOKUP($DQ7+HS$1,$DQ$3:$HT$98,4,0),0) -> 0
A8: 24 | B8: 0.00121 | C8: 0.00126 | K8: =K7+1 -> 24 | L8: =VLOOKUP(K8,Fe_MDT,6,0) -> 0.200968 | M8: 1 | N8: =1-L8 -> 0.799032 | O8: =N8*IFERROR(VLOOKUP($K8+N$1,$K$3:$DN$98,4,0),0) -> 0.63843935 | P8: =O8*IFERROR(VLOOKUP($K8+O$1,$K$3:$DN$98,4,0),0) -> 0.51011815 | Q8: =P8*IFERROR(VLOOKUP($K8+P$1,$K$3:$DN$98,4,0),0) -> 0.40758032 | R8: =Q8*IFERROR(VLOOKUP($K8+Q$1,$K$3:$DN$98,4,0),0) -> 0.32564689 | S8: =R8*IFERROR(VLOOKUP($K8+R$1,$K$3:$DN$98,4,0),0) -> 0.26017884 | T8: =S8*IFERROR(VLOOKUP($K8+S$1,$K$3:$DN$98,4,0),0) -> 0.20786833 | U8: =T8*IFERROR(VLOOKUP($K8+T$1,$K$3:$DN$98,4,0),0) -> 0.16607016 | V8: =U8*IFERROR(VLOOKUP($K8+U$1,$K$3:$DN$98,4,0),0) -> 0.13267279 | ... DN8: =DM8*IFERROR(VLOOKUP($K8+DM$1,$K$3:$DN$98,4,0),0) -> 0 | DQ8: =DQ7+1 -> 24 | DR8: =VLOOKUP(DQ8,Male_MDT,6,0) -> 0.201008 | DS8: 1 | DT8: =1-DR8 -> 0.798992 | DU8: =DT8*IFERROR(VLOOKUP($DQ8+DT$1,$DQ$3:$HT$98,4,0),0) -> 0.63837543 | DV8: =DU8*IFERROR(VLOOKUP($DQ8+DU$1,$DQ$3:$HT$98,4,0),0) -> 0.51004154 | DW8: =DV8*IFERROR(VLOOKUP($DQ8+DV$1,$DQ$3:$HT$98,4,0),0) -> 0.40749871 | DX8: =DW8*IFERROR(VLOOKUP($DQ8+DW$1,$DQ$3:$HT$98,4,0),0) -> 0.32556539 | DY8: =DX8*IFERROR(VLOOKUP($DQ8+DX$1,$DQ$3:$HT$98,4,0),0) -> 0.2600981 | DZ8: =DY8*IFERROR(VLOOKUP($DQ8+DY$1,$DQ$3:$HT$98,4,0),0) -> 0.20778925 | EA8: =DZ8*IFERROR(VLOOKUP($DQ8+DZ$1,$DQ$3:$HT$98,4,0),0) -> 0.16599369 | EB8: =EA8*IFERROR(VLOOKUP($DQ8+EA$1,$DQ$3:$HT$98,4,0),0) -> 0.13259841 | ... HT8: =HS8*IFERROR(VLOOKUP($DQ8+HS$1,$DQ$3:$HT$98,4,0),0) -> 0
A9: 25 | B9: 0.00123 | C9: 0.00128 | K9: =K8+1 -> 25 | L9: =VLOOKUP(K9,Fe_MDT,6,0) -> 0.200984 | M9: 1 | N9: =1-L9 -> 0.799016 | O9: =N9*IFERROR(VLOOKUP($K9+N$1,$K$3:$DN$98,4,0),0) -> 0.63842018 | P9: =O9*IFERROR(VLOOKUP($K9+O$1,$K$3:$DN$98,4,0),0) -> 0.51009261 | Q9: =P9*IFERROR(VLOOKUP($K9+P$1,$K$3:$DN$98,4,0),0) -> 0.40755176 | R9: =Q9*IFERROR(VLOOKUP($K9+Q$1,$K$3:$DN$98,4,0),0) -> 0.32561755 | S9: =R9*IFERROR(VLOOKUP($K9+R$1,$K$3:$DN$98,4,0),0) -> 0.26015019 | T9: =S9*IFERROR(VLOOKUP($K9+S$1,$K$3:$DN$98,4,0),0) -> 0.20783919 | U9: =T9*IFERROR(VLOOKUP($K9+T$1,$K$3:$DN$98,4,0),0) -> 0.1660419 | V9: =U9*IFERROR(VLOOKUP($K9+U$1,$K$3:$DN$98,4,0),0) -> 0.13264489 | ... DN9: =DM9*IFERROR(VLOOKUP($K9+DM$1,$K$3:$DN$98,4,0),0) -> 0 | DQ9: =DQ8+1 -> 25 | DR9: =VLOOKUP(DQ9,Male_MDT,6,0) -> 0.201024 | DS9: 1 | DT9: =1-DR9 -> 0.798976 | DU9: =DT9*IFERROR(VLOOKUP($DQ9+DT$1,$DQ$3:$HT$98,4,0),0) -> 0.63835626 | DV9: =DU9*IFERROR(VLOOKUP($DQ9+DU$1,$DQ$3:$HT$98,4,0),0) -> 0.51001601 | DW9: =DV9*IFERROR(VLOOKUP($DQ9+DV$1,$DQ$3:$HT$98,4,0),0) -> 0.40747015 | DX9: =DW9*IFERROR(VLOOKUP($DQ9+DW$1,$DQ$3:$HT$98,4,0),0) -> 0.32553279 | DY9: =DX9*IFERROR(VLOOKUP($DQ9+DX$1,$DQ$3:$HT$98,4,0),0) -> 0.26006424 | DZ9: =DY9*IFERROR(VLOOKUP($DQ9+DY$1,$DQ$3:$HT$98,4,0),0) -> 0.20775388 | EA9: =DZ9*IFERROR(VLOOKUP($DQ9+DZ$1,$DQ$3:$HT$98,4,0),0) -> 0.16595712 | EB9: =EA9*IFERROR(VLOOKUP($DQ9+EA$1,$DQ$3:$HT$98,4,0),0) -> 0.13256257 | ... HT9: =HS9*IFERROR(VLOOKUP($DQ9+HS$1,$DQ$3:$HT$98,4,0),0) -> 0
A10: 26 | B10: 0.00124 | C10: 0.00129 | K10: =K9+1 -> 26 | L10: =VLOOKUP(K10,Fe_MDT,6,0) -> 0.200992 | M10: 1 | N10: =1-L10 -> 0.799008 | O10: =N10*IFERROR(VLOOKUP($K10+N$1,$K$3:$DN$98,4,0),0) -> 0.638401 | P10: =O10*IFERROR(VLOOKUP($K10+O$1,$K$3:$DN$98,4,0),0) -> 0.51006708 | Q10: =P10*IFERROR(VLOOKUP($K10+P$1,$K$3:$DN$98,4,0),0) -> 0.40752319 | R10: =Q10*IFERROR(VLOOKUP($K10+Q$1,$K$3:$DN$98,4,0),0) -> 0.32558821 | S10: =R10*IFERROR(VLOOKUP($K10+R$1,$K$3:$DN$98,4,0),0) -> 0.26011893 | T10: =S10*IFERROR(VLOOKUP($K10+S$1,$K$3:$DN$98,4,0),0) -> 0.20780797 | U10: =T10*IFERROR(VLOOKUP($K10+T$1,$K$3:$DN$98,4,0),0) -> 0.16601031 | V10: =U10*IFERROR(VLOOKUP($K10+U$1,$K$3:$DN$98,4,0),0) -> 0.13261302 | ... DN10: =DM10*IFERROR(VLOOKUP($K10+DM$1,$K$3:$DN$98,4,0),0) -> 0 | DQ10: =DQ9+1 -> 26 | DR10: =VLOOKUP(DQ10,Male_MDT,6,0) -> 0.201032 | DS10: 1 | DT10: =1-DR10 -> 0.798968 | DU10: =DT10*IFERROR(VLOOKUP($DQ10+DT$1,$DQ$3:$HT$98,4,0),0) -> 0.63833708 | DV10: =DU10*IFERROR(VLOOKUP($DQ10+DU$1,$DQ$3:$HT$98,4,0),0) -> 0.50999047 | DW10: =DV10*IFERROR(VLOOKUP($DQ10+DV$1,$DQ$3:$HT$98,4,0),0) -> 0.40743751 | DX10: =DW10*IFERROR(VLOOKUP($DQ10+DW$1,$DQ$3:$HT$98,4,0),0) -> 0.32549694 | DY10: =DX10*IFERROR(VLOOKUP($DQ10+DX$1,$DQ$3:$HT$98,4,0),0) -> 0.26002518 | DZ10: =DY10*IFERROR(VLOOKUP($DQ10+DY$1,$DQ$3:$HT$98,4,0),0) -> 0.20771228 | EA10: =DZ10*IFERROR(VLOOKUP($DQ10+DZ$1,$DQ$3:$HT$98,4,0),0) -> 0.16591558 | EB10: =EA10*IFERROR(VLOOKUP($DQ10+EA$1,$DQ$3:$HT$98,4,0),0) -> 0.13252009 | ... HT10: =HS10*IFERROR(VLOOKUP($DQ10+HS$1,$DQ$3:$HT$98,4,0),0) -> 0
A11: 27 | B11: 0.00126 | C11: 0.00131 | K11: =K10+1 -> 27 | L11: =VLOOKUP(K11,Fe_MDT,6,0) -> 0.201008 | M11: 1 | N11: =1-L11 -> 0.798992 | O11: =N11*IFERROR(VLOOKUP($K11+N$1,$K$3:$DN$98,4,0),0) -> 0.63837543 | P11: =O11*IFERROR(VLOOKUP($K11+O$1,$K$3:$DN$98,4,0),0) -> 0.51003644 | Q11: =P11*IFERROR(VLOOKUP($K11+P$1,$K$3:$DN$98,4,0),0) -> 0.40749055 | R11: =Q11*IFERROR(VLOOKUP($K11+Q$1,$K$3:$DN$98,4,0),0) -> 0.32555235 | S11: =R11*IFERROR(VLOOKUP($K11+R$1,$K$3:$DN$98,4,0),0) -> 0.26008247 | T11: =S11*IFERROR(VLOOKUP($K11+S$1,$K$3:$DN$98,4,0),0) -> 0.20777052 | U11: =T11*IFERROR(VLOOKUP($K11+T$1,$K$3:$DN$98,4,0),0) -> 0.16597208 | V11: =U11*IFERROR(VLOOKUP($K11+U$1,$K$3:$DN$98,4,0),0) -> 0.13257451 | ... DN11: =DM11*IFERROR(VLOOKUP($K11+DM$1,$K$3:$DN$98,4,0),0) -> 0 | DQ11: =DQ10+1 -> 27 | DR11: =VLOOKUP(DQ11,Male_MDT,6,0) -> 0.201048 | DS11: 1 | DT11: =1-DR11 -> 0.798952 | DU11: =DT11*IFERROR(VLOOKUP($DQ11+DT$1,$DQ$3:$HT$98,4,0),0) -> 0.63831152 | DV11: =DU11*IFERROR(VLOOKUP($DQ11+DU$1,$DQ$3:$HT$98,4,0),0) -> 0.50995473 | DW11: =DV11*IFERROR(VLOOKUP($DQ11+DV$1,$DQ$3:$HT$98,4,0),0) -> 0.40739671 | DX11: =DW11*IFERROR(VLOOKUP($DQ11+DW$1,$DQ$3:$HT$98,4,0),0) -> 0.32545131 | DY11: =DX11*IFERROR(VLOOKUP($DQ11+DX$1,$DQ$3:$HT$98,4,0),0) -> 0.25997571 | DZ11: =DY11*IFERROR(VLOOKUP($DQ11+DY$1,$DQ$3:$HT$98,4,0),0) -> 0.20766236 | EA11: =DZ11*IFERROR(VLOOKUP($DQ11+DZ$1,$DQ$3:$HT$98,4,0),0) -> 0.16586408 | EB11: =EA11*IFERROR(VLOOKUP($DQ11+EA$1,$DQ$3:$HT$98,4,0),0) -> 0.13246834 | ... HT11: =HS11*IFERROR(VLOOKUP($DQ11+HS$1,$DQ$3:$HT$98,4,0),0) -> 0
A12: 28 | B12: 0.00128 | C12: 0.00133 | K12: =K11+1 -> 28 | L12: =VLOOKUP(K12,Fe_MDT,6,0) -> 0.201024 | M12: 1 | N12: =1-L12 -> 0.798976 | O12: =N12*IFERROR(VLOOKUP($K12+N$1,$K$3:$DN$98,4,0),0) -> 0.63834986 | P12: =O12*IFERROR(VLOOKUP($K12+O$1,$K$3:$DN$98,4,0),0) -> 0.51000579 | Q12: =P12*IFERROR(VLOOKUP($K12+P$1,$K$3:$DN$98,4,0),0) -> 0.40745383 | R12: =Q12*IFERROR(VLOOKUP($K12+Q$1,$K$3:$DN$98,4,0),0) -> 0.32551323 | S12: =R12*IFERROR(VLOOKUP($K12+R$1,$K$3:$DN$98,4,0),0) -> 0.2600408 | T12: =S12*IFERROR(VLOOKUP($K12+S$1,$K$3:$DN$98,4,0),0) -> 0.20772684 | U12: =T12*IFERROR(VLOOKUP($K12+T$1,$K$3:$DN$98,4,0),0) -> 0.16592721 | V12: =U12*IFERROR(VLOOKUP($K12+U$1,$K$3:$DN$98,4,0),0) -> 0.13253204 | ... DN12: =DM12*IFERROR(VLOOKUP($K12+DM$1,$K$3:$DN$98,4,0),0) -> 0 | DQ12: =DQ11+1 -> 28 | DR12: =VLOOKUP(DQ12,Male_MDT,6,0) -> 0.201064 | DS12: 1 | DT12: =1-DR12 -> 0.798936 | DU12: =DT12*IFERROR(VLOOKUP($DQ12+DT$1,$DQ$3:$HT$98,4,0),0) -> 0.63827956 | DV12: =DU12*IFERROR(VLOOKUP($DQ12+DU$1,$DQ$3:$HT$98,4,0),0) -> 0.50991388 | DW12: =DV12*IFERROR(VLOOKUP($DQ12+DV$1,$DQ$3:$HT$98,4,0),0) -> 0.40734776 | DX12: =DW12*IFERROR(VLOOKUP($DQ12+DW$1,$DQ$3:$HT$98,4,0),0) -> 0.32539591 | DY12: =DX12*IFERROR(VLOOKUP($DQ12+DX$1,$DQ$3:$HT$98,4,0),0) -> 0.25991844 | DZ12: =DY12*IFERROR(VLOOKUP($DQ12+DY$1,$DQ$3:$HT$98,4,0),0) -> 0.20760206 | EA12: =DZ12*IFERROR(VLOOKUP($DQ12+DZ$1,$DQ$3:$HT$98,4,0),0) -> 0.16580263 | EB12: =EA12*IFERROR(VLOOKUP($DQ12+EA$1,$DQ$3:$HT$98,4,0),0) -> 0.13240733 | ... HT12: =HS12*IFERROR(VLOOKUP($DQ12+HS$1,$DQ$3:$HT$98,4,0),0) -> 0
A13: 29 | B13: 0.0013 | C13: 0.00136 | K13: =K12+1 -> 29 | L13: =VLOOKUP(K13,Fe_MDT,6,0) -> 0.20104 | M13: 1 | N13: =1-L13 -> 0.79896 | O13: =N13*IFERROR(VLOOKUP($K13+N$1,$K$3:$DN$98,4,0),0) -> 0.6383243 | P13: =O13*IFERROR(VLOOKUP($K13+O$1,$K$3:$DN$98,4,0),0) -> 0.50997005 | Q13: =P13*IFERROR(VLOOKUP($K13+P$1,$K$3:$DN$98,4,0),0) -> 0.40741303 | R13: =Q13*IFERROR(VLOOKUP($K13+Q$1,$K$3:$DN$98,4,0),0) -> 0.3254676 | S13: =R13*IFERROR(VLOOKUP($K13+R$1,$K$3:$DN$98,4,0),0) -> 0.25999133 | T13: =S13*IFERROR(VLOOKUP($K13+S$1,$K$3:$DN$98,4,0),0) -> 0.20767484 | U13: =T13*IFERROR(VLOOKUP($K13+T$1,$K$3:$DN$98,4,0),0) -> 0.16587737 | V13: =U13*IFERROR(VLOOKUP($K13+U$1,$K$3:$DN$98,4,0),0) -> 0.13248294 | ... DN13: =DM13*IFERROR(VLOOKUP($K13+DM$1,$K$3:$DN$98,4,0),0) -> 0 | DQ13: =DQ12+1 -> 29 | DR13: =VLOOKUP(DQ13,Male_MDT,6,0) -> 0.201088 | DS13: 1 | DT13: =1-DR13 -> 0.798912 | DU13: =DT13*IFERROR(VLOOKUP($DQ13+DT$1,$DQ$3:$HT$98,4,0),0) -> 0.63824121 | DV13: =DU13*IFERROR(VLOOKUP($DQ13+DU$1,$DQ$3:$HT$98,4,0),0) -> 0.50986282 | DW13: =DV13*IFERROR(VLOOKUP($DQ13+DV$1,$DQ$3:$HT$98,4,0),0) -> 0.40728658 | DX13: =DW13*IFERROR(VLOOKUP($DQ13+DW$1,$DQ$3:$HT$98,4,0),0) -> 0.32533074 | DY13: =DX13*IFERROR(VLOOKUP($DQ13+DX$1,$DQ$3:$HT$98,4,0),0) -> 0.25984817 | DZ13: =DY13*IFERROR(VLOOKUP($DQ13+DY$1,$DQ$3:$HT$98,4,0),0) -> 0.2075293 | EA13: =DZ13*IFERROR(VLOOKUP($DQ13+DZ$1,$DQ$3:$HT$98,4,0),0) -> 0.16572958 | EB13: =EA13*IFERROR(VLOOKUP($DQ13+EA$1,$DQ$3:$HT$98,4,0),0) -> 0.13233573 | ... HT13: =HS13*IFERROR(VLOOKUP($DQ13+HS$1,$DQ$3:$HT$98,4,0),0) -> 0
A14: 30 | B14: 0.00132 | C14: 0.00139 | K14: =K13+1 -> 30 | L14: =VLOOKUP(K14,Fe_MDT,6,0) -> 0.201056 | M14: 1 | N14: =1-L14 -> 0.798944 | O14: =N14*IFERROR(VLOOKUP($K14+N$1,$K$3:$DN$98,4,0),0) -> 0.63829234 | P14: =O14*IFERROR(VLOOKUP($K14+O$1,$K$3:$DN$98,4,0),0) -> 0.5099292 | Q14: =P14*IFERROR(VLOOKUP($K14+P$1,$K$3:$DN$98,4,0),0) -> 0.40736408 | R14: =Q14*IFERROR(VLOOKUP($K14+Q$1,$K$3:$DN$98,4,0),0) -> 0.3254122 | S14: =R14*IFERROR(VLOOKUP($K14+R$1,$K$3:$DN$98,4,0),0) -> 0.25993146 | T14: =S14*IFERROR(VLOOKUP($K14+S$1,$K$3:$DN$98,4,0),0) -> 0.20761661 | U14: =T14*IFERROR(VLOOKUP($K14+T$1,$K$3:$DN$98,4,0),0) -> 0.16581924 | V14: =U14*IFERROR(VLOOKUP($K14+U$1,$K$3:$DN$98,4,0),0) -> 0.1324259 | ... DN14: =DM14*IFERROR(VLOOKUP($K14+DM$1,$K$3:$DN$98,4,0),0) -> 0 | DQ14: =DQ13+1 -> 30 | DR14: =VLOOKUP(DQ14,Male_MDT,6,0) -> 0.201112 | DS14: 1 | DT14: =1-DR14 -> 0.798888 | DU14: =DT14*IFERROR(VLOOKUP($DQ14+DT$1,$DQ$3:$HT$98,4,0),0) -> 0.63819647 | DV14: =DU14*IFERROR(VLOOKUP($DQ14+DU$1,$DQ$3:$HT$98,4,0),0) -> 0.50980155 | DW14: =DV14*IFERROR(VLOOKUP($DQ14+DV$1,$DQ$3:$HT$98,4,0),0) -> 0.40721725 | DX14: =DW14*IFERROR(VLOOKUP($DQ14+DW$1,$DQ$3:$HT$98,4,0),0) -> 0.32525256 | DY14: =DX14*IFERROR(VLOOKUP($DQ14+DX$1,$DQ$3:$HT$98,4,0),0) -> 0.25976491 | DZ14: =DY14*IFERROR(VLOOKUP($DQ14+DY$1,$DQ$3:$HT$98,4,0),0) -> 0.2074441 | EA14: =DZ14*IFERROR(VLOOKUP($DQ14+DZ$1,$DQ$3:$HT$98,4,0),0) -> 0.16564494 | EB14: =EA14*IFERROR(VLOOKUP($DQ14+EA$1,$DQ$3:$HT$98,4,0),0) -> 0.13225092 | ... HT14: =HS14*IFERROR(VLOOKUP($DQ14+HS$1,$DQ$3:$HT$98,4,0),0) -> 0
A15: 31 | B15: 0.00135 | C15: 0.00143 | K15: =K14+1 -> 31 | L15: =VLOOKUP(K15,Fe_MDT,6,0) -> 0.20108 | M15: 1 | N15: =1-L15 -> 0.79892 | O15: =N15*IFERROR(VLOOKUP($K15+N$1,$K$3:$DN$98,4,0),0) -> 0.63825399 | P15: =O15*IFERROR(VLOOKUP($K15+O$1,$K$3:$DN$98,4,0),0) -> 0.50987814 | Q15: =P15*IFERROR(VLOOKUP($K15+P$1,$K$3:$DN$98,4,0),0) -> 0.40730289 | R15: =Q15*IFERROR(VLOOKUP($K15+Q$1,$K$3:$DN$98,4,0),0) -> 0.32534378 | S15: =R15*IFERROR(VLOOKUP($K15+R$1,$K$3:$DN$98,4,0),0) -> 0.25986379 | T15: =S15*IFERROR(VLOOKUP($K15+S$1,$K$3:$DN$98,4,0),0) -> 0.20754801 | U15: =T15*IFERROR(VLOOKUP($K15+T$1,$K$3:$DN$98,4,0),0) -> 0.16575116 | V15: =U15*IFERROR(VLOOKUP($K15+U$1,$K$3:$DN$98,4,0),0) -> 0.13235959 | ... DN15: =DM15*IFERROR(VLOOKUP($K15+DM$1,$K$3:$DN$98,4,0),0) -> 0 | DQ15: =DQ14+1 -> 31 | DR15: =VLOOKUP(DQ15,Male_MDT,6,0) -> 0.201144 | DS15: 1 | DT15: =1-DR15 -> 0.798856 | DU15: =DT15*IFERROR(VLOOKUP($DQ15+DT$1,$DQ$3:$HT$98,4,0),0) -> 0.63813895 | DV15: =DU15*IFERROR(VLOOKUP($DQ15+DU$1,$DQ$3:$HT$98,4,0),0) -> 0.50973008 | DW15: =DV15*IFERROR(VLOOKUP($DQ15+DV$1,$DQ$3:$HT$98,4,0),0) -> 0.40713161 | DX15: =DW15*IFERROR(VLOOKUP($DQ15+DW$1,$DQ$3:$HT$98,4,0),0) -> 0.3251581 | DY15: =DX15*IFERROR(VLOOKUP($DQ15+DX$1,$DQ$3:$HT$98,4,0),0) -> 0.25966606 | DZ15: =DY15*IFERROR(VLOOKUP($DQ15+DY$1,$DQ$3:$HT$98,4,0),0) -> 0.20734439 | EA15: =DZ15*IFERROR(VLOOKUP($DQ15+DZ$1,$DQ$3:$HT$98,4,0),0) -> 0.16554376 | EB15: =EA15*IFERROR(VLOOKUP($DQ15+EA$1,$DQ$3:$HT$98,4,0),0) -> 0.1321516 | ... HT15: =HS15*IFERROR(VLOOKUP($DQ15+HS$1,$DQ$3:$HT$98,4,0),0) -> 0
A16: 32 | B16: 0.00138 | C16: 0.00148 | K16: =K15+1 -> 32 | L16: =VLOOKUP(K16,Fe_MDT,6,0) -> 0.201104 | M16: 1 | N16: =1-L16 -> 0.798896 | O16: =N16*IFERROR(VLOOKUP($K16+N$1,$K$3:$DN$98,4,0),0) -> 0.63820925 | P16: =O16*IFERROR(VLOOKUP($K16+O$1,$K$3:$DN$98,4,0),0) -> 0.50981687 | Q16: =P16*IFERROR(VLOOKUP($K16+P$1,$K$3:$DN$98,4,0),0) -> 0.40722948 | R16: =Q16*IFERROR(VLOOKUP($K16+Q$1,$K$3:$DN$98,4,0),0) -> 0.32526885 | S16: =R16*IFERROR(VLOOKUP($K16+R$1,$K$3:$DN$98,4,0),0) -> 0.25978572 | T16: =S16*IFERROR(VLOOKUP($K16+S$1,$K$3:$DN$98,4,0),0) -> 0.20746903 | U16: =T16*IFERROR(VLOOKUP($K16+T$1,$K$3:$DN$98,4,0),0) -> 0.16567315 | V16: =U16*IFERROR(VLOOKUP($K16+U$1,$K$3:$DN$98,4,0),0) -> 0.14055321 | ... DN16: =DM16*IFERROR(VLOOKUP($K16+DM$1,$K$3:$DN$98,4,0),0) -> 0 | DQ16: =DQ15+1 -> 32 | DR16: =VLOOKUP(DQ16,Male_MDT,6,0) -> 0.201184 | DS16: 1 | DT16: =1-DR16 -> 0.798816 | DU16: =DT16*IFERROR(VLOOKUP($DQ16+DT$1,$DQ$3:$HT$98,4,0),0) -> 0.63807505 | DV16: =DU16*IFERROR(VLOOKUP($DQ16+DU$1,$DQ$3:$HT$98,4,0),0) -> 0.5096433 | DW16: =DV16*IFERROR(VLOOKUP($DQ16+DV$1,$DQ$3:$HT$98,4,0),0) -> 0.40702968 | DX16: =DW16*IFERROR(VLOOKUP($DQ16+DW$1,$DQ$3:$HT$98,4,0),0) -> 0.32504739 | DY16: =DX16*IFERROR(VLOOKUP($DQ16+DX$1,$DQ$3:$HT$98,4,0),0) -> 0.25955164 | DZ16: =DY16*IFERROR(VLOOKUP($DQ16+DY$1,$DQ$3:$HT$98,4,0),0) -> 0.20722603 | EA16: =DZ16*IFERROR(VLOOKUP($DQ16+DZ$1,$DQ$3:$HT$98,4,0),0) -> 0.16542605 | EB16: =EA16*IFERROR(VLOOKUP($DQ16+EA$1,$DQ$3:$HT$98,4,0),0) -> 0.14028874 | ... HT16: =HS16*IFERROR(VLOOKUP($DQ16+HS$1,$DQ$3:$HT$98,4,0),0) -> 0
... A98: 114 | B98: 0.829 | C98: 1 | K98: =K97+1 -> 114 | L98: =VLOOKUP(K98,Fe_MDT,6,0) -> 0.829 | M98: 1 | N98: =1-L98 -> 0.171 | O98: =N98*IFERROR(VLOOKUP($K98+N$1,$K$3:$DN$98,4,0),0) -> 0 | P98: =O98*IFERROR(VLOOKUP($K98+O$1,$K$3:$DN$98,4,0),0) -> 0 | Q98: =P98*IFERROR(VLOOKUP($K98+P$1,$K$3:$DN$98,4,0),0) -> 0 | R98: =Q98*IFERROR(VLOOKUP($K98+Q$1,$K$3:$DN$98,4,0),0) -> 0 | S98: =R98*IFERROR(VLOOKUP($K98+R$1,$K$3:$DN$98,4,0),0) -> 0 | T98: =S98*IFERROR(VLOOKUP($K98+S$1,$K$3:$DN$98,4,0),0) -> 0 | U98: =T98*IFERROR(VLOOKUP($K98+T$1,$K$3:$DN$98,4,0),0) -> 0 | V98: =U98*IFERROR(VLOOKUP($K98+U$1,$K$3:$DN$98,4,0),0) -> 0 | ... DN98: =DM98*IFERROR(VLOOKUP($K98+DM$1,$K$3:$DN$98,4,0),0) -> 0 | DQ98: =DQ97+1 -> 114 | DR98: =VLOOKUP(DQ98,Male_MDT,6,0) -> 1 | DS98: 1 | DT98: =1-DR98 -> 0 | DU98: =DT98*IFERROR(VLOOKUP($DQ98+DT$1,$DQ$3:$HT$98,4,0),0) -> 0 | DV98: =DU98*IFERROR(VLOOKUP($DQ98+DU$1,$DQ$3:$HT$98,4,0),0) -> 0 | DW98: =DV98*IFERROR(VLOOKUP($DQ98+DV$1,$DQ$3:$HT$98,4,0),0) -> 0 | DX98: =DW98*IFERROR(VLOOKUP($DQ98+DW$1,$DQ$3:$HT$98,4,0),0) -> 0 | DY98: =DX98*IFERROR(VLOOKUP($DQ98+DX$1,$DQ$3:$HT$98,4,0),0) -> 0 | DZ98: =DY98*IFERROR(VLOOKUP($DQ98+DY$1,$DQ$3:$HT$98,4,0),0) -> 0 | EA98: =DZ98*IFERROR(VLOOKUP($DQ98+DZ$1,$DQ$3:$HT$98,4,0),0) -> 0 | EB98: =EA98*IFERROR(VLOOKUP($DQ98+EA$1,$DQ$3:$HT$98,4,0),0) -> 0 | ... HT98: =HS98*IFERROR(VLOOKUP($DQ98+HS$1,$DQ$3:$HT$98,4,0),0) -> 0
A99: 115 | B99: 0.909 | C99: 1
A100: 116 | B100: 1 | C100: 1

Sheet MDT
G1: 1 | H1: 2 | I1: 3 | J1: 4 | K1: 5 | L1: 6 | M1: 7 | O1: 1 | P1: 2 | Q1: 3 | R1: 4 | S1: 5 | T1: 6 | U1: 7
A2: Withdrawal Probabilities | H2: MALES | P2: FEMALES
A3: Age x | B3: Withdrawal | D3: Age limit | E3: Withdrawal | G3: Age x | H3: qxd | I3: qxw | J3: (aq)dX | K3: (aq)wX | L3: (aq)X | M3: (ap)X | O3: Age x | P3: qxd | Q3: qxw | R3: (aq)dX | S3: (aq)wX | T3: (aq)X | U3: (ap)X
A4: 20 | B4: =IF(A4<$D$4,0,IF(A4<$D$5,$E$4,IF(A4<$D$6,$E$5,IF(A4<$D$7,$E$6,IF(A4<$D$8,$E$7,0))))) -> 0.2 | D4: 20 | E4: 0.2 | G4: 20 | H4: =VLOOKUP($G4,Mortality_Table,3,FALSE) -> 0.00118 | I4: =VLOOKUP($G4,Withdrawal_Probs,2,FALSE) -> 0.2 | J4: =$H4*(1-0.5*$I4) -> 0.001062 | K4: =$I4*(1-0.5*$H4) -> 0.199882 | L4: =SUM(J4:K4) -> 0.200944 | M4: =1-L4 -> 0.799056 | O4: 20 | P4: =VLOOKUP($G4,Mortality_Table,2,FALSE) -> 0.00117 | Q4: =VLOOKUP($G4,Withdrawal_Probs,2,FALSE) -> 0.2 | R4: =$P4*(1-0.5*$Q4) -> 0.001053 | S4: =$Q4*(1-0.5*$P4) -> 0.199883 | T4: =SUM(R4:S4) -> 0.200936 | U4: =1-T4 -> 0.799064
A5: 21 | B5: =IF(A5<$D$4,0,IF(A5<$D$5,$E$4,IF(A5<$D$6,$E$5,IF(A5<$D$7,$E$6,IF(A5<$D$8,$E$7,0))))) -> 0.2 | D5: 40 | E5: 0.15 | G5: 21 | H5: =VLOOKUP($G5,Mortality_Table,3,FALSE) -> 0.0012 | I5: =VLOOKUP($G5,Withdrawal_Probs,2,FALSE) -> 0.2 | J5: =$H5*(1-0.5*$I5) -> 0.00108 | K5: =$I5*(1-0.5*$H5) -> 0.19988 | L5: =SUM(J5:K5) -> 0.20096 | M5: =1-L5 -> 0.79904 | O5: 21 | P5: =VLOOKUP($G5,Mortality_Table,2,FALSE) -> 0.00118 | Q5: =VLOOKUP($G5,Withdrawal_Probs,2,FALSE) -> 0.2 | R5: =$P5*(1-0.5*$Q5) -> 0.001062 | S5: =$Q5*(1-0.5*$P5) -> 0.199882 | T5: =SUM(R5:S5) -> 0.200944 | U5: =1-T5 -> 0.799056
A6: 22 | B6: =IF(A6<$D$4,0,IF(A6<$D$5,$E$4,IF(A6<$D$6,$E$5,IF(A6<$D$7,$E$6,IF(A6<$D$8,$E$7,0))))) -> 0.2 | D6: 50 | E6: 0.1 | G6: 22 | H6: =VLOOKUP($G6,Mortality_Table,3,FALSE) -> 0.00123 | I6: =VLOOKUP($G6,Withdrawal_Probs,2,FALSE) -> 0.2 | J6: =$H6*(1-0.5*$I6) -> 0.001107 | K6: =$I6*(1-0.5*$H6) -> 0.199877 | L6: =SUM(J6:K6) -> 0.200984 | M6: =1-L6 -> 0.799016 | O6: 22 | P6: =VLOOKUP($G6,Mortality_Table,2,FALSE) -> 0.00119 | Q6: =VLOOKUP($G6,Withdrawal_Probs,2,FALSE) -> 0.2 | R6: =$P6*(1-0.5*$Q6) -> 0.001071 | S6: =$Q6*(1-0.5*$P6) -> 0.199881 | T6: =SUM(R6:S6) -> 0.200952 | U6: =1-T6 -> 0.799048
A7: 23 | B7: =IF(A7<$D$4,0,IF(A7<$D$5,$E$4,IF(A7<$D$6,$E$5,IF(A7<$D$7,$E$6,IF(A7<$D$8,$E$7,0))))) -> 0.2 | D7: 55 | E7: 0.05 | G7: 23 | H7: =VLOOKUP($G7,Mortality_Table,3,FALSE) -> 0.00124 | I7: =VLOOKUP($G7,Withdrawal_Probs,2,FALSE) -> 0.2 | J7: =$H7*(1-0.5*$I7) -> 0.001116 | K7: =$I7*(1-0.5*$H7) -> 0.199876 | L7: =SUM(J7:K7) -> 0.200992 | M7: =1-L7 -> 0.799008 | O7: 23 | P7: =VLOOKUP($G7,Mortality_Table,2,FALSE) -> 0.0012 | Q7: =VLOOKUP($G7,Withdrawal_Probs,2,FALSE) -> 0.2 | R7: =$P7*(1-0.5*$Q7) -> 0.00108 | S7: =$Q7*(1-0.5*$P7) -> 0.19988 | T7: =SUM(R7:S7) -> 0.20096 | U7: =1-T7 -> 0.79904
A8: 24 | B8: =IF(A8<$D$4,0,IF(A8<$D$5,$E$4,IF(A8<$D$6,$E$5,IF(A8<$D$7,$E$6,IF(A8<$D$8,$E$7,0))))) -> 0.2 | D8: 60 | G8: 24 | H8: =VLOOKUP($G8,Mortality_Table,3,FALSE) -> 0.00126 | I8: =VLOOKUP($G8,Withdrawal_Probs,2,FALSE) -> 0.2 | J8: =$H8*(1-0.5*$I8) -> 0.001134 | K8: =$I8*(1-0.5*$H8) -> 0.199874 | L8: =SUM(J8:K8) -> 0.201008 | M8: =1-L8 -> 0.798992 | O8: 24 | P8: =VLOOKUP($G8,Mortality_Table,2,FALSE) -> 0.00121 | Q8: =VLOOKUP($G8,Withdrawal_Probs,2,FALSE) -> 0.2 | R8: =$P8*(1-0.5*$Q8) -> 0.001089 | S8: =$Q8*(1-0.5*$P8) -> 0.199879 | T8: =SUM(R8:S8) -> 0.200968 | U8: =1-T8 -> 0.799032
A9: 25 | B9: =IF(A9<$D$4,0,IF(A9<$D$5,$E$4,IF(A9<$D$6,$E$5,IF(A9<$D$7,$E$6,IF(A9<$D$8,$E$7,0))))) -> 0.2 | G9: 25 | H9: =VLOOKUP($G9,Mortality_Table,3,FALSE) -> 0.00128 | I9: =VLOOKUP($G9,Withdrawal_Probs,2,FALSE) -> 0.2 | J9: =$H9*(1-0.5*$I9) -> 0.001152 | K9: =$I9*(1-0.5*$H9) -> 0.199872 | L9: =SUM(J9:K9) -> 0.201024 | M9: =1-L9 -> 0.798976 | O9: 25 | P9: =VLOOKUP($G9,Mortality_Table,2,FALSE) -> 0.00123 | Q9: =VLOOKUP($G9,Withdrawal_Probs,2,FALSE) -> 0.2 | R9: =$P9*(1-0.5*$Q9) -> 0.001107 | S9: =$Q9*(1-0.5*$P9) -> 0.199877 | T9: =SUM(R9:S9) -> 0.200984 | U9: =1-T9 -> 0.799016
A10: 26 | B10: =IF(A10<$D$4,0,IF(A10<$D$5,$E$4,IF(A10<$D$6,$E$5,IF(A10<$D$7,$E$6,IF(A10<$D$8,$E$7,0))))) -> 0.2 | G10: 26 | H10: =VLOOKUP($G10,Mortality_Table,3,FALSE) -> 0.00129 | I10: =VLOOKUP($G10,Withdrawal_Probs,2,FALSE) -> 0.2 | J10: =$H10*(1-0.5*$I10) -> 0.001161 | K10: =$I10*(1-0.5*$H10) -> 0.199871 | L10: =SUM(J10:K10) -> 0.201032 | M10: =1-L10 -> 0.798968 | O10: 26 | P10: =VLOOKUP($G10,Mortality_Table,2,FALSE) -> 0.00124 | Q10: =VLOOKUP($G10,Withdrawal_Probs,2,FALSE) -> 0.2 | R10: =$P10*(1-0.5*$Q10) -> 0.001116 | S10: =$Q10*(1-0.5*$P10) -> 0.199876 | T10: =SUM(R10:S10) -> 0.200992 | U10: =1-T10 -> 0.799008
A11: 27 | B11: =IF(A11<$D$4,0,IF(A11<$D$5,$E$4,IF(A11<$D$6,$E$5,IF(A11<$D$7,$E$6,IF(A11<$D$8,$E$7,0))))) -> 0.2 | G11: 27 | H11: =VLOOKUP($G11,Mortality_Table,3,FALSE) -> 0.00131 | I11: =VLOOKUP($G11,Withdrawal_Probs,2,FALSE) -> 0.2 | J11: =$H11*(1-0.5*$I11) -> 0.001179 | K11: =$I11*(1-0.5*$H11) -> 0.199869 | L11: =SUM(J11:K11) -> 0.201048 | M11: =1-L11 -> 0.798952 | O11: 27 | P11: =VLOOKUP($G11,Mortality_Table,2,FALSE) -> 0.00126 | Q11: =VLOOKUP($G11,Withdrawal_Probs,2,FALSE) -> 0.2 | R11: =$P11*(1-0.5*$Q11) -> 0.001134 | S11: =$Q11*(1-0.5*$P11) -> 0.199874 | T11: =SUM(R11:S11) -> 0.201008 | U11: =1-T11 -> 0.798992
A12: 28 | B12: =IF(A12<$D$4,0,IF(A12<$D$5,$E$4,IF(A12<$D$6,$E$5,IF(A12<$D$7,$E$6,IF(A12<$D$8,$E$7,0))))) -> 0.2 | G12: 28 | H12: =VLOOKUP($G12,Mortality_Table,3,FALSE) -> 0.00133 | I12: =VLOOKUP($G12,Withdrawal_Probs,2,FALSE) -> 0.2 | J12: =$H12*(1-0.5*$I12) -> 0.001197 | K12: =$I12*(1-0.5*$H12) -> 0.199867 | L12: =SUM(J12:K12) -> 0.201064 | M12: =1-L12 -> 0.798936 | O12: 28 | P12: =VLOOKUP($G12,Mortality_Table,2,FALSE) -> 0.00128 | Q12: =VLOOKUP($G12,Withdrawal_Probs,2,FALSE) -> 0.2 | R12: =$P12*(1-0.5*$Q12) -> 0.001152 | S12: =$Q12*(1-0.5*$P12) -> 0.199872 | T12: =SUM(R12:S12) -> 0.201024 | U12: =1-T12 -> 0.798976
A13: 29 | B13: =IF(A13<$D$4,0,IF(A13<$D$5,$E$4,IF(A13<$D$6,$E$5,IF(A13<$D$7,$E$6,IF(A13<$D$8,$E$7,0))))) -> 0.2 | G13: 29 | H13: =VLOOKUP($G13,Mortality_Table,3,FALSE) -> 0.00136 | I13: =VLOOKUP($G13,Withdrawal_Probs,2,FALSE) -> 0.2 | J13: =$H13*(1-0.5*$I13) -> 0.001224 | K13: =$I13*(1-0.5*$H13) -> 0.199864 | L13: =SUM(J13:K13) -> 0.201088 | M13: =1-L13 -> 0.798912 | O13: 29 | P13: =VLOOKUP($G13,Mortality_Table,2,FALSE) -> 0.0013 | Q13: =VLOOKUP($G13,Withdrawal_Probs,2,FALSE) -> 0.2 | R13: =$P13*(1-0.5*$Q13) -> 0.00117 | S13: =$Q13*(1-0.5*$P13) -> 0.19987 | T13: =SUM(R13:S13) -> 0.20104 | U13: =1-T13 -> 0.79896
A14: 30 | B14: =IF(A14<$D$4,0,IF(A14<$D$5,$E$4,IF(A14<$D$6,$E$5,IF(A14<$D$7,$E$6,IF(A14<$D$8,$E$7,0))))) -> 0.2 | G14: 30 | H14: =VLOOKUP($G14,Mortality_Table,3,FALSE) -> 0.00139 | I14: =VLOOKUP($G14,Withdrawal_Probs,2,FALSE) -> 0.2 | J14: =$H14*(1-0.5*$I14) -> 0.001251 | K14: =$I14*(1-0.5*$H14) -> 0.199861 | L14: =SUM(J14:K14) -> 0.201112 | M14: =1-L14 -> 0.798888 | O14: 30 | P14: =VLOOKUP($G14,Mortality_Table,2,FALSE) -> 0.00132 | Q14: =VLOOKUP($G14,Withdrawal_Probs,2,FALSE) -> 0.2 | R14: =$P14*(1-0.5*$Q14) -> 0.001188 | S14: =$Q14*(1-0.5*$P14) -> 0.199868 | T14: =SUM(R14:S14) -> 0.201056 | U14: =1-T14 -> 0.798944
A15: 31 | B15: =IF(A15<$D$4,0,IF(A15<$D$5,$E$4,IF(A15<$D$6,$E$5,IF(A15<$D$7,$E$6,IF(A15<$D$8,$E$7,0))))) -> 0.2 | G15: 31 | H15: =VLOOKUP($G15,Mortality_Table,3,FALSE) -> 0.00143 | I15: =VLOOKUP($G15,Withdrawal_Probs,2,FALSE) -> 0.2 | J15: =$H15*(1-0.5*$I15) -> 0.001287 | K15: =$I15*(1-0.5*$H15) -> 0.199857 | L15: =SUM(J15:K15) -> 0.201144 | M15: =1-L15 -> 0.798856 | O15: 31 | P15: =VLOOKUP($G15,Mortality_Table,2,FALSE) -> 0.00135 | Q15: =VLOOKUP($G15,Withdrawal_Probs,2,FALSE) -> 0.2 | R15: =$P15*(1-0.5*$Q15) -> 0.001215 | S15: =$Q15*(1-0.5*$P15) -> 0.199865 | T15: =SUM(R15:S15) -> 0.20108 | U15: =1-T15 -> 0.79892
A16: 32 | B16: =IF(A16<$D$4,0,IF(A16<$D$5,$E$4,IF(A16<$D$6,$E$5,IF(A16<$D$7,$E$6,IF(A16<$D$8,$E$7,0))))) -> 0.2 | G16: 32 | H16: =VLOOKUP($G16,Mortality_Table,3,FALSE) -> 0.00148 | I16: =VLOOKUP($G16,Withdrawal_Probs,2,FALSE) -> 0.2 | J16: =$H16*(1-0.5*$I16) -> 0.001332 | K16: =$I16*(1-0.5*$H16) -> 0.199852 | L16: =SUM(J16:K16) -> 0.201184 | M16: =1-L16 -> 0.798816 | O16: 32 | P16: =VLOOKUP($G16,Mortality_Table,2,FALSE) -> 0.00138 | Q16: =VLOOKUP($G16,Withdrawal_Probs,2,FALSE) -> 0.2 | R16: =$P16*(1-0.5*$Q16) -> 0.001242 | S16: =$Q16*(1-0.5*$P16) -> 0.199862 | T16: =SUM(R16:S16) -> 0.201104 | U16: =1-T16 -> 0.798896
A17: 33 | B17: =IF(A17<$D$4,0,IF(A17<$D$5,$E$4,IF(A17<$D$6,$E$5,IF(A17<$D$7,$E$6,IF(A17<$D$8,$E$7,0))))) -> 0.2 | G17: 33 | H17: =VLOOKUP($G17,Mortality_Table,3,FALSE) -> 0.00153 | I17: =VLOOKUP($G17,Withdrawal_Probs,2,FALSE) -> 0.2 | J17: =$H17*(1-0.5*$I17) -> 0.001377 | K17: =$I17*(1-0.5*$H17) -> 0.199847 | L17: =SUM(J17:K17) -> 0.201224 | M17: =1-L17 -> 0.798776 | O17: 33 | P17: =VLOOKUP($G17,Mortality_Table,2,FALSE) -> 0.00142 | Q17: =VLOOKUP($G17,Withdrawal_Probs,2,FALSE) -> 0.2 | R17: =$P17*(1-0.5*$Q17) -> 0.001278 | S17: =$Q17*(1-0.5*$P17) -> 0.199858 | T17: =SUM(R17:S17) -> 0.201136 | U17: =1-T17 -> 0.798864
A18: 34 | B18: =IF(A18<$D$4,0,IF(A18<$D$5,$E$4,IF(A18<$D$6,$E$5,IF(A18<$D$7,$E$6,IF(A18<$D$8,$E$7,0))))) -> 0.2 | G18: 34 | H18: =VLOOKUP($G18,Mortality_Table,3,FALSE) -> 0.0016 | I18: =VLOOKUP($G18,Withdrawal_Probs,2,FALSE) -> 0.2 | J18: =$H18*(1-0.5*$I18) -> 0.00144 | K18: =$I18*(1-0.5*$H18) -> 0.19984 | L18: =SUM(J18:K18) -> 0.20128 | M18: =1-L18 -> 0.79872 | O18: 34 | P18: =VLOOKUP($G18,Mortality_Table,2,FALSE) -> 0.00147 | Q18: =VLOOKUP($G18,Withdrawal_Probs,2,FALSE) -> 0.2 | R18: =$P18*(1-0.5*$Q18) -> 0.001323 | S18: =$Q18*(1-0.5*$P18) -> 0.199853 | T18: =SUM(R18:S18) -> 0.201176 | U18: =1-T18 -> 0.798824
A19: 35 | B19: =IF(A19<$D$4,0,IF(A19<$D$5,$E$4,IF(A19<$D$6,$E$5,IF(A19<$D$7,$E$6,IF(A19<$D$8,$E$7,0))))) -> 0.2 | G19: 35 | H19: =VLOOKUP($G19,Mortality_Table,3,FALSE) -> 0.00168 | I19: =VLOOKUP($G19,Withdrawal_Probs,2,FALSE) -> 0.2 | J19: =$H19*(1-0.5*$I19) -> 0.001512 | K19: =$I19*(1-0.5*$H19) -> 0.199832 | L19: =SUM(J19:K19) -> 0.201344 | M19: =1-L19 -> 0.798656 | O19: 35 | P19: =VLOOKUP($G19,Mortality_Table,2,FALSE) -> 0.00153 | Q19: =VLOOKUP($G19,Withdrawal_Probs,2,FALSE) -> 0.2 | R19: =$P19*(1-0.5*$Q19) -> 0.001377 | S19: =$Q19*(1-0.5*$P19) -> 0.199847 | T19: =SUM(R19:S19) -> 0.201224 | U19: =1-T19 -> 0.798776
A20: 36 | B20: =IF(A20<$D$4,0,IF(A20<$D$5,$E$4,IF(A20<$D$6,$E$5,IF(A20<$D$7,$E$6,IF(A20<$D$8,$E$7,0))))) -> 0.2 | G20: 36 | H20: =VLOOKUP($G20,Mortality_Table,3,FALSE) -> 0.00177 | I20: =VLOOKUP($G20,Withdrawal_Probs,2,FALSE) -> 0.2 | J20: =$H20*(1-0.5*$I20) -> 0.001593 | K20: =$I20*(1-0.5*$H20) -> 0.199823 | L20: =SUM(J20:K20) -> 0.201416 | M20: =1-L20 -> 0.798584 | O20: 36 | P20: =VLOOKUP($G20,Mortality_Table,2,FALSE) -> 0.00158 | Q20: =VLOOKUP($G20,Withdrawal_Probs,2,FALSE) -> 0.2 | R20: =$P20*(1-0.5*$Q20) -> 0.001422 | S20: =$Q20*(1-0.5*$P20) -> 0.199842 | T20: =SUM(R20:S20) -> 0.201264 | U20: =1-T20 -> 0.798736
... A100: 116 | B100: =IF(A100<$D$4,0,IF(A100<$D$5,$E$4,IF(A100<$D$6,$E$5,IF(A100<$D$7,$E$6,IF(A100<$D$8,$E$7,0))))) -> 0 | G100: 116 | H100: =VLOOKUP($G100,Mortality_Table,3,FALSE) -> 1 | I100: =VLOOKUP($G100,Withdrawal_Probs,2,FALSE) -> 0 | J100: =$H100*(1-0.5*$I100) -> 1 | K100: =$I100*(1-0.5*$H100) -> 0 | L100: =SUM(J100:K100) -> 1 | M100: =1-L100 -> 0 | O100: 116 | P100: =VLOOKUP($G100,Mortality_Table,2,FALSE) -> 1 | Q100: =VLOOKUP($G100,Withdrawal_Probs,2,FALSE) -> 0 | R100: =$P100*(1-0.5*$Q100) -> 1 | S100: =$Q100*(1-0.5*$P100) -> 0 | T100: =SUM(R100:S100) -> 1 | U100: =1-T100 -> 0

Sheet Membership Analysis
A1: Scheme Establishment | B1: ='Scheme Details'!C4 -> 35674 | C1: MALE | D1: =COUNTIF($D$4:$D$950,C1)/COUNTA($D$4:$D$950) -> 0.5 | F1: =0.5*SUMIF(Age,"<35",Fund_Credits)/SUM(Fund_Credits) -> 0.058121574 | I1: =SUMIF(Age,">=50",Fund_Credits)/SUM(Fund_Credits) -> 0.43762519 | J1: =0.5*SUMIF(Age,"<35",Fund_Credits)/SUM(Fund_Credits) -> 0.058121574 | K1: ='Investment Income'!$J$5 -> 714517650 | L1: =K1/L2-1 -> 4.3421432 | Y1: =Y2/SUM(Fund_Credits) -> 0.0053792055 | BS1: =SUM(BS4:BS950) -> 3.1482148e+08 | BT1: =SUM(BT4:BT950) -> 4.4780565e+08 | BU1: =SUM(BU4:BU950) -> 5.1423604e+08 | BV1: =SUM(BV4:BV204) -> 2.2565505e+08 | BW1: =SUM(BW4:BW204) -> 2.4116694e+08 | BX1: =SUM(BX4:BX204) -> 2.4458892e+08 | BY1: =SUM(BY4:BY204) -> 2.3902586e+08 | BZ1: =SUM(BZ4:BZ204) -> 2.4772777e+08 | CA1: =SUM(CA4:CA204) -> 2.4282735e+08 | CB1: =SUM(CB4:CB204) -> 2.4159995e+08 | CC1: =SUM(CC4:CC204) -> 2.4189079e+08 | ... DH1: =SUM(DH4:DH204) -> 0 | DK1: Annuity Ratio | DL1: 0.67 | DM1: =AVERAGE(DN4:DN950) -> 0.066916379 | DN1: =SUMPRODUCT($DJ$4:$DJ$950,$DN$4:$DN$950)/SUMIF($DN$4:$DN$950,">"&0,$DJ$4:$DJ$950) -> 0.09427732 | DP1: =SUM(DP4:DP950)/$L$2 -> 0.31254403 | DQ1: =SUM(DQ4:DQ950)/$L$2 -> 0.43880089 | DR1: =SUM(DR4:DR950)/$L$2 -> 0.50345286
A2: =COUNTA(A4:A950) -> 500 | C2: FEMALE | D2: =COUNTIF($D$4:$D$950,C2)/COUNTA($D$4:$D$950) -> 0.5 | H2: 12 | I2: Fund Credit as at Analysis Date | L2: =SUM(L4:L950) -> 1.3375112e+08 | M2: DATA CHECKS | T2: =AVERAGE(Age) -> 47.262 | W2: =SUMPRODUCT(Years_To_Retirement,Fund_Credits)/SUM(Fund_Credits) -> 12.60523 | X2: =SUM(X4:X950) -> 1.6859637e+09 | Y2: =SUMPRODUCT($Y$4:$Y$950,Fund_Credits) -> 719474.77 | AB2: SALARY PROJECTIONS (ADDITIONAL PENSIONABLE YEARS OF SERVICE) | BS2: PROJECTED FUND CREDITS (ADDITIONAL PENSIONABLE YEARS OF SERVICE) | DJ2: IRR Calcs | DP2: Liquidity Requirement
A3: M/No | B3: Member Name | C3: Membership Status | D3: Gender | E3: Date of Birth | F3: Date of Employment | G3: Date of Joining Scheme | H3: Annual Salary as at Analysis Date | I3: Employee | J3: Employer | K3: AVC | L3: Accumulated Fund Credit as at Analysis Date | M3: Check for Duplicates in ID | N3: Unusual Ages | O3: DOJS>DOB | P3: DOJS after Est | Q3: DOJS after DOE | R3: DOE>DOB | S3: Age at Employment | T3: Age Last Birthday | U3: Age at Joining Scheme | V3: Years in Service | W3: Years To Retirement | X3: FC*YTR | Y3: qx | Z3: ytr(ap)x | AB3: 1 | AC3: 2 | AD3: 3 | AE3: 4 | AF3: 5 | AG3: 6 | AH3: 7 | AI3: 8 | AJ3: 9 | AK3: 10 | AL3: 11 | AM3: 12 | AN3: 13 | AO3: 14 | AP3: 15 | AQ3: 16 | AR3: 17 | AS3: 18 | AT3: 19 | AU3: 20 | AV3: 21 | AW3: 22 | AX3: 23 | AY3: 24 | AZ3: 25 | BA3: 26 | BB3: 27 | BC3: 28 | BD3: 29 | BE3: 30 | BF3: 31 | BG3: 32 | BH3: 33 | BI3: 34 | BJ3: 35 | BK3: 36 | BL3: 37 | BM3: 38 | BN3: 39 | BO3: 40 | BP3: 41 | BQ3: 42 | BS3: 1 | BT3: 2 | BU3: 3 | BV3: 4 | BW3: 5 | BX3: 6 | BY3: 7 | BZ3: 8 | CA3: 9 | CB3: 10 | CC3: 11 | CD3: 12 | CE3: 13 | CF3: 14 | CG3: 15 | CH3: 16 | CI3: 17 | CJ3: 18 | CK3: 19 | CL3: 20 | CM3: 21 | CN3: 22 | CO3: 23 | CP3: 24 | CQ3: 25 | CR3: 26 | CS3: 27 | CT3: 28 | CU3: 29 | CV3: 30 | CW3: 31 | CX3: 32 | CY3: 33 | CZ3: 34 | DA3: 35 | DB3: 36 | DC3: 37 | DD3: 38 | DE3: 39 | DF3: 40 | DG3: 41 | DH3: 42 | DJ3: Expected Fund Credits at Retirement | DK3: Annuity Factor | DL3: Annual Pension | DM3: Annual Salary b4 Retirement | DN3: IRR | DP3: 1 | DQ3: =DP3+1 -> 2 | DR3: =DQ3+1 -> 3
A4: M0001 | B4: Allison Hill | C4: Active | D4: Male | E4: 27372 | F4: 36708 | G4: 37981 | H4: 1453556 | I4: 90476 | J4: 82819.11 | L4: 173295.11 | M4: =IF(COUNTIF($A$4:A204,A4)=1,0,1) -> 0 | N4: =IF(T4<=18,"WHAT!!!",IF(T4>100,"EERM","Okay")) -> Okay | O4: =IF(G4>E4,"TRUE","FALSE") -> TRUE | P4: =G4>=Comm_Date -> TRUE | Q4: =$G4>=$F4 -> TRUE | R4: =$F4>$E4 -> TRUE | S4: =YEARFRAC(E4,F4,3) -> 25.578082 | T4: =ROUNDDOWN(YEARFRAC($E4,Analysis_Date,3),0) -> 50 | U4: =ROUNDDOWN(YEARFRAC($E4,$G4,3),0) -> 29 | V4: =YEARFRAC($G4,Analysis_Date,3) -> 21.027397 | W4: =MAX(ROUNDDOWN(NRA-T4,0),0) -> 10 | X4: =L4*W4 -> 1732951.1 | Y4: =IF($D4=$C$1,VLOOKUP($T4,Mortality_Table,3,FALSE),VLOOKUP($T4,Mortality_Table,2,FALSE)) -> 0.00547 | Z4: =IF($D4=$C$1,VLOOKUP($T4,Male_Annuity_Tables,MATCH($W4+2,'Mortality Tables'!$DS$1:$HT$1,0),FALSE),VLOOKUP($T4,Fe_Annuity_Tables,MATCH($W4+2,'Mortality Tables'!$M$1:$DN$1,0),FALSE)) -> 0.41898499 | AB4: =IFERROR(IF($W4>=AB$3,($H4*(1+Ann_Salary_Growth_Rate)^AB$3),""),0) -> 1527614.7 | AC4: =IFERROR(IF($W4>=AC$3,($H4*(1+Ann_Salary_Growth_Rate)^AC$3),""),0) -> 1605446.6 | AD4: =IFERROR(IF($W4>=AD$3,($H4*(1+Ann_Salary_Growth_Rate)^AD$3),""),0) -> 1687244.2 | AE4: =IFERROR(IF($W4>=AE$3,($H4*(1+Ann_Salary_Growth_Rate)^AE$3),""),0) -> 1773209.2 | AF4: =IFERROR(IF($W4>=AF$3,($H4*(1+Ann_Salary_Growth_Rate)^AF$3),""),0) -> 1863554.3 | AG4: =IFERROR(IF($W4>=AG$3,($H4*(1+Ann_Salary_Growth_Rate)^AG$3),""),0) -> 1958502.3 | AH4: =IFERROR(IF($W4>=AH$3,($H4*(1+Ann_Salary_Growth_Rate)^AH$3),""),0) -> 2058288 | AI4: =IFERROR(IF($W4>=AI$3,($H4*(1+Ann_Salary_Growth_Rate)^AI$3),""),0) -> 2163157.8 | ... BQ4: =IFERROR(IF($W4>=BQ$3,($H4*(1+Ann_Salary_Growth_Rate)^BQ$3),""),0) | BS4: =IFERROR(($L4+AB4*Contr_Rate)*(1+Inv_Return)*IF($D4=$C$1,VLOOKUP($T4,Male_Annuity_Tables,MATCH($BS$3+3,'Mortality Tables'!$N$1:$DN$1,0),FALSE),VLOOKUP($T4,Fe_Annuity_Tables,MATCH(BS$3+3,'Mortality Tables'!$N$1:$DN$1,0),FALSE)),"") -> 580939.97 | BT4: =IFERROR(($BS4+AC4*Contr_Rate)*(1+Inv_Return)*IF($D4=$C$1,VLOOKUP($T4,Male_Annuity_Tables,MATCH($BS$3+3,'Mortality Tables'!$N$1:$DN$1,0),FALSE),VLOOKUP($T4,Fe_Annuity_Tables,MATCH(BT$3+3,'Mortality Tables'!$N$1:$DN$1,0),FALSE)),"") -> 977377.63 | BU4: =IFERROR((BT4+AD4*Contr_Rate)*(1+Inv_Return)*IF($D4=$C$1,VLOOKUP($T4,Male_Annuity_Tables,MATCH($BS$3+3,'Mortality Tables'!$N$1:$DN$1,0),FALSE),VLOOKUP($T4,Fe_Annuity_Tables,MATCH(BU$3+3,'Mortality Tables'!$N$1:$DN$1,0),FALSE)),"") -> 1364601 | BV4: =IFERROR((BU4+AE4*Contr_Rate)*(1+Inv_Return)*IF($D4=$C$1,VLOOKUP($T4,Male_Annuity_Tables,MATCH($BS$3+3,'Mortality Tables'!$N$1:$DN$1,0),FALSE),VLOOKUP($T4,Fe_Annuity_Tables,MATCH(BV$3+3,'Mortality Tables'!$N$1:$DN$1,0),FALSE)),"") -> 1744498.8 | BW4: =IFERROR((BV4+AF4*Contr_Rate)*(1+Inv_Return)*IF($D4=$C$1,VLOOKUP($T4,Male_Annuity_Tables,MATCH($BS$3+3,'Mortality Tables'!$N$1:$DN$1,0),FALSE),VLOOKUP($T4,Fe_Annuity_Tables,MATCH(BW$3+3,'Mortality Tables'!$N$1:$DN$1,0),FALSE)),"") -> 2118867 | BX4: =IFERROR((BW4+AG4*Contr_Rate)*(1+Inv_Return)*IF($D4=$C$1,VLOOKUP($T4,Male_Annuity_Tables,MATCH($BS$3+3,'Mortality Tables'!$N$1:$DN$1,0),FALSE),VLOOKUP($T4,Fe_Annuity_Tables,MATCH(BX$3+3,'Mortality Tables'!$N$1:$DN$1,0),FALSE)),"") -> 2489419.3 | BY4: =IFERROR((BX4+AH4*Contr_Rate)*(1+Inv_Return)*IF($D4=$C$1,VLOOKUP($T4,Male_Annuity_Tables,MATCH($BS$3+3,'Mortality Tables'!$N$1:$DN$1,0),FALSE),VLOOKUP($T4,Fe_Annuity_Tables,MATCH(BY$3+3,'Mortality Tables'!$N$1:$DN$1,0),FALSE)),"") -> 2857796.5 | BZ4: =IFERROR((BY4+AI4*Contr_Rate)*(1+Inv_Return)*IF($D4=$C$1,VLOOKUP($T4,Male_Annuity_Tables,MATCH($BS$3+3,'Mortality Tables'!$N$1:$DN$1,0),FALSE),VLOOKUP($T4,Fe_Annuity_Tables,MATCH(BZ$3+3,'Mortality Tables'!$N$1:$DN$1,0),FALSE)),"") -> 3225575.9 | CA4: =IFERROR((BZ4+AJ4*Contr_Rate)*(1+Inv_Return)*IF($D4=$C$1,VLOOKUP($T4,Male_Annuity_Tables,MATCH($BS$3+3,'Mortality Tables'!$N$1:$DN$1,0),FALSE),VLOOKUP($T4,Fe_Annuity_Tables,MATCH(CA$3+3,'Mortality Tables'!$N$1:$DN$1,0),FALSE)),"") -> 3594279.9 | CB4: =IFERROR((CA4+AK4*Contr_Rate)*(1+Inv_Return)*IF($D4=$C$1,VLOOKUP($T4,Male_Annuity_Tables,MATCH($BS$3+3,'Mortality Tables'!$N$1:$DN$1,0),FALSE),VLOOKUP($T4,Fe_Annuity_Tables,MATCH(CB$3+3,'Mortality Tables'!$N$1:$DN$1,0),FALSE)),"") -> 3965383.9 | ... DH4: =IFERROR((DG4+BQ4*Contr_Rate)*(1+Inv_Return)*IF($D4=$C$1,VLOOKUP($T4,Male_Annuity_Tables,MATCH($BS$3+3,'Mortality Tables'!$N$1:$DN$1,0),FALSE),VLOOKUP($T4,Fe_Annuity_Tables,MATCH(DH$3+3,'Mortality Tables'!$N$1:$DN$1,0),FALSE)),"") | DJ4: =MAX(BS4:DH4) -> 3965383.9 | DK4: =IF($D4="FEMALE",Fe_Annuity_Factor,Male_Annuity_Factor) -> 8.0909278 | DL4: =(DJ4*Annuity_Ratio)/DK4 -> 328368.67 | DM4: =MAX($AB4:$BQ4) -> 2389198.9 | DN4: =IFERROR((DL4/DM4),"") -> 0.13743882 | DP4: =IFERROR(IF($D4=$C$1,VLOOKUP($T4+DP$3-1,Male_Annuity_Tables,2,FALSE),VLOOKUP($T4,Fe_Annuity_Tables,2,FALSE))*BS4,"") -> 60953.965 | DQ4: =IFERROR(IF($D4=$C$1,VLOOKUP($T4+DQ$3-1,Male_Annuity_Tables,2,FALSE),VLOOKUP($T4,Fe_Annuity_Tables,2,FALSE))*BT4,"") -> 103015.6 | DR4: =IFERROR(IF($D4=$C$1,VLOOKUP($T4+DR$3-1,Male_Annuity_Tables,2,FALSE),VLOOKUP($T4,Fe_Annuity_Tables,2,FALSE))*BU4,"") -> 144553.54
A5: M0002 | B5: Stephanie Miller | C5: Active | D5: Female | E5: 25736 | F5: 35368 | G5: 35738 | H5: 433306 | I5: 22310.87 | J5: 26402.16 | K5: 6194.12 | L5: 54907.15 | M5: =IF(COUNTIF($A$4:A204,A5)=1,0,1) -> 0 | N5: =IF(T5<=18,"WHAT!!!",IF(T5>100,"EERM","Okay")) -> Okay | O5: =IF(G5>E5,"TRUE","FALSE") -> TRUE | P5: =G5>=Comm_Date -> TRUE | Q5: =$G5>=$F5 -> TRUE | R5: =$F5>$E5 -> TRUE | S5: =YEARFRAC(E5,F5,3) -> 26.389041 | T5: =ROUNDDOWN(YEARFRAC($E5,Analysis_Date,3),0) -> 54 | U5: =ROUNDDOWN(YEARFRAC($E5,$G5,3),0) -> 27 | V5: =YEARFRAC($G5,Analysis_Date,3) -> 27.172603 | W5: =MAX(ROUNDDOWN(NRA-T5,0),0) -> 6 | X5: =L5*W5 -> 329442.9 | Y5: =IF($D5=$C$1,VLOOKUP($T5,Mortality_Table,3,FALSE),VLOOKUP($T5,Mortality_Table,2,FALSE)) -> 0.0051 | Z5: =IF($D5=$C$1,VLOOKUP($T5,Male_Annuity_Tables,MATCH($W5+2,'Mortality Tables'!$DS$1:$HT$1,0),FALSE),VLOOKUP($T5,Fe_Annuity_Tables,MATCH($W5+2,'Mortality Tables'!$M$1:$DN$1,0),FALSE)) -> 0.67029933 | AB5: =IFERROR(IF($W5>=AB$3,($H5*(1+Ann_Salary_Growth_Rate)^AB$3),""),0) -> 455382.94 | AC5: =IFERROR(IF($W5>=AC$3,($H5*(1+Ann_Salary_Growth_Rate)^AC$3),""),0) -> 478584.7 | AD5: =IFERROR(IF($W5>=AD$3,($H5*(1+Ann_Salary_Growth_Rate)^AD$3),""),0) -> 502968.59 | AE5: =IFERROR(IF($W5>=AE$3,($H5*(1+Ann_Salary_Growth_Rate)^AE$3),""),0) -> 528594.84 | AF5: =IFERROR(IF($W5>=AF$3,($H5*(1+Ann_Salary_Growth_Rate)^AF$3),""),0) -> 555526.75 | AG5: =IFERROR(IF($W5>=AG$3,($H5*(1+Ann_Salary_Growth_Rate)^AG$3),""),0) -> 583830.84 | AH5: =IFERROR(IF($W5>=AH$3,($H5*(1+Ann_Salary_Growth_Rate)^AH$3),""),0) | AI5: =IFERROR(IF($W5>=AI$3,($H5*(1+Ann_Salary_Growth_Rate)^AI$3),""),0) | ... BQ5: =IFERROR(IF($W5>=BQ$3,($H5*(1+Ann_Salary_Growth_Rate)^BQ$3),""),0) | BS5: =IFERROR(($L5+AB5*Contr_Rate)*(1+Inv_Return)*IF($D5=$C$1,VLOOKUP($T5,Male_Annuity_Tables,MATCH($BS$3+3,'Mortality Tables'!$N$1:$DN$1,0),FALSE),VLOOKUP($T5,Fe_Annuity_Tables,MATCH(BS$3+3,'Mortality Tables'!$N$1:$DN$1,0),FALSE)),"") -> 176231.49 | BT5: =IFERROR(($BS5+AC5*Contr_Rate)*(1+Inv_Return)*IF($D5=$C$1,VLOOKUP($T5,Male_Annuity_Tables,MATCH($BS$3+3,'Mortality Tables'!$N$1:$DN$1,0),FALSE),VLOOKUP($T5,Fe_Annuity_Tables,MATCH(BT$3+3,'Mortality Tables'!$N$1:$DN$1,0),FALSE)),"") -> 278014.78 | BU5: =IFERROR((BT5+AD5*Contr_Rate)*(1+Inv_Return)*IF($D5=$C$1,VLOOKUP($T5,Male_Annuity_Tables,MATCH($BS$3+3,'Mortality Tables'!$N$1:$DN$1,0),FALSE),VLOOKUP($T5,Fe_Annuity_Tables,MATCH(BU$3+3,'Mortality Tables'!$N$1:$DN$1,0),FALSE)),"") -> 352088.24 | BV5: =IFERROR((BU5+AE5*Contr_Rate)*(1+Inv_Return)*IF($D5=$C$1,VLOOKUP($T5,Male_Annuity_Tables,MATCH($BS$3+3,'Mortality Tables'!$N$1:$DN$1,0),FALSE),VLOOKUP($T5,Fe_Annuity_Tables,MATCH(BV$3+3,'Mortality Tables'!$N$1:$DN$1,0),FALSE)),"") -> 395645.24 | BW5: =IFERROR((BV5+AF5*Contr_Rate)*(1+Inv_Return)*IF($D5=$C$1,VLOOKUP($T5,Male_Annuity_Tables,MATCH($BS$3+3,'Mortality Tables'!$N$1:$DN$1,0),FALSE),VLOOKUP($T5,Fe_Annuity_Tables,MATCH(BW$3+3,'Mortality Tables'!$N$1:$DN$1,0),FALSE)),"") -> 410917.85 | BX5: =IFERROR((BW5+AG5*Contr_Rate)*(1+Inv_Return)*IF($D5=$C$1,VLOOKUP($T5,Male_Annuity_Tables,MATCH($BS$3+3,'Mortality Tables'!$N$1:$DN$1,0),FALSE),VLOOKUP($T5,Fe_Annuity_Tables,MATCH(BX$3+3,'Mortality Tables'!$N$1:$DN$1,0),FALSE)),"") -> 403700.19 | BY5: =IFERROR((BX5+AH5*Contr_Rate)*(1+Inv_Return)*IF($D5=$C$1,VLOOKUP($T5,Male_Annuity_Tables,MATCH($BS$3+3,'Mortality Tables'!$N$1:$DN$1,0),FALSE),VLOOKUP($T5,Fe_Annuity_Tables,MATCH(BY$3+3,'Mortality Tables'!$N$1:$DN$1,0),FALSE)),"") | BZ5: =IFERROR((BY5+AI5*Contr_Rate)*(1+Inv_Return)*IF($D5=$C$1,VLOOKUP($T5,Male_Annuity_Tables,MATCH($BS$3+3,'Mortality Tables'!$N$1:$DN$1,0),FALSE),VLOOKUP($T5,Fe_Annuity_Tables,MATCH(BZ$3+3,'Mortality Tables'!$N$1:$DN$1,0),FALSE)),"") | CA5: =IFERROR((BZ5+AJ5*Contr_Rate)*(1+Inv_Return)*IF($D5=$C$1,VLOOKUP($T5,Male_Annuity_Tables,MATCH($BS$3+3,'Mortality Tables'!$N$1:$DN$1,0),FALSE),VLOOKUP($T5,Fe_Annuity_Tables,MATCH(CA$3+3,'Mortality Tables'!$N$1:$DN$1,0),FALSE)),"") | CB5: =IFERROR((CA5+AK5*Contr_Rate)*(1+Inv_Return)*IF($D5=$C$1,VLOOKUP($T5,Male_Annuity_Tables,MATCH($BS$3+3,'Mortality Tables'!$N$1:$DN$1,0),FALSE),VLOOKUP($T5,Fe_Annuity_Tables,MATCH(CB$3+3,'Mortality Tables'!$N$1:$DN$1,0),FALSE)),"") | ... DH5: =IFERROR((DG5+BQ5*Contr_Rate)*(1+Inv_Return)*IF($D5=$C$1,VLOOKUP($T5,Male_Annuity_Tables,MATCH($BS$3+3,'Mortality Tables'!$N$1:$DN$1,0),FALSE),VLOOKUP($T5,Fe_Annuity_Tables,MATCH(DH$3+3,'Mortality Tables'!$N$1:$DN$1,0),FALSE)),"") | DJ5: =MAX(BS5:DH5) -> 410917.85 | DK5: =IF($D5="FEMALE",Fe_Annuity_Factor,Male_Annuity_Factor) -> 8.8017766 | DL5: =(DJ5*Annuity_Ratio)/DK5 -> 31279.476 | DM5: =MAX($AB5:$BQ5) -> 583830.84 | DN5: =IFERROR((DL5/DM5),"") -> 0.053576266 | DP5: =IFERROR(IF($D5=$C$1,VLOOKUP($T5+DP$3-1,Male_Annuity_Tables,2,FALSE),VLOOKUP($T5,Fe_Annuity_Tables,2,FALSE))*BS5,"") -> 18432.051 | DQ5: =IFERROR(IF($D5=$C$1,VLOOKUP($T5+DQ$3-1,Male_Annuity_Tables,2,FALSE),VLOOKUP($T5,Fe_Annuity_Tables,2,FALSE))*BT5,"") -> 29077.566 | DR5: =IFERROR(IF($D5=$C$1,VLOOKUP($T5+DR$3-1,Male_Annuity_Tables,2,FALSE),VLOOKUP($T5,Fe_Annuity_Tables,2,FALSE))*BU5,"") -> 36824.909
