Workbook
Name Daily_Fees_Rate: Model!$C$7
Name Daily_Interest: Model!$C$6
Name i: Model!$C$4
Name Monthly_Cut_off_Date: Model!$C$11

Sheet Intro
C5: DA & IPP Valuation
C8: General Information
D10: Client | E10: Kenbright Training
D11: Project | E11: DA & IPP Training
D12: Valuation Date | E12: 45657

Sheet Guidance Notes
C3: Data Provided
C4: 1. You are provided with Contribution & Withdrawal data for 3 pension schemes
C7: Data Clean Up
C8: 1. Start by combining the Contributions and Withdrawal data into a single excel Sheet
C9: 2. Make sure to negate all the withdrawal amounts from the Fund
C10: 3. Contribution and withdrawal amounts should be pasted on different columns
C12: Transaction Dates
C13: 3. Create a copy of the data Clean up Sheet then sort the data by Transaction date from earliest transaction to Latest transaction
C15: Model
C16: 4. Paste the sorted data on the Model tab
C19: Instructions
C20: 1. Opening balance for the fund was KES 20,502,306 as at 1st January 2024. Calculate the Fund Closing balance as at 31st December
... C22: 3. The fund charges a management fee of 2%

Sheet Contributions_Data
A1: Policy Number | B1: Member Number | C1: Transaction Date | D1: Contribution Amount (KES)
A2: DA-003 | B2: DA-003-M0001 | C2: 45456 | D2: 15261.14
A3: DA-003 | B3: DA-003-M0001 | C3: 45502 | D3: 14102.98
A4: DA-003 | B4: DA-003-M0001 | C4: 45401 | D4: 9037.29
A5: DA-003 | B5: DA-003-M0001 | C5: 45644 | D5: 14340.98
A6: DA-003 | B6: DA-003-M0001 | C6: 45548 | D6: 16071.34
A7: DA-003 | B7: DA-003-M0001 | C7: 45508 | D7: 19433.68
A8: DA-003 | B8: DA-003-M0001 | C8: 45440 | D8: 12574.52
A9: DA-003 | B9: DA-003-M0001 | C9: 45344 | D9: 13494.73
A10: DA-003 | B10: DA-003-M0001 | C10: 45307 | D10: 15986.25
A11: DA-003 | B11: DA-003-M0001 | C11: 45387 | D11: 13410.72
A12: DA-003 | B12: DA-003-M0001 | C12: 45310 | D12: 16539.8
A13: DA-003 | B13: DA-003-M0001 | C13: 45463 | D13: 15291.23
... A1201: DA-003 | B1201: DA-003-M0100 | C1201: 45632 | D1201: 14766.49

Sheet Withdrawals_Data
A1: Policy Number | B1: Member Number | C1: Transaction Date | D1: Withdrawal Amount (KES)
A2: DA-001 | B2: DA-001-M0075 | C2: 45477 | D2: 18318.84
A3: DA-001 | B3: DA-001-M0053 | C3: 45422 | D3: 18107.73
A4: DA-001 | B4: DA-001-M0071 | C4: 45429 | D4: 17009.74
A5: DA-001 | B5: DA-001-M0019 | C5: 45340 | D5: 16759.21
A6: DA-002 | B6: DA-002-M0088 | C6: 45422 | D6: 16660.01
A7: DA-002 | B7: DA-002-M0062 | C7: 45397 | D7: 16569.08
A8: DA-001 | B8: DA-001-M0011 | C8: 45363 | D8: 16488.62
A9: DA-003 | B9: DA-003-M0086 | C9: 45508 | D9: 16053.55
A10: DA-001 | B10: DA-001-M0025 | C10: 45461 | D10: 15858.9
A11: DA-003 | B11: DA-003-M0068 | C11: 45320 | D11: 15656.13
A12: DA-003 | B12: DA-003-M0028 | C12: 45597 | D12: 15637.67
A13: DA-001 | B13: DA-001-M0011 | C13: 45523 | D13: 15061.82
... A1201: DA-003 | B1201: DA-003-M0100 | C1201: 45453 | D1201: 3757

Sheet Data_Clean_Up
H6: =SUM(H8:H2407) -> 18202583
D7: Transactio_Type (Withdrawal or Contribution) | E7: Policy Number | F7: Member Number | G7: Transaction Date | H7: Contribution Amount (KES) | I7: Withdrawal Amount
B8: Contributions >> | C8: {=_xlfn.SEQUENCE(COUNTA(Contributions_Data!A2:A1201))} -> 1 | D8: Contribution | E8: =Contributions_Data!A2 -> DA-003 | F8: =Contributions_Data!B2 -> DA-003-M0001 | G8: =Contributions_Data!C2 -> 45456 | H8: =Contributions_Data!D2 -> 15261.14 | I8: 0
C9: 2 | D9: Contribution | E9: =Contributions_Data!A3 -> DA-003 | F9: =Contributions_Data!B3 -> DA-003-M0001 | G9: =Contributions_Data!C3 -> 45502 | H9: =Contributions_Data!D3 -> 14102.98 | I9: 0
C10: 3 | D10: Contribution | E10: =Contributions_Data!A4 -> DA-003 | F10: =Contributions_Data!B4 -> DA-003-M0001 | G10: =Contributions_Data!C4 -> 45401 | H10: =Contributions_Data!D4 -> 9037.29 | I10: 0
C11: 4 | D11: Contribution | E11: =Contributions_Data!A5 -> DA-003 | F11: =Contributions_Data!B5 -> DA-003-M0001 | G11: =Contributions_Data!C5 -> 45644 | H11: =Contributions_Data!D5 -> 14340.98 | I11: 0
C12: 5 | D12: Contribution | E12: =Contributions_Data!A6 -> DA-003 | F12: =Contributions_Data!B6 -> DA-003-M0001 | G12: =Contributions_Data!C6 -> 45548 | H12: =Contributions_Data!D6 -> 16071.34 | I12: 0
C13: 6 | D13: Contribution | E13: =Contributions_Data!A7 -> DA-003 | F13: =Contributions_Data!B7 -> DA-003-M0001 | G13: =Contributions_Data!C7 -> 45508 | H13: =Contributions_Data!D7 -> 19433.68 | I13: 0
C14: 7 | D14: Contribution | E14: =Contributions_Data!A8 -> DA-003 | F14: =Contributions_Data!B8 -> DA-003-M0001 | G14: =Contributions_Data!C8 -> 45440 | H14: =Contributions_Data!D8 -> 12574.52 | I14: 0
C15: 8 | D15: Contribution | E15: =Contributions_Data!A9 -> DA-003 | F15: =Contributions_Data!B9 -> DA-003-M0001 | G15: =Contributions_Data!C9 -> 45344 | H15: =Contributions_Data!D9 -> 13494.73 | I15: 0
C16: 9 | D16: Contribution | E16: =Contributions_Data!A10 -> DA-003 | F16: =Contributions_Data!B10 -> DA-003-M0001 | G16: =Contributions_Data!C10 -> 45307 | H16: =Contributions_Data!D10 -> 15986.25 | I16: 0
C17: 10 | D17: Contribution | E17: =Contributions_Data!A11 -> DA-003 | F17: =Contributions_Data!B11 -> DA-003-M0001 | G17: =Contributions_Data!C11 -> 45387 | H17: =Contributions_Data!D11 -> 13410.72 | I17: 0
C18: 11 | D18: Contribution | E18: =Contributions_Data!A12 -> DA-003 | F18: =Contributions_Data!B12 -> DA-003-M0001 | G18: =Contributions_Data!C12 -> 45310 | H18: =Contributions_Data!D12 -> 16539.8 | I18: 0
C19: 12 | D19: Contribution | E19: =Contributions_Data!A13 -> DA-003 | F19: =Contributions_Data!B13 -> DA-003-M0001 | G19: =Contributions_Data!C13 -> 45463 | H19: =Contributions_Data!D13 -> 15291.23 | I19: 0
C20: 13 | D20: Contribution | E20: =Contributions_Data!A14 -> DA-001 | F20: =Contributions_Data!B14 -> DA-001-M0002 | G20: =Contributions_Data!C14 -> 45591 | H20: =Contributions_Data!D14 -> 12893.84 | I20: 0
... C1207: 1200 | D1207: Contribution | E1207: =Contributions_Data!A1201 -> DA-003 | F1207: =Contributions_Data!B1201 -> DA-003-M0100 | G1207: =Contributions_Data!C1201 -> 45632 | H1207: =Contributions_Data!D1201 -> 14766.49 | I1207: 0
B1208: Withdrawals >>> | C1208: {=_xlfn.SEQUENCE(COUNTA(Withdrawals_Data!A2:A1201))} -> 1 | D1208: Withdrawal | E1208: =Withdrawals_Data!A2 -> DA-001 | F1208: =Withdrawals_Data!B2 -> DA-001-M0075 | G1208: =Withdrawals_Data!C2 -> 45477 | H1208: 0 | I1208: =-Withdrawals_Data!D2 -> -18318.84
C1209: 2 | D1209: Withdrawal | E1209: =Withdrawals_Data!A3 -> DA-001 | F1209: =Withdrawals_Data!B3 -> DA-001-M0053 | G1209: =Withdrawals_Data!C3 -> 45422 | H1209: 0 | I1209: =-Withdrawals_Data!D3 -> -18107.73
C1210: 3 | D1210: Withdrawal | E1210: =Withdrawals_Data!A4 -> DA-001 | F1210: =Withdrawals_Data!B4 -> DA-001-M0071 | G1210: =Withdrawals_Data!C4 -> 45429 | H1210: 0 | I1210: =-Withdrawals_Data!D4 -> -17009.74
C1211: 4 | D1211: Withdrawal | E1211: =Withdrawals_Data!A5 -> DA-001 | F1211: =Withdrawals_Data!B5 -> DA-001-M0019 | G1211: =Withdrawals_Data!C5 -> 45340 | H1211: 0 | I1211: =-Withdrawals_Data!D5 -> -16759.21
C1212: 5 | D1212: Withdrawal | E1212: =Withdrawals_Data!A6 -> DA-002 | F1212: =Withdrawals_Data!B6 -> DA-002-M0088 | G1212: =Withdrawals_Data!C6 -> 45422 | H1212: 0 | I1212: =-Withdrawals_Data!D6 -> -16660.01
C1213: 6 | D1213: Withdrawal | E1213: =Withdrawals_Data!A7 -> DA-002 | F1213: =Withdrawals_Data!B7 -> DA-002-M0062 | G1213: =Withdrawals_Data!C7 -> 45397 | H1213: 0 | I1213: =-Withdrawals_Data!D7 -> -16569.08
C1214: 7 | D1214: Withdrawal | E1214: =Withdrawals_Data!A8 -> DA-001 | F1214: =Withdrawals_Data!B8 -> DA-001-M0011 | G1214: =Withdrawals_Data!C8 -> 45363 | H1214: 0 | I1214: =-Withdrawals_Data!D8 -> -16488.62
C1215: 8 | D1215: Withdrawal | E1215: =Withdrawals_Data!A9 -> DA-003 | F1215: =Withdrawals_Data!B9 -> DA-003-M0086 | G1215: =Withdrawals_Data!C9 -> 45508 | H1215: 0 | I1215: =-Withdrawals_Data!D9 -> -16053.55
C1216: 9 | D1216: Withdrawal | E1216: =Withdrawals_Data!A10 -> DA-001 | F1216: =Withdrawals_Data!B10 -> DA-001-M0025 | G1216: =Withdrawals_Data!C10 -> 45461 | H1216: 0 | I1216: =-Withdrawals_Data!D10 -> -15858.9
C1217: 10 | D1217: Withdrawal | E1217: =Withdrawals_Data!A11 -> DA-003 | F1217: =Withdrawals_Data!B11 -> DA-003-M0068 | G1217: =Withdrawals_Data!C11 -> 45320 | H1217: 0 | I1217: =-Withdrawals_Data!D11 -> -15656.13
C1218: 11 | D1218: Withdrawal | E1218: =Withdrawals_Data!A12 -> DA-003 | F1218: =Withdrawals_Data!B12 -> DA-003-M0028 | G1218: =Withdrawals_Data!C12 -> 45597 | H1218: 0 | I1218: =-Withdrawals_Data!D12 -> -15637.67
C1219: 12 | D1219: Withdrawal | E1219: =Withdrawals_Data!A13 -> DA-001 | F1219: =Withdrawals_Data!B13 -> DA-001-M0011 | G1219: =Withdrawals_Data!C13 -> 45523 | H1219: 0 | I1219: =-Withdrawals_Data!D13 -> -15061.82
C1220: 13 | D1220: Withdrawal | E1220: =Withdrawals_Data!A14 -> DA-001 | F1220: =Withdrawals_Data!B14 -> DA-001-M0075 | G1220: =Withdrawals_Data!C14 -> 45516 | H1220: 0 | I1220: =-Withdrawals_Data!D14 -> -14710.8
... C2407: 1200 | D2407: Withdrawal | E2407: =Withdrawals_Data!A1201 -> DA-003 | F2407: =Withdrawals_Data!B1201 -> DA-003-M0100 | G2407: =Withdrawals_Data!C1201 -> 45453 | H2407: 0 | I2407: =-Withdrawals_Data!D1201 -> -3757

Sheet Transaction_Date
H6: =SUM(H8:H2407) -> 18202583
D7: Transactio_Type (Withdrawal or Contribution) | E7: Policy Number | F7: Member Number | G7: Transaction Date | H7: Contribution Amount (KES) | I7: Withdrawal Amount
B8: Contributions >> | C8: {=_xlfn.SEQUENCE(COUNTA(Contributions_Data!A2:A1201))} -> 1 | D8: Contribution | E8: =Contributions_Data!A910 -> DA-003 | F8: =Contributions_Data!B910 -> DA-003-M0076 | G8: =Contributions_Data!C910 -> 45292 | H8: =Contributions_Data!D910 -> 15701.36 | I8: 0
C9: 2 | D9: Contribution | E9: =Contributions_Data!A1129 -> DA-002 | F9: =Contributions_Data!B1129 -> DA-002-M0094 | G9: =Contributions_Data!C1129 -> 45292 | H9: =Contributions_Data!D1129 -> 14320.55 | I9: 0
C10: 3 | D10: Withdrawal | E10: =Withdrawals_Data!A447 -> DA-003 | F10: =Withdrawals_Data!B447 -> DA-003-M0014 | G10: =Withdrawals_Data!C447 -> 45292 | H10: 0 | I10: =-Withdrawals_Data!D447 -> -4643
C11: 4 | D11: Withdrawal | E11: =Withdrawals_Data!A454 -> DA-003 | F11: =Withdrawals_Data!B454 -> DA-003-M0015 | G11: =Withdrawals_Data!C454 -> 45292 | H11: 0 | I11: =-Withdrawals_Data!D454 -> -3334
C12: 5 | D12: Contribution | E12: =Contributions_Data!A361 -> DA-002 | F12: =Contributions_Data!B361 -> DA-002-M0030 | G12: =Contributions_Data!C361 -> 45293 | H12: =Contributions_Data!D361 -> 14390.86 | I12: 0
C13: 6 | D13: Contribution | E13: =Contributions_Data!A553 -> DA-001 | F13: =Contributions_Data!B553 -> DA-001-M0046 | G13: =Contributions_Data!C553 -> 45293 | H13: =Contributions_Data!D553 -> 18242.34 | I13: 0
C14: 7 | D14: Withdrawal | E14: =Withdrawals_Data!A854 -> DA-002 | F14: =Withdrawals_Data!B854 -> DA-002-M0060 | G14: =Withdrawals_Data!C854 -> 45293 | H14: 0 | I14: =-Withdrawals_Data!D854 -> -6605
C15: 8 | D15: Contribution | E15: =Contributions_Data!A148 -> DA-003 | F15: =Contributions_Data!B148 -> DA-003-M0013 | G15: =Contributions_Data!C148 -> 45294 | H15: =Contributions_Data!D148 -> 15030.7 | I15: 0
C16: 9 | D16: Contribution | E16: =Contributions_Data!A232 -> DA-002 | F16: =Contributions_Data!B232 -> DA-002-M0020 | G16: =Contributions_Data!C232 -> 45294 | H16: =Contributions_Data!D232 -> 13201.82 | I16: 0
C17: 10 | D17: Contribution | E17: =Contributions_Data!A574 -> DA-003 | F17: =Contributions_Data!B574 -> DA-003-M0048 | G17: =Contributions_Data!C574 -> 45294 | H17: =Contributions_Data!D574 -> 10543.32 | I17: 0
C18: 11 | D18: Contribution | E18: =Contributions_Data!A1022 -> DA-003 | F18: =Contributions_Data!B1022 -> DA-003-M0086 | G18: =Contributions_Data!C1022 -> 45294 | H18: =Contributions_Data!D1022 -> 13536.27 | I18: 0
C19: 12 | D19: Contribution | E19: =Contributions_Data!A1030 -> DA-003 | F19: =Contributions_Data!B1030 -> DA-003-M0086 | G19: =Contributions_Data!C1030 -> 45294 | H19: =Contributions_Data!D1030 -> 16379.92 | I19: 0
C20: 13 | D20: Contribution | E20: =Contributions_Data!A1170 -> DA-001 | F20: =Contributions_Data!B1170 -> DA-001-M0098 | G20: =Contributions_Data!C1170 -> 45294 | H20: =Contributions_Data!D1170 -> 16399.29 | I20: 0
C21: 14 | D21: Withdrawal | E21: =Withdrawals_Data!A54 -> DA-003 | F21: =Withdrawals_Data!B54 -> DA-003-M0001 | G21: =Withdrawals_Data!C54 -> 45294 | H21: 0 | I21: =-Withdrawals_Data!D54 -> -11874.58
C22: 15 | D22: Withdrawal | E22: =Withdrawals_Data!A123 -> DA-002 | F22: =Withdrawals_Data!B123 -> DA-002-M0042 | G22: =Withdrawals_Data!C123 -> 45294 | H22: 0 | I22: =-Withdrawals_Data!D123 -> -9231.21
C23: 16 | D23: Withdrawal | E23: =Withdrawals_Data!A169 -> DA-001 | F23: =Withdrawals_Data!B169 -> DA-001-M0098 | G23: =Withdrawals_Data!C169 -> 45294 | H23: 0 | I23: =-Withdrawals_Data!D169 -> -8246.72
C24: 17 | D24: Withdrawal | E24: =Withdrawals_Data!A406 -> DA-001 | F24: =Withdrawals_Data!B406 -> DA-001-M0009 | G24: =Withdrawals_Data!C406 -> 45294 | H24: 0 | I24: =-Withdrawals_Data!D406 -> -13820
C25: 18 | D25: Withdrawal | E25: =Withdrawals_Data!A419 -> DA-001 | F25: =Withdrawals_Data!B419 -> DA-001-M0011 | G25: =Withdrawals_Data!C419 -> 45294 | H25: 0 | I25: =-Withdrawals_Data!D419 -> -15636
C26: 19 | D26: Withdrawal | E26: =Withdrawals_Data!A739 -> DA-003 | F26: =Withdrawals_Data!B739 -> DA-003-M0047 | G26: =Withdrawals_Data!C739 -> 45294 | H26: 0 | I26: =-Withdrawals_Data!D739 -> -15527
C27: 20 | D27: Withdrawal | E27: =Withdrawals_Data!A1077 -> DA-003 | F27: =Withdrawals_Data!B1077 -> DA-003-M0086 | G27: =Withdrawals_Data!C1077 -> 45294 | H27: 0 | I27: =-Withdrawals_Data!D1077 -> -12276
C28: 21 | D28: Contribution | E28: =Contributions_Data!A70 -> DA-003 | F28: =Contributions_Data!B70 -> DA-003-M0006 | G28: =Contributions_Data!C70 -> 45295 | H28: =Contributions_Data!D70 -> 20690.38 | I28: 0
C29: 22 | D29: Contribution | E29: =Contributions_Data!A343 -> DA-003 | F29: =Contributions_Data!B343 -> DA-003-M0029 | G29: =Contributions_Data!C343 -> 45295 | H29: =Contributions_Data!D343 -> 13012.13 | I29: 0
C30: 23 | D30: Contribution | E30: =Contributions_Data!A456 -> DA-001 | F30: =Contributions_Data!B456 -> DA-001-M0038 | G30: =Contributions_Data!C456 -> 45295 | H30: =Contributions_Data!D456 -> 19511.98 | I30: 0
C31: 24 | D31: Contribution | E31: =Contributions_Data!A511 -> DA-001 | F31: =Contributions_Data!B511 -> DA-001-M0043 | G31: =Contributions_Data!C511 -> 45295 | H31: =Contributions_Data!D511 -> 16417.79 | I31: 0
C32: 25 | D32: Contribution | E32: =Contributions_Data!A973 -> DA-003 | F32: =Contributions_Data!B973 -> DA-003-M0081 | G32: =Contributions_Data!C973 -> 45295 | H32: =Contributions_Data!D973 -> 15193.42 | I32: 0
C33: 26 | D33: Contribution | E33: =Contributions_Data!A1018 -> DA-002 | F33: =Contributions_Data!B1018 -> DA-002-M0085 | G33: =Contributions_Data!C1018 -> 45295 | H33: =Contributions_Data!D1018 -> 18119.71 | I33: 0
C34: 27 | D34: Contribution | E34: =Contributions_Data!A1093 -> DA-002 | F34: =Contributions_Data!B1093 -> DA-002-M0091 | G34: =Contributions_Data!C1093 -> 45295 | H34: =Contributions_Data!D1093 -> 15044.06 | I34: 0
C35: 28 | D35: Withdrawal | E35: =Withdrawals_Data!A231 -> DA-001 | F35: =Withdrawals_Data!B231 -> DA-001-M0065 | G35: =Withdrawals_Data!C231 -> 45295 | H35: 0 | I35: =-Withdrawals_Data!D231 -> -6129.2
C36: 29 | D36: Withdrawal | E36: =Withdrawals_Data!A317 -> DA-002 | F36: =Withdrawals_Data!B317 -> DA-002-M0044 | G36: =Withdrawals_Data!C317 -> 45295 | H36: 0 | I36: =-Withdrawals_Data!D317 -> -2373.36
C37: 30 | D37: Withdrawal | E37: =Withdrawals_Data!A618 -> DA-001 | F37: =Withdrawals_Data!B618 -> DA-001-M0034 | G37: =Withdrawals_Data!C618 -> 45295 | H37: 0 | I37: =-Withdrawals_Data!D618 -> -2317
C38: 31 | D38: Withdrawal | E38: =Withdrawals_Data!A648 -> DA-001 | F38: =Withdrawals_Data!B648 -> DA-001-M0038 | G38: =Withdrawals_Data!C648 -> 45295 | H38: 0 | I38: =-Withdrawals_Data!D648 -> -7390
C39: 32 | D39: Withdrawal | E39: =Withdrawals_Data!A710 -> DA-002 | F39: =Withdrawals_Data!B710 -> DA-002-M0044 | G39: =Withdrawals_Data!C710 -> 45295 | H39: 0 | I39: =-Withdrawals_Data!D710 -> -11376
C40: 33 | D40: Withdrawal | E40: =Withdrawals_Data!A1091 -> DA-001 | F40: =Withdrawals_Data!B1091 -> DA-001-M0087 | G40: =Withdrawals_Data!C1091 -> 45295 | H40: 0 | I40: =-Withdrawals_Data!D1091 -> -9068
C41: 34 | D41: Contribution | E41: =Contributions_Data!A441 -> DA-002 | F41: =Contributions_Data!B441 -> DA-002-M0037 | G41: =Contributions_Data!C441 -> 45296 | H41: =Contributions_Data!D441 -> 14837.12 | I41: 0
C42: 35 | D42: Contribution | E42: =Contributions_Data!A1132 -> DA-003 | F42: =Contributions_Data!B1132 -> DA-003-M0095 | G42: =Contributions_Data!C1132 -> 45296 | H42: =Contributions_Data!D1132 -> 20653.76 | I42: 0
C43: 36 | D43: Withdrawal | E43: =Withdrawals_Data!A466 -> DA-002 | F43: =Withdrawals_Data!B466 -> DA-002-M0017 | G43: =Withdrawals_Data!C466 -> 45296 | H43: 0 | I43: =-Withdrawals_Data!D466 -> -6425
C44: 37 | D44: Withdrawal | E44: =Withdrawals_Data!A971 -> DA-001 | F44: =Withdrawals_Data!B971 -> DA-001-M0074 | G44: =Withdrawals_Data!C971 -> 45296 | H44: 0 | I44: =-Withdrawals_Data!D971 -> -16086
C45: 38 | D45: Contribution | E45: =Contributions_Data!A262 -> DA-001 | F45: =Contributions_Data!B262 -> DA-001-M0022 | G45: =Contributions_Data!C262 -> 45297 | H45: =Contributions_Data!D262 -> 15202.56 | I45: 0
...

Sheet Model
B2: Valuation Date | C2: =Intro!E12 -> 45657
B3: Annual Fees Rate | C3: 0.02
B4: Declared Rate of Return | C4: 0
B5: δ | C5: =LN(1+i) -> 0
B6: Daily Interest | C6: {=(1+i)^(1/365)-1} -> 0
B7: Daily Fees Rate | C7: =(1+$C$3)^(1/365)-1 -> 5.4255245e-05
B9: Assumptions
B10: Interest Credited Frequency | C10: Daily
B11: Monthly Cut-off Date | C11: 10
B13: Fund Value as at 1st Januray 20242024 | C13: 20502306
B14: Fund Value as at 31 December 2024 | C14: =K2419 -> 23062009
F15: =F16=SUM(Contributions_Data!D2:D1048576) -> TRUE | G15: =G16=-SUM(Withdrawals_Data!D2:D1048576) -> TRUE
F16: =SUM(F19:F1048576) -> 18202583 | G16: =SUM(G19:G1048576) -> -12363024
B17: Kenbright DA Client Fund Balance as at 31st December 2024
B18: Date of Transaction | C18: Policy No | D18: Transaction Type | E18: Opening Balance | F18: Contributions | G18: Withdrawals | H18: Net Inflow | I18: Interest Credited | J18: Fees | K18: Closing Balance
B19: 45292 | D19: Balance BF | E19: =C13 -> 20502306 | K19: =E19 -> 20502306
B20: 45292 | C20: DA-003 | D20: Contribution | E20: =K19 -> 20502306 | F20: 15701.36 | G20: 0 | H20: =SUM(F20:G20) -> 15701.36 | I20: =(($E20*Daily_Interest)*(_xlfn.DAYS(B20,B19)+1))+((IF(DAY($B19)>Monthly_Cut_off_Date,0,Daily_Interest*H20))*(_xlfn.DAYS(B20,B19)+1)) -> 0 | J20: =(($I20+E20)*Daily_Fees_Rate)*((_xlfn.DAYS(B20,B19)+1)) -> 1112.3576 | K20: =E20+H20+I20-J20 -> 20516895
B21: 45292 | C21: DA-002 | D21: Contribution | E21: =K20 -> 20516895 | F21: 14320.55 | G21: 0 | H21: =SUM(F21:G21) -> 14320.55 | I21: =(($E21*Daily_Interest)*(_xlfn.DAYS(B21,B20)+1))+((IF(DAY($B20)>Monthly_Cut_off_Date,0,Daily_Interest*H21))*(_xlfn.DAYS(B21,B20)+1)) -> 0 | J21: =(($I21+E21)*Daily_Fees_Rate)*((_xlfn.DAYS(B21,B20)+1)) -> 1113.1492 | K21: =E21+H21+I21-J21 -> 20530102
B22: 45292 | C22: DA-003 | D22: Withdrawal | E22: =K21 -> 20530102 | F22: 0 | G22: -4643 | H22: =SUM(F22:G22) -> -4643 | I22: =(($E22*Daily_Interest)*(_xlfn.DAYS(B22,B21)+1))+((IF(DAY($B21)>Monthly_Cut_off_Date,0,Daily_Interest*H22))*(_xlfn.DAYS(B22,B21)+1)) -> 0 | J22: =(($I22+E22)*Daily_Fees_Rate)*((_xlfn.DAYS(B22,B21)+1)) -> 1113.8657 | K22: =E22+H22+I22-J22 -> 20524346
B23: 45292 | C23: DA-003 | D23: Withdrawal | E23: =K22 -> 20524346 | F23: 0 | G23: -3334 | H23: =SUM(F23:G23) -> -3334 | I23: =(($E23*Daily_Interest)*(_xlfn.DAYS(B23,B22)+1))+((IF(DAY($B22)>Monthly_Cut_off_Date,0,Daily_Interest*H23))*(_xlfn.DAYS(B23,B22)+1)) -> 0 | J23: =(($I23+E23)*Daily_Fees_Rate)*((_xlfn.DAYS(B23,B22)+1)) -> 1113.5534 | K23: =E23+H23+I23-J23 -> 20519898
B24: 45293 | C24: DA-002 | D24: Contribution | E24: =K23 -> 20519898 | F24: 14390.86 | G24: 0 | H24: =SUM(F24:G24) -> 14390.86 | I24: =(($E24*Daily_Interest)*(_xlfn.DAYS(B24,B23)+1))+((IF(DAY($B23)>Monthly_Cut_off_Date,0,Daily_Interest*H24))*(_xlfn.DAYS(B24,B23)+1)) -> 0 | J24: =(($I24+E24)*Daily_Fees_Rate)*((_xlfn.DAYS(B24,B23)+1)) -> 2226.6242 | K24: =E24+H24+I24-J24 -> 20532062
B25: 45293 | C25: DA-001 | D25: Contribution | E25: =K24 -> 20532062 | F25: 18242.34 | G25: 0 | H25: =SUM(F25:G25) -> 18242.34 | I25: =(($E25*Daily_Interest)*(_xlfn.DAYS(B25,B24)+1))+((IF(DAY($B24)>Monthly_Cut_off_Date,0,Daily_Interest*H25))*(_xlfn.DAYS(B25,B24)+1)) -> 0 | J25: =(($I25+E25)*Daily_Fees_Rate)*((_xlfn.DAYS(B25,B24)+1)) -> 1113.9721 | K25: =E25+H25+I25-J25 -> 20549191
B26: 45293 | C26: DA-002 | D26: Withdrawal | E26: =K25 -> 20549191 | F26: 0 | G26: -6605 | H26: =SUM(F26:G26) -> -6605 | I26: =(($E26*Daily_Interest)*(_xlfn.DAYS(B26,B25)+1))+((IF(DAY($B25)>Monthly_Cut_off_Date,0,Daily_Interest*H26))*(_xlfn.DAYS(B26,B25)+1)) -> 0 | J26: =(($I26+E26)*Daily_Fees_Rate)*((_xlfn.DAYS(B26,B25)+1)) -> 1114.9014 | K26: =E26+H26+I26-J26 -> 20541471
B27: 45294 | C27: DA-003 | D27: Contribution | E27: =K26 -> 20541471 | F27: 15030.7 | G27: 0 | H27: =SUM(F27:G27) -> 15030.7 | I27: =(($E27*Daily_Interest)*(_xlfn.DAYS(B27,B26)+1))+((IF(DAY($B26)>Monthly_Cut_off_Date,0,Daily_Interest*H27))*(_xlfn.DAYS(B27,B26)+1)) -> 0 | J27: =(($I27+E27)*Daily_Fees_Rate)*((_xlfn.DAYS(B27,B26)+1)) -> 2228.9651 | K27: =E27+H27+I27-J27 -> 20554272
B28: 45294 | C28: DA-002 | D28: Contribution | E28: =K27 -> 20554272 | F28: 13201.82 | G28: 0 | H28: =SUM(F28:G28) -> 13201.82 | I28: =(($E28*Daily_Interest)*(_xlfn.DAYS(B28,B27)+1))+((IF(DAY($B27)>Monthly_Cut_off_Date,0,Daily_Interest*H28))*(_xlfn.DAYS(B28,B27)+1)) -> 0 | J28: =(($I28+E28)*Daily_Fees_Rate)*((_xlfn.DAYS(B28,B27)+1)) -> 1115.1771 | K28: =E28+H28+I28-J28 -> 20566359
B29: 45294 | C29: DA-003 | D29: Contribution | E29: =K28 -> 20566359 | F29: 10543.32 | G29: 0 | H29: =SUM(F29:G29) -> 10543.32 | I29: =(($E29*Daily_Interest)*(_xlfn.DAYS(B29,B28)+1))+((IF(DAY($B28)>Monthly_Cut_off_Date,0,Daily_Interest*H29))*(_xlfn.DAYS(B29,B28)+1)) -> 0 | J29: =(($I29+E29)*Daily_Fees_Rate)*((_xlfn.DAYS(B29,B28)+1)) -> 1115.8329 | K29: =E29+H29+I29-J29 -> 20575787
B30: 45294 | C30: DA-003 | D30: Contribution | E30: =K29 -> 20575787 | F30: 13536.27 | G30: 0 | H30: =SUM(F30:G30) -> 13536.27 | I30: =(($E30*Daily_Interest)*(_xlfn.DAYS(B30,B29)+1))+((IF(DAY($B29)>Monthly_Cut_off_Date,0,Daily_Interest*H30))*(_xlfn.DAYS(B30,B29)+1)) -> 0 | J30: =(($I30+E30)*Daily_Fees_Rate)*((_xlfn.DAYS(B30,B29)+1)) -> 1116.3443 | K30: =E30+H30+I30-J30 -> 20588206
B31: 45294 | C31: DA-003 | D31: Contribution | E31: =K30 -> 20588206 | F31: 16379.92 | G31: 0 | H31: =SUM(F31:G31) -> 16379.92 | I31: =(($E31*Daily_Interest)*(_xlfn.DAYS(B31,B30)+1))+((IF(DAY($B30)>Monthly_Cut_off_Date,0,Daily_Interest*H31))*(_xlfn.DAYS(B31,B30)+1)) -> 0 | J31: =(($I31+E31)*Daily_Fees_Rate)*((_xlfn.DAYS(B31,B30)+1)) -> 1117.0182 | K31: =E31+H31+I31-J31 -> 20603469
... B130: 45307 | C130: DA-003 | D130: Contribution | E130: =K129 -> 20583683 | F130: 15986.25 | G130: 0 | H130: =SUM(F130:G130) -> 15986.25 | I130: =(($E130*Daily_Interest)*(_xlfn.DAYS(B130,B129)+1))+((IF(DAY($B129)>Monthly_Cut_off_Date,0,Daily_Interest*H130))*(_xlfn.DAYS(B130,B129)+1)) -> 0 | J130: =(($I130+E130)*Daily_Fees_Rate)*((_xlfn.DAYS(B130,B129)+1)) -> 2233.5456 | K130: =E130+H130+I130-J130 -> 20597436
B131: 45307 | C131: DA-003 | D131: Contribution | E131: =K130 -> 20597436 | F131: 19592.25 | G131: 0 | H131: =SUM(F131:G131) -> 19592.25 | I131: =(($E131*Daily_Interest)*(_xlfn.DAYS(B131,B130)+1))+((IF(DAY($B130)>Monthly_Cut_off_Date,0,Daily_Interest*H131))*(_xlfn.DAYS(B131,B130)+1)) -> 0 | J131: =(($I131+E131)*Daily_Fees_Rate)*((_xlfn.DAYS(B131,B130)+1)) -> 1117.5189 | K131: =E131+H131+I131-J131 -> 20615911 | L131: 0
B132: 45307 | C132: DA-003 | D132: Withdrawal | E132: =K131 -> 20615911 | F132: 0 | G132: -4985.06 | H132: =SUM(F132:G132) -> -4985.06 | I132: =(($E132*Daily_Interest)*(_xlfn.DAYS(B132,B131)+1))+((IF(DAY($B131)>Monthly_Cut_off_Date,0,Daily_Interest*H132))*(_xlfn.DAYS(B132,B131)+1)) -> 0 | J132: =(($I132+E132)*Daily_Fees_Rate)*((_xlfn.DAYS(B132,B131)+1)) -> 1118.5213 | K132: =E132+H132+I132-J132 -> 20609807
B133: 45307 | C133: DA-002 | D133: Withdrawal | E133: =K132 -> 20609807 | F133: 0 | G133: -1879 | H133: =SUM(F133:G133) -> -1879 | I133: =(($E133*Daily_Interest)*(_xlfn.DAYS(B133,B132)+1))+((IF(DAY($B132)>Monthly_Cut_off_Date,0,Daily_Interest*H133))*(_xlfn.DAYS(B133,B132)+1)) -> 0 | J133: =(($I133+E133)*Daily_Fees_Rate)*((_xlfn.DAYS(B133,B132)+1)) -> 1118.1901 | K133: =E133+H133+I133-J133 -> 20606810
B134: 45307 | C134: DA-002 | D134: Withdrawal | E134: =K133 -> 20606810 | F134: 0 | G134: -4861 | H134: =SUM(F134:G134) -> -4861 | I134: =(($E134*Daily_Interest)*(_xlfn.DAYS(B134,B133)+1))+((IF(DAY($B133)>Monthly_Cut_off_Date,0,Daily_Interest*H134))*(_xlfn.DAYS(B134,B133)+1)) -> 0 | J134: =(($I134+E134)*Daily_Fees_Rate)*((_xlfn.DAYS(B134,B133)+1)) -> 1118.0275 | K134: =E134+H134+I134-J134 -> 20600831
B135: 45307 | C135: DA-002 | D135: Withdrawal | E135: =K134 -> 20600831 | F135: 0 | G135: -14349 | H135: =SUM(F135:G135) -> -14349 | I135: =(($E135*Daily_Interest)*(_xlfn.DAYS(B135,B134)+1))+((IF(DAY($B134)>Monthly_Cut_off_Date,0,Daily_Interest*H135))*(_xlfn.DAYS(B135,B134)+1)) -> 0 | J135: =(($I135+E135)*Daily_Fees_Rate)*((_xlfn.DAYS(B135,B134)+1)) -> 1117.7031 | K135: =E135+H135+I135-J135 -> 20585364
B136: 45307 | C136: DA-003 | D136: Withdrawal | E136: =K135 -> 20585364 | F136: 0 | G136: -12046 | H136: =SUM(F136:G136) -> -12046 | I136: =(($E136*Daily_Interest)*(_xlfn.DAYS(B136,B135)+1))+((IF(DAY($B135)>Monthly_Cut_off_Date,0,Daily_Interest*H136))*(_xlfn.DAYS(B136,B135)+1)) -> 0 | J136: =(($I136+E136)*Daily_Fees_Rate)*((_xlfn.DAYS(B136,B135)+1)) -> 1116.864 | K136: =E136+H136+I136-J136 -> 20572201
B137: 45307 | C137: DA-002 | D137: Withdrawal | E137: =K136 -> 20572201 | F137: 0 | G137: -7640 | H137: =SUM(F137:G137) -> -7640 | I137: =(($E137*Daily_Interest)*(_xlfn.DAYS(B137,B136)+1))+((IF(DAY($B136)>Monthly_Cut_off_Date,0,Daily_Interest*H137))*(_xlfn.DAYS(B137,B136)+1)) -> 0 | J137: =(($I137+E137)*Daily_Fees_Rate)*((_xlfn.DAYS(B137,B136)+1)) -> 1116.1498 | K137: =E137+H137+I137-J137 -> 20563445
B138: 45308 | C138: DA-001 | D138: Contribution | E138: =K137 -> 20563445 | F138: 13738.06 | G138: 0 | H138: =SUM(F138:G138) -> 13738.06 | I138: =(($E138*Daily_Interest)*(_xlfn.DAYS(B138,B137)+1))+((IF(DAY($B137)>Monthly_Cut_off_Date,0,Daily_Interest*H138))*(_xlfn.DAYS(B138,B137)+1)) -> 0 | J138: =(($I138+E138)*Daily_Fees_Rate)*((_xlfn.DAYS(B138,B137)+1)) -> 2231.3495 | K138: =E138+H138+I138-J138 -> 20574952
B139: 45308 | C139: DA-003 | D139: Contribution | E139: =K138 -> 20574952 | F139: 16915.78 | G139: 0 | H139: =SUM(F139:G139) -> 16915.78 | I139: =(($E139*Daily_Interest)*(_xlfn.DAYS(B139,B138)+1))+((IF(DAY($B138)>Monthly_Cut_off_Date,0,Daily_Interest*H139))*(_xlfn.DAYS(B139,B138)+1)) -> 0 | J139: =(($I139+E139)*Daily_Fees_Rate)*((_xlfn.DAYS(B139,B138)+1)) -> 1116.2991 | K139: =E139+H139+I139-J139 -> 20590751
B140: 45308 | C140: DA-002 | D140: Contribution | E140: =K139 -> 20590751 | F140: 19324.71 | G140: 0 | H140: =SUM(F140:G140) -> 19324.71 | I140: =(($E140*Daily_Interest)*(_xlfn.DAYS(B140,B139)+1))+((IF(DAY($B139)>Monthly_Cut_off_Date,0,Daily_Interest*H140))*(_xlfn.DAYS(B140,B139)+1)) -> 0 | J140: =(($I140+E140)*Daily_Fees_Rate)*((_xlfn.DAYS(B140,B139)+1)) -> 1117.1563 | K140: =E140+H140+I140-J140 -> 20608959
B141: 45308 | C141: DA-001 | D141: Contribution | E141: =K140 -> 20608959 | F141: 14776.7 | G141: 0 | H141: =SUM(F141:G141) -> 14776.7 | I141: =(($E141*Daily_Interest)*(_xlfn.DAYS(B141,B140)+1))+((IF(DAY($B140)>Monthly_Cut_off_Date,0,Daily_Interest*H141))*(_xlfn.DAYS(B141,B140)+1)) -> 0 | J141: =(($I141+E141)*Daily_Fees_Rate)*((_xlfn.DAYS(B141,B140)+1)) -> 1118.1441 | K141: =E141+H141+I141-J141 -> 20622618
...

Sheet Results
B2: Types of Insurance | C2: No of Contracts | D2: No of Lives | E2: Amount of Sums Assured | F2: Amount of Vested Bonuses | G2: Amount of Office Premiums | H2: Value of Benefits | I2: Value of Bonuses | J2: Value of Expenses | K2: Value of Commissions | L2: Value of Office Premiums | M2: BE Liability Before Zeroisation | N2: Negative Reserves | O2: Gross Reserve Before Zeroisation | P2: Risk Margin | Q2: Reinsurance | R2: Total Liability
B4: Group Deposit Administration | C4: =COUNTA(_xlfn.UNIQUE(Model!C20:C2419)) -> 3 | H4: =Model!C14 -> 23062009 | M4: =SUM(H4:L4) -> 23062009 | O4: =M4+P4 -> 23062009 | R4: =O4 -> 23062009
C5: =SUM(C4:C4) -> 3 | E5: =SUM(E4:E4) -> 0 | F5: =SUM(F4:F4) -> 0 | G5: =SUM(G4:G4) -> 0 | H5: =SUM(H4:H4) -> 23062009 | I5: =SUM(I4:I4) -> 0 | J5: =SUM(J4:J4) -> 0 | K5: =SUM(K4:K4) -> 0 | L5: =SUM(L4:L4) -> 0 | ... R5: =SUM(R4:R4) -> 23062009
B7: Internal Results (4% guarantee) | C7: 3 | H7: 30050954 | M7: 30050954 | O7: 30050954 | R7: 30050954
B10: Declared Interest at 8% | C10: 3 | E10: 0 | F10: 0 | G10: 0 | H10: 38953126 | I10: 0 | J10: 0 | K10: 0 | L10: 0 | M10: 38953126 | N10: 0 | O10: 38953126 | P10: 0 | Q10: 0 | R10: 38953126
B11: Declared Interest at 10% | C11: 3 | E11: 0 | F11: 0 | G11: 0 | H11: 44255148 | I11: 0 | J11: 0 | K11: 0 | L11: 0 | M11: 44255148 | N11: 0 | O11: 44255148 | P11: 0 | Q11: 0 | R11: 44255148
B12: Declared Interest at 0% | C12: 3 | H12: 23062009 | M12: 23062009 | O12: 23062009 | R12: 23062009
B16: Cost of additional Interest Declared
B17: Declared Interest at 8% | C17: =C10-C7 -> 0 | D17: =D10-D7 -> 0 | E17: =E10-E7 -> 0 | F17: =F10-F7 -> 0 | G17: =G10-G7 -> 0 | H17: =H10-H7 -> 8902172.2 | I17: =I10-I7 -> 0 | J17: =J10-J7 -> 0 | ... R17: =R10-R7 -> 8902172.2
B18: Declared Interest at 10% | C18: =C11-C7 -> 0 | D18: =D11-D7 -> 0 | E18: =E11-E7 -> 0 | F18: =F11-F7 -> 0 | G18: =G11-G7 -> 0 | H18: =H11-H7 -> 14204194 | I18: =I11-I7 -> 0 | J18: =J11-J7 -> 0 | ... R18: =R11-R7 -> 14204194
